Workbook

Sheet ICPOES RESULTS
A1: University of Northern British Columbia
A2: Northern Analytical Laboratory Services
A3: Report File (Processing) | B3: =INSTRUCTIONS!A3
A5: Analyst:
A6: NALS Director: | B6: Dr. Hossein Kazemian
A8: Date:
A9: Client Name:
A10: Supervisor:
A11: Client Company Name:
A12: Reference File:
A13: Number of Samples:
A14: Detection Limits File: | B14: =INSTRUCTIONS!B40
A16: ICPOES (Raw Data - ONLY CLIENT SAMPLE, NO QA/QC) | C16: Ag 328.068 nm | D16: Ag 338.289 nm | E16: Al 396.152 nm | F16: As 188.980 nm | G16: As 193.696 nm | H16: B 249.678 nm | I16: B 249.772 nm | J16: Ba 493.408 nm | K16: Ba-A 455.403 nm | L16: Be 234.861 nm | M16: Be 313.042 nm | N16: Bi 222.821 nm | O16: Bi 223.061 nm | P16: Ca 317.933 nm | Q16: Ca 422.673 nm | R16: Cd 214.439 nm | S16: Cd 226.502 nm | T16: Ce 418.659 nm | U16: Ce 446.021 nm | V16: Co 238.892 nm | W16: Co 258.033 nm | X16: Cr 206.158 nm | Y16: Cr 267.716 nm | Z16: Cu-A 327.395 nm | AA16: Dy 340.780 nm | AB16: Dy 353.171 nm | AC16: Er 337.275 nm | AD16: Er 349.910 nm | AE16: Eu 397.197 nm | AF16: Eu 420.504 nm | AG16: Fe 234.350 nm | AH16: Fe 238.204 nm | AI16: Ga 294.363 nm | AJ16: Ga 417.204 nm | AK16: Gd 335.048 nm | AL16: Gd 342.246 nm | AM16: Hf 263.872 nm | AN16: Hf 264.141 nm | AO16: Hg 184.887 nm | AP16: Hg 194.164 nm | AQ16: Ho 339.895 nm | AR16: Ho 345.600 nm | AS16: K 766.491 nm | AT16: La 333.749 nm | AU16: La 379.477 nm | AV16: Li 610.365 nm | AW16: Li 670.783 nm | AX16: Lu 261.541 nm | AY16: Lu 291.139 nm | AZ16: Mg 280.270 nm | BA16: Mg 285.213 nm | BB16: Mn 257.610 nm | BC16: Mn 294.921 nm | BD16: Mo 202.032 nm | BE16: Mo 204.598 nm | BF16: Na 588.995 nm | BG16: Na 589.592 nm | BH16: Nb 309.417 nm | BI16: Nb 313.078 nm | BJ16: Nd 401.224 nm | BK16: Nd 406.108 nm | BL16: Ni 216.555 nm | BM16: Ni 231.604 nm | BN16: P 177.434 nm | BO16: P 178.222 nm | BP16: P 213.618 nm | BQ16: Pb 220.353 nm | BR16: Rb 780.026 nm | BS16: S 180.669 nm | BT16: S 181.972 nm | BU16: Sb 206.834 nm | BV16: Sb 217.582 nm | BW16: Sc 335.372 nm | BX16: Sc 361.383 nm | BY16: Se 196.026 nm | BZ16: Se 203.985 nm | CA16: Si 251.611 nm | CB16: Si 288.158 nm | CC16: Sm 359.259 nm | CD16: Sm 360.949 nm | CE16: Sn 189.925 nm | CF16: Sn 283.998 nm | CG16: Sr-R 407.771 nm | CH16: Sr-R 421.552 nm | CI16: Ta 263.558 nm | CJ16: Ta 268.517 nm | CK16: Te 182.153 nm | CL16: Te 214.282 nm | CM16: Th 269.242 nm | CN16: Th 283.730 nm | CO16: Ti 334.941 nm | CP16: Ti 336.122 nm | CQ16: Tl 190.794 nm | CR16: Tl 276.789 nm | CS16: Tl 351.923 nm | CT16: Tm 313.125 nm | CU16: Tm 342.508 nm | CV16: U 367.007 nm | CW16: U 385.957 nm | CX16: V 292.401 nm | CY16: V 309.310 nm | CZ16: W 207.912 nm | DA16: W 209.475 nm | DB16: Y 360.074 nm | DC16: Y 371.029 nm | DD16: Yb 328.937 nm | DE16: Yb 369.419 nm | DF16: Zn 202.548 nm | DG16: Zn 213.857 nm | DH16: Zr 339.198 nm | DI16: Zr 343.823 nm
A17: Sample Name | B17: Comment | C17: Conc. (mg/L) | D17: Conc. (mg/L) | E17: Conc. (mg/L) | F17: Conc. (mg/L) | G17: Conc. (mg/L) | H17: Conc. (mg/L) | I17: Conc. (mg/L) | J17: Conc. (mg/L) | K17: Conc. (mg/L) | L17: Conc. (mg/L) | M17: Conc. (µg/L) | N17: Conc. (mg/L) | O17: Conc. (mg/L) | P17: Conc. (mg/L) | Q17: Conc. (mg/L) | R17: Conc. (mg/L) | S17: Conc. (mg/L) | T17: Conc. (mg/L) | U17: Conc. (mg/L) | V17: Conc. (mg/L) | W17: Conc. (mg/L) | X17: Conc. (mg/L) | Y17: Conc. (mg/L) | Z17: Conc. (mg/L) | AA17: Conc. (mg/L) | AB17: Conc. (mg/L) | AC17: Conc. (mg/L) | AD17: Conc. (mg/L) | AE17: Conc. (mg/L) | AF17: Conc. (mg/L) | AG17: Conc. (mg/L) | AH17: Conc. (mg/L) | AI17: Conc. (mg/L) | AJ17: Conc. (mg/L) | AK17: Conc. (mg/L) | AL17: Conc. (mg/L) | AM17: Conc. (mg/L) | AN17: Conc. (mg/L) | AO17: Conc. (µg/L) | AP17: Conc. (µg/L) | AQ17: Conc. (mg/L) | AR17: Conc. (mg/L) | AS17: Conc. (mg/L) | AT17: Conc. (mg/L) | AU17: Conc. (mg/L) | AV17: Conc. (mg/L) | AW17: Conc. (mg/L) | AX17: Conc. (mg/L) | AY17: Conc. (mg/L) | AZ17: Conc. (mg/L) | BA17: Conc. (mg/L) | BB17: Conc. (mg/L) | BC17: Conc. (mg/L) | BD17: Conc. (mg/L) | BE17: Conc. (mg/L) | BF17: Conc. (mg/L) | BG17: Conc. (mg/L) | BH17: Conc. (mg/L) | BI17: Conc. (mg/L) | BJ17: Conc. (mg/L) | BK17: Conc. (mg/L) | BL17: Conc. (mg/L) | BM17: Conc. (mg/L) | BN17: Conc. (mg/L) | BO17: Conc. (mg/L) | BP17: Conc. (mg/L) | BQ17: Conc. (mg/L) | BR17: Conc. (mg/L) | BS17: Conc. (mg/L) | BT17: Conc. (mg/L) | BU17: Conc. (mg/L) | BV17: Conc. (mg/L) | BW17: Conc. (mg/L) | BX17: Conc. (mg/L) | BY17: Conc. (mg/L) | BZ17: Conc. (mg/L) | CA17: Conc. (mg/L) | CB17: Conc. (mg/L) | CC17: Conc. (mg/L) | CD17: Conc. (mg/L) | CE17: Conc. (mg/L) | CF17: Conc. (mg/L) | CG17: Conc. (mg/L) | CH17: Conc. (mg/L) | CI17: Conc. (mg/L) | CJ17: Conc. (mg/L) | CK17: Conc. (mg/L) | CL17: Conc. (mg/L) | CM17: Conc. (mg/L) | CN17: Conc. (mg/L) | CO17: Conc. (mg/L) | CP17: Conc. (mg/L) | CQ17: Conc. (mg/L) | CR17: Conc. (mg/L) | CS17: Conc. (mg/L) | CT17: Conc. (mg/L) | CU17: Conc. (mg/L) | CV17: Conc. (mg/L) | CW17: Conc. (mg/L) | CX17: Conc. (mg/L) | CY17: Conc. (mg/L) | CZ17: Conc. (mg/L) | DA17: Conc. (mg/L) | DB17: Conc. (mg/L) | DC17: Conc. (mg/L) | DD17: Conc. (mg/L) | DE17: Conc. (mg/L) | DF17: Conc. (mg/L) | DG17: Conc. (mg/L) | DH17: Conc. (mg/L) | DI17: Conc. (mg/L)
A63: Reportable Limit (3xMDL) | B63: Reportable Limit (No Dilution) | C63: 0.007 | D63: 0.009 | E63: 0.012 | F63: 0.013 | G63: 0.014 | H63: 0.0017 | I63: 0.0011 | J63: 0.0007 | K63: 0.001 | L63: 0.0005 | M63: 0.0015 | N63: n/a | O63: n/a | P63: 0.004 | Q63: 0.02 | R63: 0.0007 | S63: 0.0007 | T63: 0.001 | U63: 0.002 | V63: 0.0009 | W63: 0.0014 | X63: 0.0032 | Y63: 0.0005 | Z63: 0.0007 | AA63: 0.002 | AB63: 0.001 | AC63: 0.0003 | AD63: 0.001 | AE63: 0.0005 | AF63: 0.0003 | AG63: 0.0067 | AH63: 0.0025 | AI63: 0.004 | AJ63: 0.005 | AK63: 0.001 | AL63: 0.001 | AM63: 0.002 | AN63: 0.001 | AO63: 7 | AP63: 7 | AQ63: 0.002 | AR63: 0.001 | AS63: 0.002 | AT63: 0.0004 | AU63: 0.0003 | AV63: n/a | AW63: n/a | AX63: 0.0004 | AY63: 0.001 | AZ63: 0.0007 | BA63: 0.0041 | BB63: 0.0007 | BC63: 0.0035 | BD63: 0.0023 | BE63: 0.0022 | BF63: 0.0069 | BG63: 0.0011 | BH63: 0.01 | BI63: 0.06 | BJ63: 0.003 | BK63: 0.002 | BL63: 0.0017 | BM63: 0.0009 | BN63: n/a | BO63: n/a | BP63: 0.011 | BQ63: 0.005 | BR63: 0.007 | BS63: 0.056 | BT63: 0.034 | BU63: 0.011 | BV63: 0.007 | BW63: n/a | BX63: n/a | BY63: 0.018 | BZ63: 0.025 | CA63: 0.004 | CB63: 0.003 | CC63: 0.001 | CD63: 0.002 | CE63: 0.01 | CF63: 0.005 | CG63: 0.0003 | CH63: 0.0005 | CI63: 0.003 | CJ63: 0.004 | CK63: 0.1 | CL63: 0.01 | CM63: 0.01 | CN63: 0.003 | CO63: 0.0005 | CP63: 0.0005 | CQ63: 0.01 | CR63: 0.03 | CS63: 0.02 | CT63: 0.002 | CU63: 0.001 | CV63: 0.03 | CW63: 0.012 | CX63: 0.0008 | CY63: 0.003 | CZ63: 0.005 | DA63: 0.01 | DB63: n/a | DC63: n/a | DD63: 0.0003 | DE63: 0.0004 | DF63: 0.001 | DG63: 0.0007 | DH63: 0.0006 | DI63: 0.0005
A64: Reportable Limit (3xMDL) | B64: Reportable Limit (No Dilution) | C64: <0.007 | D64: <0.009 | E64: <0.012 | F64: <0.013 | G64: <0.014 | H64: <0.0017 | I64: <0.0011 | J64: <0.0007 | K64: <0.0010 | L64: <0.0005 | M64: <0.0015 | N64: n/a | O64: n/a | P64: <0.004 | Q64: <0.02 | R64: <0.0007 | S64: <0.0007 | T64: <0.001 | U64: <0.002 | V64: <0.0009 | W64: <0.0014 | X64: <0.0032 | Y64: <0.0005 | Z64: <0.0007 | AA64: <0.002 | AB64: <0.001 | AC64: <0.0003 | AD64: <0.001 | AE64: <0.0005 | AF64: <0.0003 | AG64: <0.0067 | AH64: <0.0025 | AI64: <0.004 | AJ64: <0.005 | AK64: <0.001 | AL64: <0.001 | AM64: <0.002 | AN64: <0.001 | AO64: <7 | AP64: <7 | AQ64: <0.002 | AR64: <0.001 | AS64: <0.002 | AT64: <0.0004 | AU64: <0.0003 | AV64: n/a | AW64: n/a | AX64: <0.0004 | AY64: <0.001 | AZ64: <0.0007 | BA64: <0.0041 | BB64: <0.0007 | BC64: <0.0035 | BD64: <0.0023 | BE64: <0.0022 | BF64: <0.0069 | BG64: <0.0011 | BH64: <0.01 | BI64: <0.06 | BJ64: <0.003 | BK64: <0.002 | BL64: <0.0017 | BM64: <0.0009 | BN64: n/a | BO64: n/a | BP64: <0.011 | BQ64: <0.005 | BR64: <0.007 | BS64: <0.056 | BT64: <0.034 | BU64: <0.011 | BV64: <0.007 | BW64: n/a | BX64: n/a | BY64: <0.018 | BZ64: <0.025 | CA64: <0.004 | CB64: <0.003 | CC64: <0.001 | CD64: <0.002 | CE64: <0.010 | CF64: <0.005 | CG64: <0.0003 | CH64: <0.0005 | CI64: <0.003 | CJ64: <0.004 | CK64: <0.1 | CL64: <0.01 | CM64: <0.01 | CN64: <0.003 | CO64: <0.0005 | CP64: <0.0005 | CQ64: <0.01 | CR64: <0.03 | CS64: <0.02 | CT64: <0.002 | CU64: <0.001 | CV64: <0.03 | CW64: <0.012 | CX64: <0.0008 | CY64: <0.003 | CZ64: <0.005 | DA64: <0.01 | DB64: n/a | DC64: n/a | DD64: <0.0003 | DE64: <0.0004 | DF64: <0.0010 | DG64: <0.0007 | DH64: <0.0006 | DI64: <0.0005
A67: YELLOW IS PREFERRED WAVELENGTH
A68: ICPOES (Reportable Numbers) *DO NOT ADJUST* | C68: =C16 | D68: =D16 | E68: =E16 | F68: =F16 | G68: =G16 | H68: =H16 | I68: =I16 | J68: =J16 | ... DI68: =DI16
A69: Sample Name | B69: Comment | C69: =C17 | D69: =D17 | E69: =E17 | F69: =F17 | G69: =G17 | H69: =H17 | I69: =I17 | J69: =J17 | ... DI69: =DI17
A70: =A18 | B70: =B18 | C70: =IF(ISBLANK(C18),"NO DATA",IF(ISNUMBER(FIND(CODES!$A$12,C18)),CODES!$A$12,IF(OR(ISNUMBER(FIND(CODES!$A$10,C18)),ISNUMBER(FIND(CODES!$A$11,C18))),CODES!$A$13,IF(OR(C18<C$63,ISNUMBER(C18)=FALSE),C$64,C18)))) | D70: =IF(ISBLANK(D18),"NO DATA",IF(ISNUMBER(FIND(CODES!$A$12,D18)),CODES!$A$12,IF(OR(ISNUMBER(FIND(CODES!$A$10,D18)),ISNUMBER(FIND(CODES!$A$11,D18))),CODES!$A$13,IF(OR(D18<D$63,ISNUMBER(D18)=FALSE),D$64,D18)))) | E70: =IF(ISBLANK(E18),"NO DATA",IF(ISNUMBER(FIND(CODES!$A$12,E18)),CODES!$A$12,IF(OR(ISNUMBER(FIND(CODES!$A$10,E18)),ISNUMBER(FIND(CODES!$A$11,E18))),CODES!$A$13,IF(OR(E18<E$63,ISNUMBER(E18)=FALSE),E$64,E18)))) | F70: =IF(ISBLANK(F18),"NO DATA",IF(ISNUMBER(FIND(CODES!$A$12,F18)),CODES!$A$12,IF(OR(ISNUMBER(FIND(CODES!$A$10,F18)),ISNUMBER(FIND(CODES!$A$11,F18))),CODES!$A$13,IF(OR(F18<F$63,ISNUMBER(F18)=FALSE),F$64,F18)))) | G70: =IF(ISBLANK(G18),"NO DATA",IF(ISNUMBER(FIND(CODES!$A$12,G18)),CODES!$A$12,IF(OR(ISNUMBER(FIND(CODES!$A$10,G18)),ISNUMBER(FIND(CODES!$A$11,G18))),CODES!$A$13,IF(OR(G18<G$63,ISNUMBER(G18)=FALSE),G$64,G18)))) | H70: =IF(ISBLANK(H18),"NO DATA",IF(ISNUMBER(FIND(CODES!$A$12,H18)),CODES!$A$12,IF(OR(ISNUMBER(FIND(CODES!$A$10,H18)),ISNUMBER(FIND(CODES!$A$11,H18))),CODES!$A$13,IF(OR(H18<H$63,ISNUMBER(H18)=FALSE),H$64,H18)))) | I70: =IF(ISBLANK(I18),"NO DATA",IF(ISNUMBER(FIND(CODES!$A$12,I18)),CODES!$A$12,IF(OR(ISNUMBER(FIND(CODES!$A$10,I18)),ISNUMBER(FIND(CODES!$A$11,I18))),CODES!$A$13,IF(OR(I18<I$63,ISNUMBER(I18)=FALSE),I$64,I18)))) | J70: =IF(ISBLANK(J18),"NO DATA",IF(ISNUMBER(FIND(CODES!$A$12,J18)),CODES!$A$12,IF(OR(ISNUMBER(FIND(CODES!$A$10,J18)),ISNUMBER(FIND(CODES!$A$11,J18))),CODES!$A$13,IF(OR(J18<J$63,ISNUMBER(J18)=FALSE),J$64,J18)))) | ... DI70: =IF(ISBLANK(DI18),"NO DATA",IF(ISNUMBER(FIND(CODES!$A$12,DI18)),CODES!$A$12,IF(OR(ISNUMBER(FIND(CODES!$A$10,DI18)),ISNUMBER(FIND(CODES!$A$11,DI18))),CODES!$A$13,IF(OR(DI18<DI$63,ISNUMBER(DI18)=FALSE),DI$64,DI18))))
A71: =A19 | B71: =B19 | C71: =IF(ISBLANK(C19),"NO DATA",IF(ISNUMBER(FIND(CODES!$A$12,C19)),CODES!$A$12,IF(OR(ISNUMBER(FIND(CODES!$A$10,C19)),ISNUMBER(FIND(CODES!$A$11,C19))),CODES!$A$13,IF(OR(C19<C$63,ISNUMBER(C19)=FALSE),C$64,C19)))) | D71: =IF(ISBLANK(D19),"NO DATA",IF(ISNUMBER(FIND(CODES!$A$12,D19)),CODES!$A$12,IF(OR(ISNUMBER(FIND(CODES!$A$10,D19)),ISNUMBER(FIND(CODES!$A$11,D19))),CODES!$A$13,IF(OR(D19<D$63,ISNUMBER(D19)=FALSE),D$64,D19)))) | E71: =IF(ISBLANK(E19),"NO DATA",IF(ISNUMBER(FIND(CODES!$A$12,E19)),CODES!$A$12,IF(OR(ISNUMBER(FIND(CODES!$A$10,E19)),ISNUMBER(FIND(CODES!$A$11,E19))),CODES!$A$13,IF(OR(E19<E$63,ISNUMBER(E19)=FALSE),E$64,E19)))) | F71: =IF(ISBLANK(F19),"NO DATA",IF(ISNUMBER(FIND(CODES!$A$12,F19)),CODES!$A$12,IF(OR(ISNUMBER(FIND(CODES!$A$10,F19)),ISNUMBER(FIND(CODES!$A$11,F19))),CODES!$A$13,IF(OR(F19<F$63,ISNUMBER(F19)=FALSE),F$64,F19)))) | G71: =IF(ISBLANK(G19),"NO DATA",IF(ISNUMBER(FIND(CODES!$A$12,G19)),CODES!$A$12,IF(OR(ISNUMBER(FIND(CODES!$A$10,G19)),ISNUMBER(FIND(CODES!$A$11,G19))),CODES!$A$13,IF(OR(G19<G$63,ISNUMBER(G19)=FALSE),G$64,G19)))) | H71: =IF(ISBLANK(H19),"NO DATA",IF(ISNUMBER(FIND(CODES!$A$12,H19)),CODES!$A$12,IF(OR(ISNUMBER(FIND(CODES!$A$10,H19)),ISNUMBER(FIND(CODES!$A$11,H19))),CODES!$A$13,IF(OR(H19<H$63,ISNUMBER(H19)=FALSE),H$64,H19)))) | I71: =IF(ISBLANK(I19),"NO DATA",IF(ISNUMBER(FIND(CODES!$A$12,I19)),CODES!$A$12,IF(OR(ISNUMBER(FIND(CODES!$A$10,I19)),ISNUMBER(FIND(CODES!$A$11,I19))),CODES!$A$13,IF(OR(I19<I$63,ISNUMBER(I19)=FALSE),I$64,I19)))) | J71: =IF(ISBLANK(J19),"NO DATA",IF(ISNUMBER(FIND(CODES!$A$12,J19)),CODES!$A$12,IF(OR(ISNUMBER(FIND(CODES!$A$10,J19)),ISNUMBER(FIND(CODES!$A$11,J19))),CODES!$A$13,IF(OR(J19<J$63,ISNUMBER(J19)=FALSE),J$64,J19)))) | ... DI71: =IF(ISBLANK(DI19),"NO DATA",IF(ISNUMBER(FIND(CODES!$A$12,DI19)),CODES!$A$12,IF(OR(ISNUMBER(FIND(CODES!$A$10,DI19)),ISNUMBER(FIND(CODES!$A$11,DI19))),CODES!$A$13,IF(OR(DI19<DI$63,ISNUMBER(DI19)=FALSE),DI$64,DI19))))
A72: =A20 | B72: =B20 | C72: =IF(ISBLANK(C20),"NO DATA",IF(ISNUMBER(FIND(CODES!$A$12,C20)),CODES!$A$12,IF(OR(ISNUMBER(FIND(CODES!$A$10,C20)),ISNUMBER(FIND(CODES!$A$11,C20))),CODES!$A$13,IF(OR(C20<C$63,ISNUMBER(C20)=FALSE),C$64,C20)))) | D72: =IF(ISBLANK(D20),"NO DATA",IF(ISNUMBER(FIND(CODES!$A$12,D20)),CODES!$A$12,IF(OR(ISNUMBER(FIND(CODES!$A$10,D20)),ISNUMBER(FIND(CODES!$A$11,D20))),CODES!$A$13,IF(OR(D20<D$63,ISNUMBER(D20)=FALSE),D$64,D20)))) | E72: =IF(ISBLANK(E20),"NO DATA",IF(ISNUMBER(FIND(CODES!$A$12,E20)),CODES!$A$12,IF(OR(ISNUMBER(FIND(CODES!$A$10,E20)),ISNUMBER(FIND(CODES!$A$11,E20))),CODES!$A$13,IF(OR(E20<E$63,ISNUMBER(E20)=FALSE),E$64,E20)))) | F72: =IF(ISBLANK(F20),"NO DATA",IF(ISNUMBER(FIND(CODES!$A$12,F20)),CODES!$A$12,IF(OR(ISNUMBER(FIND(CODES!$A$10,F20)),ISNUMBER(FIND(CODES!$A$11,F20))),CODES!$A$13,IF(OR(F20<F$63,ISNUMBER(F20)=FALSE),F$64,F20)))) | G72: =IF(ISBLANK(G20),"NO DATA",IF(ISNUMBER(FIND(CODES!$A$12,G20)),CODES!$A$12,IF(OR(ISNUMBER(FIND(CODES!$A$10,G20)),ISNUMBER(FIND(CODES!$A$11,G20))),CODES!$A$13,IF(OR(G20<G$63,ISNUMBER(G20)=FALSE),G$64,G20)))) | H72: =IF(ISBLANK(H20),"NO DATA",IF(ISNUMBER(FIND(CODES!$A$12,H20)),CODES!$A$12,IF(OR(ISNUMBER(FIND(CODES!$A$10,H20)),ISNUMBER(FIND(CODES!$A$11,H20))),CODES!$A$13,IF(OR(H20<H$63,ISNUMBER(H20)=FALSE),H$64,H20)))) | I72: =IF(ISBLANK(I20),"NO DATA",IF(ISNUMBER(FIND(CODES!$A$12,I20)),CODES!$A$12,IF(OR(ISNUMBER(FIND(CODES!$A$10,I20)),ISNUMBER(FIND(CODES!$A$11,I20))),CODES!$A$13,IF(OR(I20<I$63,ISNUMBER(I20)=FALSE),I$64,I20)))) | J72: =IF(ISBLANK(J20),"NO DATA",IF(ISNUMBER(FIND(CODES!$A$12,J20)),CODES!$A$12,IF(OR(ISNUMBER(FIND(CODES!$A$10,J20)),ISNUMBER(FIND(CODES!$A$11,J20))),CODES!$A$13,IF(OR(J20<J$63,ISNUMBER(J20)=FALSE),J$64,J20)))) | ... DI72: =IF(ISBLANK(DI20),"NO DATA",IF(ISNUMBER(FIND(CODES!$A$12,DI20)),CODES!$A$12,IF(OR(ISNUMBER(FIND(CODES!$A$10,DI20)),ISNUMBER(FIND(CODES!$A$11,DI20))),CODES!$A$13,IF(OR(DI20<DI$63,ISNUMBER(DI20)=FALSE),DI$64,DI20))))
A73: =A21 | B73: =B21 | C73: =IF(ISBLANK(C21),"NO DATA",IF(ISNUMBER(FIND(CODES!$A$12,C21)),CODES!$A$12,IF(OR(ISNUMBER(FIND(CODES!$A$10,C21)),ISNUMBER(FIND(CODES!$A$11,C21))),CODES!$A$13,IF(OR(C21<C$63,ISNUMBER(C21)=FALSE),C$64,C21)))) | D73: =IF(ISBLANK(D21),"NO DATA",IF(ISNUMBER(FIND(CODES!$A$12,D21)),CODES!$A$12,IF(OR(ISNUMBER(FIND(CODES!$A$10,D21)),ISNUMBER(FIND(CODES!$A$11,D21))),CODES!$A$13,IF(OR(D21<D$63,ISNUMBER(D21)=FALSE),D$64,D21)))) | E73: =IF(ISBLANK(E21),"NO DATA",IF(ISNUMBER(FIND(CODES!$A$12,E21)),CODES!$A$12,IF(OR(ISNUMBER(FIND(CODES!$A$10,E21)),ISNUMBER(FIND(CODES!$A$11,E21))),CODES!$A$13,IF(OR(E21<E$63,ISNUMBER(E21)=FALSE),E$64,E21)))) | F73: =IF(ISBLANK(F21),"NO DATA",IF(ISNUMBER(FIND(CODES!$A$12,F21)),CODES!$A$12,IF(OR(ISNUMBER(FIND(CODES!$A$10,F21)),ISNUMBER(FIND(CODES!$A$11,F21))),CODES!$A$13,IF(OR(F21<F$63,ISNUMBER(F21)=FALSE),F$64,F21)))) | G73: =IF(ISBLANK(G21),"NO DATA",IF(ISNUMBER(FIND(CODES!$A$12,G21)),CODES!$A$12,IF(OR(ISNUMBER(FIND(CODES!$A$10,G21)),ISNUMBER(FIND(CODES!$A$11,G21))),CODES!$A$13,IF(OR(G21<G$63,ISNUMBER(G21)=FALSE),G$64,G21)))) | H73: =IF(ISBLANK(H21),"NO DATA",IF(ISNUMBER(FIND(CODES!$A$12,H21)),CODES!$A$12,IF(OR(ISNUMBER(FIND(CODES!$A$10,H21)),ISNUMBER(FIND(CODES!$A$11,H21))),CODES!$A$13,IF(OR(H21<H$63,ISNUMBER(H21)=FALSE),H$64,H21)))) | I73: =IF(ISBLANK(I21),"NO DATA",IF(ISNUMBER(FIND(CODES!$A$12,I21)),CODES!$A$12,IF(OR(ISNUMBER(FIND(CODES!$A$10,I21)),ISNUMBER(FIND(CODES!$A$11,I21))),CODES!$A$13,IF(OR(I21<I$63,ISNUMBER(I21)=FALSE),I$64,I21)))) | J73: =IF(ISBLANK(J21),"NO DATA",IF(ISNUMBER(FIND(CODES!$A$12,J21)),CODES!$A$12,IF(OR(ISNUMBER(FIND(CODES!$A$10,J21)),ISNUMBER(FIND(CODES!$A$11,J21))),CODES!$A$13,IF(OR(J21<J$63,ISNUMBER(J21)=FALSE),J$64,J21)))) | ... DI73: =IF(ISBLANK(DI21),"NO DATA",IF(ISNUMBER(FIND(CODES!$A$12,DI21)),CODES!$A$12,IF(OR(ISNUMBER(FIND(CODES!$A$10,DI21)),ISNUMBER(FIND(CODES!$A$11,DI21))),CODES!$A$13,IF(OR(DI21<DI$63,ISNUMBER(DI21)=FALSE),DI$64,DI21))))
A74: =A22 | B74: =B22 | C74: =IF(ISBLANK(C22),"NO DATA",IF(ISNUMBER(FIND(CODES!$A$12,C22)),CODES!$A$12,IF(OR(ISNUMBER(FIND(CODES!$A$10,C22)),ISNUMBER(FIND(CODES!$A$11,C22))),CODES!$A$13,IF(OR(C22<C$63,ISNUMBER(C22)=FALSE),C$64,C22)))) | D74: =IF(ISBLANK(D22),"NO DATA",IF(ISNUMBER(FIND(CODES!$A$12,D22)),CODES!$A$12,IF(OR(ISNUMBER(FIND(CODES!$A$10,D22)),ISNUMBER(FIND(CODES!$A$11,D22))),CODES!$A$13,IF(OR(D22<D$63,ISNUMBER(D22)=FALSE),D$64,D22)))) | E74: =IF(ISBLANK(E22),"NO DATA",IF(ISNUMBER(FIND(CODES!$A$12,E22)),CODES!$A$12,IF(OR(ISNUMBER(FIND(CODES!$A$10,E22)),ISNUMBER(FIND(CODES!$A$11,E22))),CODES!$A$13,IF(OR(E22<E$63,ISNUMBER(E22)=FALSE),E$64,E22)))) | F74: =IF(ISBLANK(F22),"NO DATA",IF(ISNUMBER(FIND(CODES!$A$12,F22)),CODES!$A$12,IF(OR(ISNUMBER(FIND(CODES!$A$10,F22)),ISNUMBER(FIND(CODES!$A$11,F22))),CODES!$A$13,IF(OR(F22<F$63,ISNUMBER(F22)=FALSE),F$64,F22)))) | G74: =IF(ISBLANK(G22),"NO DATA",IF(ISNUMBER(FIND(CODES!$A$12,G22)),CODES!$A$12,IF(OR(ISNUMBER(FIND(CODES!$A$10,G22)),ISNUMBER(FIND(CODES!$A$11,G22))),CODES!$A$13,IF(OR(G22<G$63,ISNUMBER(G22)=FALSE),G$64,G22)))) | H74: =IF(ISBLANK(H22),"NO DATA",IF(ISNUMBER(FIND(CODES!$A$12,H22)),CODES!$A$12,IF(OR(ISNUMBER(FIND(CODES!$A$10,H22)),ISNUMBER(FIND(CODES!$A$11,H22))),CODES!$A$13,IF(OR(H22<H$63,ISNUMBER(H22)=FALSE),H$64,H22)))) | I74: =IF(ISBLANK(I22),"NO DATA",IF(ISNUMBER(FIND(CODES!$A$12,I22)),CODES!$A$12,IF(OR(ISNUMBER(FIND(CODES!$A$10,I22)),ISNUMBER(FIND(CODES!$A$11,I22))),CODES!$A$13,IF(OR(I22<I$63,ISNUMBER(I22)=FALSE),I$64,I22)))) | J74: =IF(ISBLANK(J22),"NO DATA",IF(ISNUMBER(FIND(CODES!$A$12,J22)),CODES!$A$12,IF(OR(ISNUMBER(FIND(CODES!$A$10,J22)),ISNUMBER(FIND(CODES!$A$11,J22))),CODES!$A$13,IF(OR(J22<J$63,ISNUMBER(J22)=FALSE),J$64,J22)))) | ... DI74: =IF(ISBLANK(DI22),"NO DATA",IF(ISNUMBER(FIND(CODES!$A$12,DI22)),CODES!$A$12,IF(OR(ISNUMBER(FIND(CODES!$A$10,DI22)),ISNUMBER(FIND(CODES!$A$11,DI22))),CODES!$A$13,IF(OR(DI22<DI$63,ISNUMBER(DI22)=FALSE),DI$64,DI22))))
A75: =A23 | B75: =B23 | C75: =IF(ISBLANK(C23),"NO DATA",IF(ISNUMBER(FIND(CODES!$A$12,C23)),CODES!$A$12,IF(OR(ISNUMBER(FIND(CODES!$A$10,C23)),ISNUMBER(FIND(CODES!$A$11,C23))),CODES!$A$13,IF(OR(C23<C$63,ISNUMBER(C23)=FALSE),C$64,C23)))) | D75: =IF(ISBLANK(D23),"NO DATA",IF(ISNUMBER(FIND(CODES!$A$12,D23)),CODES!$A$12,IF(OR(ISNUMBER(FIND(CODES!$A$10,D23)),ISNUMBER(FIND(CODES!$A$11,D23))),CODES!$A$13,IF(OR(D23<D$63,ISNUMBER(D23)=FALSE),D$64,D23)))) | E75: =IF(ISBLANK(E23),"NO DATA",IF(ISNUMBER(FIND(CODES!$A$12,E23)),CODES!$A$12,IF(OR(ISNUMBER(FIND(CODES!$A$10,E23)),ISNUMBER(FIND(CODES!$A$11,E23))),CODES!$A$13,IF(OR(E23<E$63,ISNUMBER(E23)=FALSE),E$64,E23)))) | F75: =IF(ISBLANK(F23),"NO DATA",IF(ISNUMBER(FIND(CODES!$A$12,F23)),CODES!$A$12,IF(OR(ISNUMBER(FIND(CODES!$A$10,F23)),ISNUMBER(FIND(CODES!$A$11,F23))),CODES!$A$13,IF(OR(F23<F$63,ISNUMBER(F23)=FALSE),F$64,F23)))) | G75: =IF(ISBLANK(G23),"NO DATA",IF(ISNUMBER(FIND(CODES!$A$12,G23)),CODES!$A$12,IF(OR(ISNUMBER(FIND(CODES!$A$10,G23)),ISNUMBER(FIND(CODES!$A$11,G23))),CODES!$A$13,IF(OR(G23<G$63,ISNUMBER(G23)=FALSE),G$64,G23)))) | H75: =IF(ISBLANK(H23),"NO DATA",IF(ISNUMBER(FIND(CODES!$A$12,H23)),CODES!$A$12,IF(OR(ISNUMBER(FIND(CODES!$A$10,H23)),ISNUMBER(FIND(CODES!$A$11,H23))),CODES!$A$13,IF(OR(H23<H$63,ISNUMBER(H23)=FALSE),H$64,H23)))) | I75: =IF(ISBLANK(I23),"NO DATA",IF(ISNUMBER(FIND(CODES!$A$12,I23)),CODES!$A$12,IF(OR(ISNUMBER(FIND(CODES!$A$10,I23)),ISNUMBER(FIND(CODES!$A$11,I23))),CODES!$A$13,IF(OR(I23<I$63,ISNUMBER(I23)=FALSE),I$64,I23)))) | J75: =IF(ISBLANK(J23),"NO DATA",IF(ISNUMBER(FIND(CODES!$A$12,J23)),CODES!$A$12,IF(OR(ISNUMBER(FIND(CODES!$A$10,J23)),ISNUMBER(FIND(CODES!$A$11,J23))),CODES!$A$13,IF(OR(J23<J$63,ISNUMBER(J23)=FALSE),J$64,J23)))) | ... DI75: =IF(ISBLANK(DI23),"NO DATA",IF(ISNUMBER(FIND(CODES!$A$12,DI23)),CODES!$A$12,IF(OR(ISNUMBER(FIND(CODES!$A$10,DI23)),ISNUMBER(FIND(CODES!$A$11,DI23))),CODES!$A$13,IF(OR(DI23<DI$63,ISNUMBER(DI23)=FALSE),DI$64,DI23))))
A76: =A24 | B76: =B24 | C76: =IF(ISBLANK(C24),"NO DATA",IF(ISNUMBER(FIND(CODES!$A$12,C24)),CODES!$A$12,IF(OR(ISNUMBER(FIND(CODES!$A$10,C24)),ISNUMBER(FIND(CODES!$A$11,C24))),CODES!$A$13,IF(OR(C24<C$63,ISNUMBER(C24)=FALSE),C$64,C24)))) | D76: =IF(ISBLANK(D24),"NO DATA",IF(ISNUMBER(FIND(CODES!$A$12,D24)),CODES!$A$12,IF(OR(ISNUMBER(FIND(CODES!$A$10,D24)),ISNUMBER(FIND(CODES!$A$11,D24))),CODES!$A$13,IF(OR(D24<D$63,ISNUMBER(D24)=FALSE),D$64,D24)))) | E76: =IF(ISBLANK(E24),"NO DATA",IF(ISNUMBER(FIND(CODES!$A$12,E24)),CODES!$A$12,IF(OR(ISNUMBER(FIND(CODES!$A$10,E24)),ISNUMBER(FIND(CODES!$A$11,E24))),CODES!$A$13,IF(OR(E24<E$63,ISNUMBER(E24)=FALSE),E$64,E24)))) | F76: =IF(ISBLANK(F24),"NO DATA",IF(ISNUMBER(FIND(CODES!$A$12,F24)),CODES!$A$12,IF(OR(ISNUMBER(FIND(CODES!$A$10,F24)),ISNUMBER(FIND(CODES!$A$11,F24))),CODES!$A$13,IF(OR(F24<F$63,ISNUMBER(F24)=FALSE),F$64,F24)))) | G76: =IF(ISBLANK(G24),"NO DATA",IF(ISNUMBER(FIND(CODES!$A$12,G24)),CODES!$A$12,IF(OR(ISNUMBER(FIND(CODES!$A$10,G24)),ISNUMBER(FIND(CODES!$A$11,G24))),CODES!$A$13,IF(OR(G24<G$63,ISNUMBER(G24)=FALSE),G$64,G24)))) | H76: =IF(ISBLANK(H24),"NO DATA",IF(ISNUMBER(FIND(CODES!$A$12,H24)),CODES!$A$12,IF(OR(ISNUMBER(FIND(CODES!$A$10,H24)),ISNUMBER(FIND(CODES!$A$11,H24))),CODES!$A$13,IF(OR(H24<H$63,ISNUMBER(H24)=FALSE),H$64,H24)))) | I76: =IF(ISBLANK(I24),"NO DATA",IF(ISNUMBER(FIND(CODES!$A$12,I24)),CODES!$A$12,IF(OR(ISNUMBER(FIND(CODES!$A$10,I24)),ISNUMBER(FIND(CODES!$A$11,I24))),CODES!$A$13,IF(OR(I24<I$63,ISNUMBER(I24)=FALSE),I$64,I24)))) | J76: =IF(ISBLANK(J24),"NO DATA",IF(ISNUMBER(FIND(CODES!$A$12,J24)),CODES!$A$12,IF(OR(ISNUMBER(FIND(CODES!$A$10,J24)),ISNUMBER(FIND(CODES!$A$11,J24))),CODES!$A$13,IF(OR(J24<J$63,ISNUMBER(J24)=FALSE),J$64,J24)))) | ... DI76: =IF(ISBLANK(DI24),"NO DATA",IF(ISNUMBER(FIND(CODES!$A$12,DI24)),CODES!$A$12,IF(OR(ISNUMBER(FIND(CODES!$A$10,DI24)),ISNUMBER(FIND(CODES!$A$11,DI24))),CODES!$A$13,IF(OR(DI24<DI$63,ISNUMBER(DI24)=FALSE),DI$64,DI24))))
A77: =A25 | B77: =B25 | C77: =IF(ISBLANK(C25),"NO DATA",IF(ISNUMBER(FIND(CODES!$A$12,C25)),CODES!$A$12,IF(OR(ISNUMBER(FIND(CODES!$A$10,C25)),ISNUMBER(FIND(CODES!$A$11,C25))),CODES!$A$13,IF(OR(C25<C$63,ISNUMBER(C25)=FALSE),C$64,C25)))) | D77: =IF(ISBLANK(D25),"NO DATA",IF(ISNUMBER(FIND(CODES!$A$12,D25)),CODES!$A$12,IF(OR(ISNUMBER(FIND(CODES!$A$10,D25)),ISNUMBER(FIND(CODES!$A$11,D25))),CODES!$A$13,IF(OR(D25<D$63,ISNUMBER(D25)=FALSE),D$64,D25)))) | E77: =IF(ISBLANK(E25),"NO DATA",IF(ISNUMBER(FIND(CODES!$A$12,E25)),CODES!$A$12,IF(OR(ISNUMBER(FIND(CODES!$A$10,E25)),ISNUMBER(FIND(CODES!$A$11,E25))),CODES!$A$13,IF(OR(E25<E$63,ISNUMBER(E25)=FALSE),E$64,E25)))) | F77: =IF(ISBLANK(F25),"NO DATA",IF(ISNUMBER(FIND(CODES!$A$12,F25)),CODES!$A$12,IF(OR(ISNUMBER(FIND(CODES!$A$10,F25)),ISNUMBER(FIND(CODES!$A$11,F25))),CODES!$A$13,IF(OR(F25<F$63,ISNUMBER(F25)=FALSE),F$64,F25)))) | G77: =IF(ISBLANK(G25),"NO DATA",IF(ISNUMBER(FIND(CODES!$A$12,G25)),CODES!$A$12,IF(OR(ISNUMBER(FIND(CODES!$A$10,G25)),ISNUMBER(FIND(CODES!$A$11,G25))),CODES!$A$13,IF(OR(G25<G$63,ISNUMBER(G25)=FALSE),G$64,G25)))) | H77: =IF(ISBLANK(H25),"NO DATA",IF(ISNUMBER(FIND(CODES!$A$12,H25)),CODES!$A$12,IF(OR(ISNUMBER(FIND(CODES!$A$10,H25)),ISNUMBER(FIND(CODES!$A$11,H25))),CODES!$A$13,IF(OR(H25<H$63,ISNUMBER(H25)=FALSE),H$64,H25)))) | I77: =IF(ISBLANK(I25),"NO DATA",IF(ISNUMBER(FIND(CODES!$A$12,I25)),CODES!$A$12,IF(OR(ISNUMBER(FIND(CODES!$A$10,I25)),ISNUMBER(FIND(CODES!$A$11,I25))),CODES!$A$13,IF(OR(I25<I$63,ISNUMBER(I25)=FALSE),I$64,I25)))) | J77: =IF(ISBLANK(J25),"NO DATA",IF(ISNUMBER(FIND(CODES!$A$12,J25)),CODES!$A$12,IF(OR(ISNUMBER(FIND(CODES!$A$10,J25)),ISNUMBER(FIND(CODES!$A$11,J25))),CODES!$A$13,IF(OR(J25<J$63,ISNUMBER(J25)=FALSE),J$64,J25)))) | ... DI77: =IF(ISBLANK(DI25),"NO DATA",IF(ISNUMBER(FIND(CODES!$A$12,DI25)),CODES!$A$12,IF(OR(ISNUMBER(FIND(CODES!$A$10,DI25)),ISNUMBER(FIND(CODES!$A$11,DI25))),CODES!$A$13,IF(OR(DI25<DI$63,ISNUMBER(DI25)=FALSE),DI$64,DI25))))
A78: =A26 | B78: =B26 | C78: =IF(ISBLANK(C26),"NO DATA",IF(ISNUMBER(FIND(CODES!$A$12,C26)),CODES!$A$12,IF(OR(ISNUMBER(FIND(CODES!$A$10,C26)),ISNUMBER(FIND(CODES!$A$11,C26))),CODES!$A$13,IF(OR(C26<C$63,ISNUMBER(C26)=FALSE),C$64,C26)))) | D78: =IF(ISBLANK(D26),"NO DATA",IF(ISNUMBER(FIND(CODES!$A$12,D26)),CODES!$A$12,IF(OR(ISNUMBER(FIND(CODES!$A$10,D26)),ISNUMBER(FIND(CODES!$A$11,D26))),CODES!$A$13,IF(OR(D26<D$63,ISNUMBER(D26)=FALSE),D$64,D26)))) | E78: =IF(ISBLANK(E26),"NO DATA",IF(ISNUMBER(FIND(CODES!$A$12,E26)),CODES!$A$12,IF(OR(ISNUMBER(FIND(CODES!$A$10,E26)),ISNUMBER(FIND(CODES!$A$11,E26))),CODES!$A$13,IF(OR(E26<E$63,ISNUMBER(E26)=FALSE),E$64,E26)))) | F78: =IF(ISBLANK(F26),"NO DATA",IF(ISNUMBER(FIND(CODES!$A$12,F26)),CODES!$A$12,IF(OR(ISNUMBER(FIND(CODES!$A$10,F26)),ISNUMBER(FIND(CODES!$A$11,F26))),CODES!$A$13,IF(OR(F26<F$63,ISNUMBER(F26)=FALSE),F$64,F26)))) | G78: =IF(ISBLANK(G26),"NO DATA",IF(ISNUMBER(FIND(CODES!$A$12,G26)),CODES!$A$12,IF(OR(ISNUMBER(FIND(CODES!$A$10,G26)),ISNUMBER(FIND(CODES!$A$11,G26))),CODES!$A$13,IF(OR(G26<G$63,ISNUMBER(G26)=FALSE),G$64,G26)))) | H78: =IF(ISBLANK(H26),"NO DATA",IF(ISNUMBER(FIND(CODES!$A$12,H26)),CODES!$A$12,IF(OR(ISNUMBER(FIND(CODES!$A$10,H26)),ISNUMBER(FIND(CODES!$A$11,H26))),CODES!$A$13,IF(OR(H26<H$63,ISNUMBER(H26)=FALSE),H$64,H26)))) | I78: =IF(ISBLANK(I26),"NO DATA",IF(ISNUMBER(FIND(CODES!$A$12,I26)),CODES!$A$12,IF(OR(ISNUMBER(FIND(CODES!$A$10,I26)),ISNUMBER(FIND(CODES!$A$11,I26))),CODES!$A$13,IF(OR(I26<I$63,ISNUMBER(I26)=FALSE),I$64,I26)))) | J78: =IF(ISBLANK(J26),"NO DATA",IF(ISNUMBER(FIND(CODES!$A$12,J26)),CODES!$A$12,IF(OR(ISNUMBER(FIND(CODES!$A$10,J26)),ISNUMBER(FIND(CODES!$A$11,J26))),CODES!$A$13,IF(OR(J26<J$63,ISNUMBER(J26)=FALSE),J$64,J26)))) | ... DI78: =IF(ISBLANK(DI26),"NO DATA",IF(ISNUMBER(FIND(CODES!$A$12,DI26)),CODES!$A$12,IF(OR(ISNUMBER(FIND(CODES!$A$10,DI26)),ISNUMBER(FIND(CODES!$A$11,DI26))),CODES!$A$13,IF(OR(DI26<DI$63,ISNUMBER(DI26)=FALSE),DI$64,DI26))))
A79: =A27 | B79: =B27 | C79: =IF(ISBLANK(C27),"NO DATA",IF(ISNUMBER(FIND(CODES!$A$12,C27)),CODES!$A$12,IF(OR(ISNUMBER(FIND(CODES!$A$10,C27)),ISNUMBER(FIND(CODES!$A$11,C27))),CODES!$A$13,IF(OR(C27<C$63,ISNUMBER(C27)=FALSE),C$64,C27)))) | D79: =IF(ISBLANK(D27),"NO DATA",IF(ISNUMBER(FIND(CODES!$A$12,D27)),CODES!$A$12,IF(OR(ISNUMBER(FIND(CODES!$A$10,D27)),ISNUMBER(FIND(CODES!$A$11,D27))),CODES!$A$13,IF(OR(D27<D$63,ISNUMBER(D27)=FALSE),D$64,D27)))) | E79: =IF(ISBLANK(E27),"NO DATA",IF(ISNUMBER(FIND(CODES!$A$12,E27)),CODES!$A$12,IF(OR(ISNUMBER(FIND(CODES!$A$10,E27)),ISNUMBER(FIND(CODES!$A$11,E27))),CODES!$A$13,IF(OR(E27<E$63,ISNUMBER(E27)=FALSE),E$64,E27)))) | F79: =IF(ISBLANK(F27),"NO DATA",IF(ISNUMBER(FIND(CODES!$A$12,F27)),CODES!$A$12,IF(OR(ISNUMBER(FIND(CODES!$A$10,F27)),ISNUMBER(FIND(CODES!$A$11,F27))),CODES!$A$13,IF(OR(F27<F$63,ISNUMBER(F27)=FALSE),F$64,F27)))) | G79: =IF(ISBLANK(G27),"NO DATA",IF(ISNUMBER(FIND(CODES!$A$12,G27)),CODES!$A$12,IF(OR(ISNUMBER(FIND(CODES!$A$10,G27)),ISNUMBER(FIND(CODES!$A$11,G27))),CODES!$A$13,IF(OR(G27<G$63,ISNUMBER(G27)=FALSE),G$64,G27)))) | H79: =IF(ISBLANK(H27),"NO DATA",IF(ISNUMBER(FIND(CODES!$A$12,H27)),CODES!$A$12,IF(OR(ISNUMBER(FIND(CODES!$A$10,H27)),ISNUMBER(FIND(CODES!$A$11,H27))),CODES!$A$13,IF(OR(H27<H$63,ISNUMBER(H27)=FALSE),H$64,H27)))) | I79: =IF(ISBLANK(I27),"NO DATA",IF(ISNUMBER(FIND(CODES!$A$12,I27)),CODES!$A$12,IF(OR(ISNUMBER(FIND(CODES!$A$10,I27)),ISNUMBER(FIND(CODES!$A$11,I27))),CODES!$A$13,IF(OR(I27<I$63,ISNUMBER(I27)=FALSE),I$64,I27)))) | J79: =IF(ISBLANK(J27),"NO DATA",IF(ISNUMBER(FIND(CODES!$A$12,J27)),CODES!$A$12,IF(OR(ISNUMBER(FIND(CODES!$A$10,J27)),ISNUMBER(FIND(CODES!$A$11,J27))),CODES!$A$13,IF(OR(J27<J$63,ISNUMBER(J27)=FALSE),J$64,J27)))) | ... DI79: =IF(ISBLANK(DI27),"NO DATA",IF(ISNUMBER(FIND(CODES!$A$12,DI27)),CODES!$A$12,IF(OR(ISNUMBER(FIND(CODES!$A$10,DI27)),ISNUMBER(FIND(CODES!$A$11,DI27))),CODES!$A$13,IF(OR(DI27<DI$63,ISNUMBER(DI27)=FALSE),DI$64,DI27))))
A80: =A28 | B80: =B28 | C80: =IF(ISBLANK(C28),"NO DATA",IF(ISNUMBER(FIND(CODES!$A$12,C28)),CODES!$A$12,IF(OR(ISNUMBER(FIND(CODES!$A$10,C28)),ISNUMBER(FIND(CODES!$A$11,C28))),CODES!$A$13,IF(OR(C28<C$63,ISNUMBER(C28)=FALSE),C$64,C28)))) | D80: =IF(ISBLANK(D28),"NO DATA",IF(ISNUMBER(FIND(CODES!$A$12,D28)),CODES!$A$12,IF(OR(ISNUMBER(FIND(CODES!$A$10,D28)),ISNUMBER(FIND(CODES!$A$11,D28))),CODES!$A$13,IF(OR(D28<D$63,ISNUMBER(D28)=FALSE),D$64,D28)))) | E80: =IF(ISBLANK(E28),"NO DATA",IF(ISNUMBER(FIND(CODES!$A$12,E28)),CODES!$A$12,IF(OR(ISNUMBER(FIND(CODES!$A$10,E28)),ISNUMBER(FIND(CODES!$A$11,E28))),CODES!$A$13,IF(OR(E28<E$63,ISNUMBER(E28)=FALSE),E$64,E28)))) | F80: =IF(ISBLANK(F28),"NO DATA",IF(ISNUMBER(FIND(CODES!$A$12,F28)),CODES!$A$12,IF(OR(ISNUMBER(FIND(CODES!$A$10,F28)),ISNUMBER(FIND(CODES!$A$11,F28))),CODES!$A$13,IF(OR(F28<F$63,ISNUMBER(F28)=FALSE),F$64,F28)))) | G80: =IF(ISBLANK(G28),"NO DATA",IF(ISNUMBER(FIND(CODES!$A$12,G28)),CODES!$A$12,IF(OR(ISNUMBER(FIND(CODES!$A$10,G28)),ISNUMBER(FIND(CODES!$A$11,G28))),CODES!$A$13,IF(OR(G28<G$63,ISNUMBER(G28)=FALSE),G$64,G28)))) | H80: =IF(ISBLANK(H28),"NO DATA",IF(ISNUMBER(FIND(CODES!$A$12,H28)),CODES!$A$12,IF(OR(ISNUMBER(FIND(CODES!$A$10,H28)),ISNUMBER(FIND(CODES!$A$11,H28))),CODES!$A$13,IF(OR(H28<H$63,ISNUMBER(H28)=FALSE),H$64,H28)))) | I80: =IF(ISBLANK(I28),"NO DATA",IF(ISNUMBER(FIND(CODES!$A$12,I28)),CODES!$A$12,IF(OR(ISNUMBER(FIND(CODES!$A$10,I28)),ISNUMBER(FIND(CODES!$A$11,I28))),CODES!$A$13,IF(OR(I28<I$63,ISNUMBER(I28)=FALSE),I$64,I28)))) | J80: =IF(ISBLANK(J28),"NO DATA",IF(ISNUMBER(FIND(CODES!$A$12,J28)),CODES!$A$12,IF(OR(ISNUMBER(FIND(CODES!$A$10,J28)),ISNUMBER(FIND(CODES!$A$11,J28))),CODES!$A$13,IF(OR(J28<J$63,ISNUMBER(J28)=FALSE),J$64,J28)))) | ... DI80: =IF(ISBLANK(DI28),"NO DATA",IF(ISNUMBER(FIND(CODES!$A$12,DI28)),CODES!$A$12,IF(OR(ISNUMBER(FIND(CODES!$A$10,DI28)),ISNUMBER(FIND(CODES!$A$11,DI28))),CODES!$A$13,IF(OR(DI28<DI$63,ISNUMBER(DI28)=FALSE),DI$64,DI28))))
A81: =A29 | B81: =B29 | C81: =IF(ISBLANK(C29),"NO DATA",IF(ISNUMBER(FIND(CODES!$A$12,C29)),CODES!$A$12,IF(OR(ISNUMBER(FIND(CODES!$A$10,C29)),ISNUMBER(FIND(CODES!$A$11,C29))),CODES!$A$13,IF(OR(C29<C$63,ISNUMBER(C29)=FALSE),C$64,C29)))) | D81: =IF(ISBLANK(D29),"NO DATA",IF(ISNUMBER(FIND(CODES!$A$12,D29)),CODES!$A$12,IF(OR(ISNUMBER(FIND(CODES!$A$10,D29)),ISNUMBER(FIND(CODES!$A$11,D29))),CODES!$A$13,IF(OR(D29<D$63,ISNUMBER(D29)=FALSE),D$64,D29)))) | E81: =IF(ISBLANK(E29),"NO DATA",IF(ISNUMBER(FIND(CODES!$A$12,E29)),CODES!$A$12,IF(OR(ISNUMBER(FIND(CODES!$A$10,E29)),ISNUMBER(FIND(CODES!$A$11,E29))),CODES!$A$13,IF(OR(E29<E$63,ISNUMBER(E29)=FALSE),E$64,E29)))) | F81: =IF(ISBLANK(F29),"NO DATA",IF(ISNUMBER(FIND(CODES!$A$12,F29)),CODES!$A$12,IF(OR(ISNUMBER(FIND(CODES!$A$10,F29)),ISNUMBER(FIND(CODES!$A$11,F29))),CODES!$A$13,IF(OR(F29<F$63,ISNUMBER(F29)=FALSE),F$64,F29)))) | G81: =IF(ISBLANK(G29),"NO DATA",IF(ISNUMBER(FIND(CODES!$A$12,G29)),CODES!$A$12,IF(OR(ISNUMBER(FIND(CODES!$A$10,G29)),ISNUMBER(FIND(CODES!$A$11,G29))),CODES!$A$13,IF(OR(G29<G$63,ISNUMBER(G29)=FALSE),G$64,G29)))) | H81: =IF(ISBLANK(H29),"NO DATA",IF(ISNUMBER(FIND(CODES!$A$12,H29)),CODES!$A$12,IF(OR(ISNUMBER(FIND(CODES!$A$10,H29)),ISNUMBER(FIND(CODES!$A$11,H29))),CODES!$A$13,IF(OR(H29<H$63,ISNUMBER(H29)=FALSE),H$64,H29)))) | I81: =IF(ISBLANK(I29),"NO DATA",IF(ISNUMBER(FIND(CODES!$A$12,I29)),CODES!$A$12,IF(OR(ISNUMBER(FIND(CODES!$A$10,I29)),ISNUMBER(FIND(CODES!$A$11,I29))),CODES!$A$13,IF(OR(I29<I$63,ISNUMBER(I29)=FALSE),I$64,I29)))) | J81: =IF(ISBLANK(J29),"NO DATA",IF(ISNUMBER(FIND(CODES!$A$12,J29)),CODES!$A$12,IF(OR(ISNUMBER(FIND(CODES!$A$10,J29)),ISNUMBER(FIND(CODES!$A$11,J29))),CODES!$A$13,IF(OR(J29<J$63,ISNUMBER(J29)=FALSE),J$64,J29)))) | ... DI81: =IF(ISBLANK(DI29),"NO DATA",IF(ISNUMBER(FIND(CODES!$A$12,DI29)),CODES!$A$12,IF(OR(ISNUMBER(FIND(CODES!$A$10,DI29)),ISNUMBER(FIND(CODES!$A$11,DI29))),CODES!$A$13,IF(OR(DI29<DI$63,ISNUMBER(DI29)=FALSE),DI$64,DI29))))
... A114: =A62 | B114: =B62 | C114: =IF(ISBLANK(C62),"NO DATA",IF(ISNUMBER(FIND(CODES!$A$12,C62)),CODES!$A$12,IF(OR(ISNUMBER(FIND(CODES!$A$10,C62)),ISNUMBER(FIND(CODES!$A$11,C62))),CODES!$A$13,IF(OR(C62<C$63,ISNUMBER(C62)=FALSE),C$64,C62)))) | D114: =IF(ISBLANK(D62),"NO DATA",IF(ISNUMBER(FIND(CODES!$A$12,D62)),CODES!$A$12,IF(OR(ISNUMBER(FIND(CODES!$A$10,D62)),ISNUMBER(FIND(CODES!$A$11,D62))),CODES!$A$13,IF(OR(D62<D$63,ISNUMBER(D62)=FALSE),D$64,D62)))) | E114: =IF(ISBLANK(E62),"NO DATA",IF(ISNUMBER(FIND(CODES!$A$12,E62)),CODES!$A$12,IF(OR(ISNUMBER(FIND(CODES!$A$10,E62)),ISNUMBER(FIND(CODES!$A$11,E62))),CODES!$A$13,IF(OR(E62<E$63,ISNUMBER(E62)=FALSE),E$64,E62)))) | F114: =IF(ISBLANK(F62),"NO DATA",IF(ISNUMBER(FIND(CODES!$A$12,F62)),CODES!$A$12,IF(OR(ISNUMBER(FIND(CODES!$A$10,F62)),ISNUMBER(FIND(CODES!$A$11,F62))),CODES!$A$13,IF(OR(F62<F$63,ISNUMBER(F62)=FALSE),F$64,F62)))) | G114: =IF(ISBLANK(G62),"NO DATA",IF(ISNUMBER(FIND(CODES!$A$12,G62)),CODES!$A$12,IF(OR(ISNUMBER(FIND(CODES!$A$10,G62)),ISNUMBER(FIND(CODES!$A$11,G62))),CODES!$A$13,IF(OR(G62<G$63,ISNUMBER(G62)=FALSE),G$64,G62)))) | H114: =IF(ISBLANK(H62),"NO DATA",IF(ISNUMBER(FIND(CODES!$A$12,H62)),CODES!$A$12,IF(OR(ISNUMBER(FIND(CODES!$A$10,H62)),ISNUMBER(FIND(CODES!$A$11,H62))),CODES!$A$13,IF(OR(H62<H$63,ISNUMBER(H62)=FALSE),H$64,H62)))) | I114: =IF(ISBLANK(I62),"NO DATA",IF(ISNUMBER(FIND(CODES!$A$12,I62)),CODES!$A$12,IF(OR(ISNUMBER(FIND(CODES!$A$10,I62)),ISNUMBER(FIND(CODES!$A$11,I62))),CODES!$A$13,IF(OR(I62<I$63,ISNUMBER(I62)=FALSE),I$64,I62)))) | J114: =IF(ISBLANK(J62),"NO DATA",IF(ISNUMBER(FIND(CODES!$A$12,J62)),CODES!$A$12,IF(OR(ISNUMBER(FIND(CODES!$A$10,J62)),ISNUMBER(FIND(CODES!$A$11,J62))),CODES!$A$13,IF(OR(J62<J$63,ISNUMBER(J62)=FALSE),J$64,J62)))) | ... DI114: =IF(ISBLANK(DI62),"NO DATA",IF(ISNUMBER(FIND(CODES!$A$12,DI62)),CODES!$A$12,IF(OR(ISNUMBER(FIND(CODES!$A$10,DI62)),ISNUMBER(FIND(CODES!$A$11,DI62))),CODES!$A$13,IF(OR(DI62<DI$63,ISNUMBER(DI62)=FALSE),DI$64,DI62))))

Sheet ICPMS RESULTS
A1: University of Northern British Columbia | B1: THIS DOES NOT AUTO DETECT OVER-RANGE VALUES
A2: Northern Analytical Laboratory Services
A3: Report File (Processing) | B3: =INSTRUCTIONS!A3
A5: Analyst:
A6: NALS Director: | B6: ='ICPOES RESULTS'!B6
A8: Date: | B8: ='ICPOES RESULTS'!B8
A9: Client Name: | B9: ='ICPOES RESULTS'!B9
A10: Supervisor: | B10: ='ICPOES RESULTS'!B10
A11: Client Company Name: | B11: ='ICPOES RESULTS'!B11
A12: Reference File: | B12: ='ICPOES RESULTS'!B12
A13: Number of Samples: | B13: ='ICPOES RESULTS'!B13
A14: Detection Limits File: | B14: =INSTRUCTIONS!B39
A16: ICPMS (Raw Data - ONLY CLIENT SAMPLE, NO QA/QC) | C16: 9 Be [ 1 ] | D16: 11 B [ 1 ] | E16: 51 V [ 1 ] | F16: 52 Cr [ 1 ] | G16: 53 (V) [ 1 ] | H16: 55 Mn [ 1 ] | I16: 59 Co [ 1 ] | J16: 60 Ni [ 1 ] | K16: 63 Cu [ 1 ] | L16: 66 Zn [ 1 ] | M16: 75 As [ 1 ] | N16: 77 (As) [ 1 ] | O16: 78 Se [ 1 ] | P16: 82 (As) [ 1 ] | Q16: 95 Mo [ 1 ] | R16: 106 (Cd) [ 1 ] | S16: 107 Ag [ 1 ] | T16: 108 (Cd) [ 1 ] | U16: 111 Cd [ 1 ] | V16: 121 Sb [ 1 ] | W16: 137 Ba [ 1 ] | X16: 202 Hg [ 1 ] | Y16: 205 Tl [ 1 ] | Z16: 206 (Pb) [ 1 ] | AA16: 207 (Pb) [ 1 ] | AB16: 208 Pb [ 1 ] | AC16: 232 Th [ 1 ] | AD16: 238 U [ 1 ]
A17: Sample Name | B17: Comment | C17: Conc. [ ppm ] | D17: Conc. [ ppm ] | E17: Conc. [ ppm ] | F17: Conc. [ ppm ] | G17: Conc. [ ppm ] | H17: Conc. [ ppm ] | I17: Conc. [ ppm ] | J17: Conc. [ ppm ] | K17: Conc. [ ppm ] | L17: Conc. [ ppm ] | M17: Conc. [ ppm ] | N17: Conc. [ ppm ] | O17: Conc. [ ppm ] | P17: Conc. [ ppm ] | Q17: Conc. [ ppm ] | R17: Conc. [ ppm ] | S17: Conc. [ ppm ] | T17: Conc. [ ppm ] | U17: Conc. [ ppm ] | V17: Conc. [ ppm ] | W17: Conc. [ ppm ] | X17: Conc. [ ppb ] | Y17: Conc. [ ppm ] | Z17: Conc. [ ppm ] | AA17: Conc. [ ppm ] | AB17: Conc. [ ppm ] | AC17: Conc. [ ppm ] | AD17: Conc. [ ppm ]
A18: ='ICPOES RESULTS'!A18
A19: ='ICPOES RESULTS'!A19
A20: ='ICPOES RESULTS'!A20
A21: ='ICPOES RESULTS'!A21
A22: ='ICPOES RESULTS'!A22
A23: ='ICPOES RESULTS'!A23
A24: ='ICPOES RESULTS'!A24
A25: ='ICPOES RESULTS'!A25
A26: ='ICPOES RESULTS'!A26
A27: ='ICPOES RESULTS'!A27
A28: ='ICPOES RESULTS'!A28
A29: ='ICPOES RESULTS'!A29
... A62: ='ICPOES RESULTS'!A62
A63: Reportable Limit (3xMDL) | B63: Reportable Limit (No Dilution) | C63: 0.0002 | D63: 0.003 | E63: 0.0003 | F63: 0.0001 | H63: 0.0001 | I63: 0.0003 | J63: 0.0001 | K63: 0.001 | L63: 0.0004 | M63: 0.0003 | O63: 0.001 | Q63: 0.001 | U63: 0.0002 | V63: 0.002 | W63: 0.0002 | X63: 0.3 | Y63: 0.0002 | AB63: 0.0001 | AC63: 0.0002 | AD63: 0.0002
A64: Reportable Limit (3xMDL) | B64: Reportable Limit (No Dilution) | C64: <0.0002 | D64: <0.003 | E64: <0.0003 | F64: <0.0001 | H64: <0.0001 | I64: <0.0003 | J64: <0.0001 | K64: <0.001 | L64: <0.0004 | M64: <0.0003 | O64: <0.001 | Q64: <0.001 | U64: <0.0002 | V64: <0.002 | W64: <0.0002 | X64: <0.3 | Y64: <0.0002 | AB64: <0.0001 | AC64: <0.0002 | AD64: <0.0002
A67: ICPMS (Reportable Numbers) *DO NOT ADJUST* | C67: 9 Be [ 1 ] | D67: 11 B [ 1 ] | E67: 51 V [ 1 ] | F67: 52 Cr [ 1 ] | G67: 55 Mn [ 1 ] | H67: 59 Co [ 1 ] | I67: 60 Ni [ 1 ] | J67: 63 Cu [ 1 ] | K67: 66 Zn [ 1 ] | L67: 75 As [ 1 ] | M67: 78 Se [ 1 ] | N67: 95 Mo [ 1 ] | O67: 111 Cd [ 1 ] | P67: 121 Sb [ 1 ] | Q67: 137 Ba [ 1 ] | R67: 202 Hg [ 1 ] | S67: 205 Tl [ 1 ] | T67: 208 Pb [ 1 ] | U67: 232 Th [ 1 ] | V67: 238 U [ 1 ]
A68: Sample Name | B68: Comment | C68: Conc. [ ppm ] | D68: Conc. [ ppm ] | E68: Conc. [ ppm ] | F68: Conc. [ ppm ] | G68: Conc. [ ppm ] | H68: Conc. [ ppm ] | I68: Conc. [ ppm ] | J68: Conc. [ ppm ] | K68: Conc. [ ppm ] | L68: Conc. [ ppm ] | M68: Conc. [ ppm ] | N68: Conc. [ ppm ] | O68: Conc. [ ppm ] | P68: Conc. [ ppm ] | Q68: Conc. [ ppm ] | R68: Conc. [ ppb ] | S68: Conc. [ ppm ] | T68: Conc. [ ppm ] | U68: Conc. [ ppm ] | V68: Conc. [ ppm ]
A69: =A18 | B69: =B18 | C69: =IF(ISBLANK(C18),"NO DATA",IF(OR(C18<C$63,ISNUMBER(C18)=FALSE),C$64,C18)) | D69: =IF(ISBLANK(D18),"NO DATA",IF(OR(D18<D$63,ISNUMBER(D18)=FALSE),D$64,D18)) | E69: =IF(ISBLANK(E18),"NO DATA",IF(OR(E18<E$63,ISNUMBER(E18)=FALSE),E$64,E18)) | F69: =IF(ISBLANK(F18),"NO DATA",IF(OR(F18<F$63,ISNUMBER(F18)=FALSE),F$64,F18)) | G69: =IF(ISBLANK(H18),"NO DATA",IF(OR(H18<H$63,ISNUMBER(H18)=FALSE),H$64,H18)) | H69: =IF(ISBLANK(I18),"NO DATA",IF(OR(I18<I$63,ISNUMBER(I18)=FALSE),I$64,I18)) | I69: =IF(ISBLANK(J18),"NO DATA",IF(OR(J18<J$63,ISNUMBER(J18)=FALSE),J$64,J18)) | J69: =IF(ISBLANK(K18),"NO DATA",IF(OR(K18<K$63,ISNUMBER(K18)=FALSE),K$64,K18)) | K69: =IF(ISBLANK(L18),"NO DATA",IF(OR(L18<L$63,ISNUMBER(L18)=FALSE),L$64,L18)) | L69: =IF(ISBLANK(M18),"NO DATA",IF(OR(M18<M$63,ISNUMBER(M18)=FALSE),M$64,M18)) | M69: =IF(ISBLANK(O18),"NO DATA",IF(OR(O18<O$63,ISNUMBER(O18)=FALSE),O$64,O18)) | N69: =IF(ISBLANK(Q18),"NO DATA",IF(OR(Q18<Q$63,ISNUMBER(Q18)=FALSE),Q$64,Q18)) | O69: =IF(ISBLANK(U18),"NO DATA",IF(OR(U18<U$63,ISNUMBER(U18)=FALSE),U$64,U18)) | P69: =IF(ISBLANK(V18),"NO DATA",IF(OR(V18<V$63,ISNUMBER(V18)=FALSE),V$64,V18)) | Q69: =IF(ISBLANK(W18),"NO DATA",IF(OR(W18<W$63,ISNUMBER(W18)=FALSE),W$64,W18)) | R69: =IF(ISBLANK(X18),"NO DATA",IF(OR(X18<X$63,ISNUMBER(X18)=FALSE),X$64,X18)) | S69: =IF(ISBLANK(Y18),"NO DATA",IF(OR(Y18<Y$63,ISNUMBER(Y18)=FALSE),Y$64,Y18)) | T69: =IF(ISBLANK(AB18),"NO DATA",IF(OR(AB18<AB$63,ISNUMBER(AB18)=FALSE),AB$64,AB18)) | U69: =IF(ISBLANK(AC18),"NO DATA",IF(OR(AC18<AC$63,ISNUMBER(AC18)=FALSE),AC$64,AC18)) | V69: =IF(ISBLANK(AD18),"NO DATA",IF(OR(AD18<AD$63,ISNUMBER(AD18)=FALSE),AD$64,AD18))
A70: =A19 | B70: =B19 | C70: =IF(ISBLANK(C19),"NO DATA",IF(OR(C19<C$63,ISNUMBER(C19)=FALSE),C$64,C19)) | D70: =IF(ISBLANK(D19),"NO DATA",IF(OR(D19<D$63,ISNUMBER(D19)=FALSE),D$64,D19)) | E70: =IF(ISBLANK(E19),"NO DATA",IF(OR(E19<E$63,ISNUMBER(E19)=FALSE),E$64,E19)) | F70: =IF(ISBLANK(F19),"NO DATA",IF(OR(F19<F$63,ISNUMBER(F19)=FALSE),F$64,F19)) | G70: =IF(ISBLANK(H19),"NO DATA",IF(OR(H19<H$63,ISNUMBER(H19)=FALSE),H$64,H19)) | H70: =IF(ISBLANK(I19),"NO DATA",IF(OR(I19<I$63,ISNUMBER(I19)=FALSE),I$64,I19)) | I70: =IF(ISBLANK(J19),"NO DATA",IF(OR(J19<J$63,ISNUMBER(J19)=FALSE),J$64,J19)) | J70: =IF(ISBLANK(K19),"NO DATA",IF(OR(K19<K$63,ISNUMBER(K19)=FALSE),K$64,K19)) | K70: =IF(ISBLANK(L19),"NO DATA",IF(OR(L19<L$63,ISNUMBER(L19)=FALSE),L$64,L19)) | L70: =IF(ISBLANK(M19),"NO DATA",IF(OR(M19<M$63,ISNUMBER(M19)=FALSE),M$64,M19)) | M70: =IF(ISBLANK(O19),"NO DATA",IF(OR(O19<O$63,ISNUMBER(O19)=FALSE),O$64,O19)) | N70: =IF(ISBLANK(Q19),"NO DATA",IF(OR(Q19<Q$63,ISNUMBER(Q19)=FALSE),Q$64,Q19)) | O70: =IF(ISBLANK(U19),"NO DATA",IF(OR(U19<U$63,ISNUMBER(U19)=FALSE),U$64,U19)) | P70: =IF(ISBLANK(V19),"NO DATA",IF(OR(V19<V$63,ISNUMBER(V19)=FALSE),V$64,V19)) | Q70: =IF(ISBLANK(W19),"NO DATA",IF(OR(W19<W$63,ISNUMBER(W19)=FALSE),W$64,W19)) | R70: =IF(ISBLANK(X19),"NO DATA",IF(OR(X19<X$63,ISNUMBER(X19)=FALSE),X$64,X19)) | S70: =IF(ISBLANK(Y19),"NO DATA",IF(OR(Y19<Y$63,ISNUMBER(Y19)=FALSE),Y$64,Y19)) | T70: =IF(ISBLANK(AB19),"NO DATA",IF(OR(AB19<AB$63,ISNUMBER(AB19)=FALSE),AB$64,AB19)) | U70: =IF(ISBLANK(AC19),"NO DATA",IF(OR(AC19<AC$63,ISNUMBER(AC19)=FALSE),AC$64,AC19)) | V70: =IF(ISBLANK(AD19),"NO DATA",IF(OR(AD19<AD$63,ISNUMBER(AD19)=FALSE),AD$64,AD19))
A71: =A20 | B71: =B20 | C71: =IF(ISBLANK(C20),"NO DATA",IF(OR(C20<C$63,ISNUMBER(C20)=FALSE),C$64,C20)) | D71: =IF(ISBLANK(D20),"NO DATA",IF(OR(D20<D$63,ISNUMBER(D20)=FALSE),D$64,D20)) | E71: =IF(ISBLANK(E20),"NO DATA",IF(OR(E20<E$63,ISNUMBER(E20)=FALSE),E$64,E20)) | F71: =IF(ISBLANK(F20),"NO DATA",IF(OR(F20<F$63,ISNUMBER(F20)=FALSE),F$64,F20)) | G71: =IF(ISBLANK(H20),"NO DATA",IF(OR(H20<H$63,ISNUMBER(H20)=FALSE),H$64,H20)) | H71: =IF(ISBLANK(I20),"NO DATA",IF(OR(I20<I$63,ISNUMBER(I20)=FALSE),I$64,I20)) | I71: =IF(ISBLANK(J20),"NO DATA",IF(OR(J20<J$63,ISNUMBER(J20)=FALSE),J$64,J20)) | J71: =IF(ISBLANK(K20),"NO DATA",IF(OR(K20<K$63,ISNUMBER(K20)=FALSE),K$64,K20)) | K71: =IF(ISBLANK(L20),"NO DATA",IF(OR(L20<L$63,ISNUMBER(L20)=FALSE),L$64,L20)) | L71: =IF(ISBLANK(M20),"NO DATA",IF(OR(M20<M$63,ISNUMBER(M20)=FALSE),M$64,M20)) | M71: =IF(ISBLANK(O20),"NO DATA",IF(OR(O20<O$63,ISNUMBER(O20)=FALSE),O$64,O20)) | N71: =IF(ISBLANK(Q20),"NO DATA",IF(OR(Q20<Q$63,ISNUMBER(Q20)=FALSE),Q$64,Q20)) | O71: =IF(ISBLANK(U20),"NO DATA",IF(OR(U20<U$63,ISNUMBER(U20)=FALSE),U$64,U20)) | P71: =IF(ISBLANK(V20),"NO DATA",IF(OR(V20<V$63,ISNUMBER(V20)=FALSE),V$64,V20)) | Q71: =IF(ISBLANK(W20),"NO DATA",IF(OR(W20<W$63,ISNUMBER(W20)=FALSE),W$64,W20)) | R71: =IF(ISBLANK(X20),"NO DATA",IF(OR(X20<X$63,ISNUMBER(X20)=FALSE),X$64,X20)) | S71: =IF(ISBLANK(Y20),"NO DATA",IF(OR(Y20<Y$63,ISNUMBER(Y20)=FALSE),Y$64,Y20)) | T71: =IF(ISBLANK(AB20),"NO DATA",IF(OR(AB20<AB$63,ISNUMBER(AB20)=FALSE),AB$64,AB20)) | U71: =IF(ISBLANK(AC20),"NO DATA",IF(OR(AC20<AC$63,ISNUMBER(AC20)=FALSE),AC$64,AC20)) | V71: =IF(ISBLANK(AD20),"NO DATA",IF(OR(AD20<AD$63,ISNUMBER(AD20)=FALSE),AD$64,AD20))
A72: =A21 | B72: =B21 | C72: =IF(ISBLANK(C21),"NO DATA",IF(OR(C21<C$63,ISNUMBER(C21)=FALSE),C$64,C21)) | D72: =IF(ISBLANK(D21),"NO DATA",IF(OR(D21<D$63,ISNUMBER(D21)=FALSE),D$64,D21)) | E72: =IF(ISBLANK(E21),"NO DATA",IF(OR(E21<E$63,ISNUMBER(E21)=FALSE),E$64,E21)) | F72: =IF(ISBLANK(F21),"NO DATA",IF(OR(F21<F$63,ISNUMBER(F21)=FALSE),F$64,F21)) | G72: =IF(ISBLANK(H21),"NO DATA",IF(OR(H21<H$63,ISNUMBER(H21)=FALSE),H$64,H21)) | H72: =IF(ISBLANK(I21),"NO DATA",IF(OR(I21<I$63,ISNUMBER(I21)=FALSE),I$64,I21)) | I72: =IF(ISBLANK(J21),"NO DATA",IF(OR(J21<J$63,ISNUMBER(J21)=FALSE),J$64,J21)) | J72: =IF(ISBLANK(K21),"NO DATA",IF(OR(K21<K$63,ISNUMBER(K21)=FALSE),K$64,K21)) | K72: =IF(ISBLANK(L21),"NO DATA",IF(OR(L21<L$63,ISNUMBER(L21)=FALSE),L$64,L21)) | L72: =IF(ISBLANK(M21),"NO DATA",IF(OR(M21<M$63,ISNUMBER(M21)=FALSE),M$64,M21)) | M72: =IF(ISBLANK(O21),"NO DATA",IF(OR(O21<O$63,ISNUMBER(O21)=FALSE),O$64,O21)) | N72: =IF(ISBLANK(Q21),"NO DATA",IF(OR(Q21<Q$63,ISNUMBER(Q21)=FALSE),Q$64,Q21)) | O72: =IF(ISBLANK(U21),"NO DATA",IF(OR(U21<U$63,ISNUMBER(U21)=FALSE),U$64,U21)) | P72: =IF(ISBLANK(V21),"NO DATA",IF(OR(V21<V$63,ISNUMBER(V21)=FALSE),V$64,V21)) | Q72: =IF(ISBLANK(W21),"NO DATA",IF(OR(W21<W$63,ISNUMBER(W21)=FALSE),W$64,W21)) | R72: =IF(ISBLANK(X21),"NO DATA",IF(OR(X21<X$63,ISNUMBER(X21)=FALSE),X$64,X21)) | S72: =IF(ISBLANK(Y21),"NO DATA",IF(OR(Y21<Y$63,ISNUMBER(Y21)=FALSE),Y$64,Y21)) | T72: =IF(ISBLANK(AB21),"NO DATA",IF(OR(AB21<AB$63,ISNUMBER(AB21)=FALSE),AB$64,AB21)) | U72: =IF(ISBLANK(AC21),"NO DATA",IF(OR(AC21<AC$63,ISNUMBER(AC21)=FALSE),AC$64,AC21)) | V72: =IF(ISBLANK(AD21),"NO DATA",IF(OR(AD21<AD$63,ISNUMBER(AD21)=FALSE),AD$64,AD21))
A73: =A22 | B73: =B22 | C73: =IF(ISBLANK(C22),"NO DATA",IF(OR(C22<C$63,ISNUMBER(C22)=FALSE),C$64,C22)) | D73: =IF(ISBLANK(D22),"NO DATA",IF(OR(D22<D$63,ISNUMBER(D22)=FALSE),D$64,D22)) | E73: =IF(ISBLANK(E22),"NO DATA",IF(OR(E22<E$63,ISNUMBER(E22)=FALSE),E$64,E22)) | F73: =IF(ISBLANK(F22),"NO DATA",IF(OR(F22<F$63,ISNUMBER(F22)=FALSE),F$64,F22)) | G73: =IF(ISBLANK(H22),"NO DATA",IF(OR(H22<H$63,ISNUMBER(H22)=FALSE),H$64,H22)) | H73: =IF(ISBLANK(I22),"NO DATA",IF(OR(I22<I$63,ISNUMBER(I22)=FALSE),I$64,I22)) | I73: =IF(ISBLANK(J22),"NO DATA",IF(OR(J22<J$63,ISNUMBER(J22)=FALSE),J$64,J22)) | J73: =IF(ISBLANK(K22),"NO DATA",IF(OR(K22<K$63,ISNUMBER(K22)=FALSE),K$64,K22)) | K73: =IF(ISBLANK(L22),"NO DATA",IF(OR(L22<L$63,ISNUMBER(L22)=FALSE),L$64,L22)) | L73: =IF(ISBLANK(M22),"NO DATA",IF(OR(M22<M$63,ISNUMBER(M22)=FALSE),M$64,M22)) | M73: =IF(ISBLANK(O22),"NO DATA",IF(OR(O22<O$63,ISNUMBER(O22)=FALSE),O$64,O22)) | N73: =IF(ISBLANK(Q22),"NO DATA",IF(OR(Q22<Q$63,ISNUMBER(Q22)=FALSE),Q$64,Q22)) | O73: =IF(ISBLANK(U22),"NO DATA",IF(OR(U22<U$63,ISNUMBER(U22)=FALSE),U$64,U22)) | P73: =IF(ISBLANK(V22),"NO DATA",IF(OR(V22<V$63,ISNUMBER(V22)=FALSE),V$64,V22)) | Q73: =IF(ISBLANK(W22),"NO DATA",IF(OR(W22<W$63,ISNUMBER(W22)=FALSE),W$64,W22)) | R73: =IF(ISBLANK(X22),"NO DATA",IF(OR(X22<X$63,ISNUMBER(X22)=FALSE),X$64,X22)) | S73: =IF(ISBLANK(Y22),"NO DATA",IF(OR(Y22<Y$63,ISNUMBER(Y22)=FALSE),Y$64,Y22)) | T73: =IF(ISBLANK(AB22),"NO DATA",IF(OR(AB22<AB$63,ISNUMBER(AB22)=FALSE),AB$64,AB22)) | U73: =IF(ISBLANK(AC22),"NO DATA",IF(OR(AC22<AC$63,ISNUMBER(AC22)=FALSE),AC$64,AC22)) | V73: =IF(ISBLANK(AD22),"NO DATA",IF(OR(AD22<AD$63,ISNUMBER(AD22)=FALSE),AD$64,AD22))
A74: =A23 | B74: =B23 | C74: =IF(ISBLANK(C23),"NO DATA",IF(OR(C23<C$63,ISNUMBER(C23)=FALSE),C$64,C23)) | D74: =IF(ISBLANK(D23),"NO DATA",IF(OR(D23<D$63,ISNUMBER(D23)=FALSE),D$64,D23)) | E74: =IF(ISBLANK(E23),"NO DATA",IF(OR(E23<E$63,ISNUMBER(E23)=FALSE),E$64,E23)) | F74: =IF(ISBLANK(F23),"NO DATA",IF(OR(F23<F$63,ISNUMBER(F23)=FALSE),F$64,F23)) | G74: =IF(ISBLANK(H23),"NO DATA",IF(OR(H23<H$63,ISNUMBER(H23)=FALSE),H$64,H23)) | H74: =IF(ISBLANK(I23),"NO DATA",IF(OR(I23<I$63,ISNUMBER(I23)=FALSE),I$64,I23)) | I74: =IF(ISBLANK(J23),"NO DATA",IF(OR(J23<J$63,ISNUMBER(J23)=FALSE),J$64,J23)) | J74: =IF(ISBLANK(K23),"NO DATA",IF(OR(K23<K$63,ISNUMBER(K23)=FALSE),K$64,K23)) | K74: =IF(ISBLANK(L23),"NO DATA",IF(OR(L23<L$63,ISNUMBER(L23)=FALSE),L$64,L23)) | L74: =IF(ISBLANK(M23),"NO DATA",IF(OR(M23<M$63,ISNUMBER(M23)=FALSE),M$64,M23)) | M74: =IF(ISBLANK(O23),"NO DATA",IF(OR(O23<O$63,ISNUMBER(O23)=FALSE),O$64,O23)) | N74: =IF(ISBLANK(Q23),"NO DATA",IF(OR(Q23<Q$63,ISNUMBER(Q23)=FALSE),Q$64,Q23)) | O74: =IF(ISBLANK(U23),"NO DATA",IF(OR(U23<U$63,ISNUMBER(U23)=FALSE),U$64,U23)) | P74: =IF(ISBLANK(V23),"NO DATA",IF(OR(V23<V$63,ISNUMBER(V23)=FALSE),V$64,V23)) | Q74: =IF(ISBLANK(W23),"NO DATA",IF(OR(W23<W$63,ISNUMBER(W23)=FALSE),W$64,W23)) | R74: =IF(ISBLANK(X23),"NO DATA",IF(OR(X23<X$63,ISNUMBER(X23)=FALSE),X$64,X23)) | S74: =IF(ISBLANK(Y23),"NO DATA",IF(OR(Y23<Y$63,ISNUMBER(Y23)=FALSE),Y$64,Y23)) | T74: =IF(ISBLANK(AB23),"NO DATA",IF(OR(AB23<AB$63,ISNUMBER(AB23)=FALSE),AB$64,AB23)) | U74: =IF(ISBLANK(AC23),"NO DATA",IF(OR(AC23<AC$63,ISNUMBER(AC23)=FALSE),AC$64,AC23)) | V74: =IF(ISBLANK(AD23),"NO DATA",IF(OR(AD23<AD$63,ISNUMBER(AD23)=FALSE),AD$64,AD23))
A75: =A24 | B75: =B24 | C75: =IF(ISBLANK(C24),"NO DATA",IF(OR(C24<C$63,ISNUMBER(C24)=FALSE),C$64,C24)) | D75: =IF(ISBLANK(D24),"NO DATA",IF(OR(D24<D$63,ISNUMBER(D24)=FALSE),D$64,D24)) | E75: =IF(ISBLANK(E24),"NO DATA",IF(OR(E24<E$63,ISNUMBER(E24)=FALSE),E$64,E24)) | F75: =IF(ISBLANK(F24),"NO DATA",IF(OR(F24<F$63,ISNUMBER(F24)=FALSE),F$64,F24)) | G75: =IF(ISBLANK(H24),"NO DATA",IF(OR(H24<H$63,ISNUMBER(H24)=FALSE),H$64,H24)) | H75: =IF(ISBLANK(I24),"NO DATA",IF(OR(I24<I$63,ISNUMBER(I24)=FALSE),I$64,I24)) | I75: =IF(ISBLANK(J24),"NO DATA",IF(OR(J24<J$63,ISNUMBER(J24)=FALSE),J$64,J24)) | J75: =IF(ISBLANK(K24),"NO DATA",IF(OR(K24<K$63,ISNUMBER(K24)=FALSE),K$64,K24)) | K75: =IF(ISBLANK(L24),"NO DATA",IF(OR(L24<L$63,ISNUMBER(L24)=FALSE),L$64,L24)) | L75: =IF(ISBLANK(M24),"NO DATA",IF(OR(M24<M$63,ISNUMBER(M24)=FALSE),M$64,M24)) | M75: =IF(ISBLANK(O24),"NO DATA",IF(OR(O24<O$63,ISNUMBER(O24)=FALSE),O$64,O24)) | N75: =IF(ISBLANK(Q24),"NO DATA",IF(OR(Q24<Q$63,ISNUMBER(Q24)=FALSE),Q$64,Q24)) | O75: =IF(ISBLANK(U24),"NO DATA",IF(OR(U24<U$63,ISNUMBER(U24)=FALSE),U$64,U24)) | P75: =IF(ISBLANK(V24),"NO DATA",IF(OR(V24<V$63,ISNUMBER(V24)=FALSE),V$64,V24)) | Q75: =IF(ISBLANK(W24),"NO DATA",IF(OR(W24<W$63,ISNUMBER(W24)=FALSE),W$64,W24)) | R75: =IF(ISBLANK(X24),"NO DATA",IF(OR(X24<X$63,ISNUMBER(X24)=FALSE),X$64,X24)) | S75: =IF(ISBLANK(Y24),"NO DATA",IF(OR(Y24<Y$63,ISNUMBER(Y24)=FALSE),Y$64,Y24)) | T75: =IF(ISBLANK(AB24),"NO DATA",IF(OR(AB24<AB$63,ISNUMBER(AB24)=FALSE),AB$64,AB24)) | U75: =IF(ISBLANK(AC24),"NO DATA",IF(OR(AC24<AC$63,ISNUMBER(AC24)=FALSE),AC$64,AC24)) | V75: =IF(ISBLANK(AD24),"NO DATA",IF(OR(AD24<AD$63,ISNUMBER(AD24)=FALSE),AD$64,AD24))
A76: =A25 | B76: =B25 | C76: =IF(ISBLANK(C25),"NO DATA",IF(OR(C25<C$63,ISNUMBER(C25)=FALSE),C$64,C25)) | D76: =IF(ISBLANK(D25),"NO DATA",IF(OR(D25<D$63,ISNUMBER(D25)=FALSE),D$64,D25)) | E76: =IF(ISBLANK(E25),"NO DATA",IF(OR(E25<E$63,ISNUMBER(E25)=FALSE),E$64,E25)) | F76: =IF(ISBLANK(F25),"NO DATA",IF(OR(F25<F$63,ISNUMBER(F25)=FALSE),F$64,F25)) | G76: =IF(ISBLANK(H25),"NO DATA",IF(OR(H25<H$63,ISNUMBER(H25)=FALSE),H$64,H25)) | H76: =IF(ISBLANK(I25),"NO DATA",IF(OR(I25<I$63,ISNUMBER(I25)=FALSE),I$64,I25)) | I76: =IF(ISBLANK(J25),"NO DATA",IF(OR(J25<J$63,ISNUMBER(J25)=FALSE),J$64,J25)) | J76: =IF(ISBLANK(K25),"NO DATA",IF(OR(K25<K$63,ISNUMBER(K25)=FALSE),K$64,K25)) | K76: =IF(ISBLANK(L25),"NO DATA",IF(OR(L25<L$63,ISNUMBER(L25)=FALSE),L$64,L25)) | L76: =IF(ISBLANK(M25),"NO DATA",IF(OR(M25<M$63,ISNUMBER(M25)=FALSE),M$64,M25)) | M76: =IF(ISBLANK(O25),"NO DATA",IF(OR(O25<O$63,ISNUMBER(O25)=FALSE),O$64,O25)) | N76: =IF(ISBLANK(Q25),"NO DATA",IF(OR(Q25<Q$63,ISNUMBER(Q25)=FALSE),Q$64,Q25)) | O76: =IF(ISBLANK(U25),"NO DATA",IF(OR(U25<U$63,ISNUMBER(U25)=FALSE),U$64,U25)) | P76: =IF(ISBLANK(V25),"NO DATA",IF(OR(V25<V$63,ISNUMBER(V25)=FALSE),V$64,V25)) | Q76: =IF(ISBLANK(W25),"NO DATA",IF(OR(W25<W$63,ISNUMBER(W25)=FALSE),W$64,W25)) | R76: =IF(ISBLANK(X25),"NO DATA",IF(OR(X25<X$63,ISNUMBER(X25)=FALSE),X$64,X25)) | S76: =IF(ISBLANK(Y25),"NO DATA",IF(OR(Y25<Y$63,ISNUMBER(Y25)=FALSE),Y$64,Y25)) | T76: =IF(ISBLANK(AB25),"NO DATA",IF(OR(AB25<AB$63,ISNUMBER(AB25)=FALSE),AB$64,AB25)) | U76: =IF(ISBLANK(AC25),"NO DATA",IF(OR(AC25<AC$63,ISNUMBER(AC25)=FALSE),AC$64,AC25)) | V76: =IF(ISBLANK(AD25),"NO DATA",IF(OR(AD25<AD$63,ISNUMBER(AD25)=FALSE),AD$64,AD25))
A77: =A26 | B77: =B26 | C77: =IF(ISBLANK(C26),"NO DATA",IF(OR(C26<C$63,ISNUMBER(C26)=FALSE),C$64,C26)) | D77: =IF(ISBLANK(D26),"NO DATA",IF(OR(D26<D$63,ISNUMBER(D26)=FALSE),D$64,D26)) | E77: =IF(ISBLANK(E26),"NO DATA",IF(OR(E26<E$63,ISNUMBER(E26)=FALSE),E$64,E26)) | F77: =IF(ISBLANK(F26),"NO DATA",IF(OR(F26<F$63,ISNUMBER(F26)=FALSE),F$64,F26)) | G77: =IF(ISBLANK(H26),"NO DATA",IF(OR(H26<H$63,ISNUMBER(H26)=FALSE),H$64,H26)) | H77: =IF(ISBLANK(I26),"NO DATA",IF(OR(I26<I$63,ISNUMBER(I26)=FALSE),I$64,I26)) | I77: =IF(ISBLANK(J26),"NO DATA",IF(OR(J26<J$63,ISNUMBER(J26)=FALSE),J$64,J26)) | J77: =IF(ISBLANK(K26),"NO DATA",IF(OR(K26<K$63,ISNUMBER(K26)=FALSE),K$64,K26)) | K77: =IF(ISBLANK(L26),"NO DATA",IF(OR(L26<L$63,ISNUMBER(L26)=FALSE),L$64,L26)) | L77: =IF(ISBLANK(M26),"NO DATA",IF(OR(M26<M$63,ISNUMBER(M26)=FALSE),M$64,M26)) | M77: =IF(ISBLANK(O26),"NO DATA",IF(OR(O26<O$63,ISNUMBER(O26)=FALSE),O$64,O26)) | N77: =IF(ISBLANK(Q26),"NO DATA",IF(OR(Q26<Q$63,ISNUMBER(Q26)=FALSE),Q$64,Q26)) | O77: =IF(ISBLANK(U26),"NO DATA",IF(OR(U26<U$63,ISNUMBER(U26)=FALSE),U$64,U26)) | P77: =IF(ISBLANK(V26),"NO DATA",IF(OR(V26<V$63,ISNUMBER(V26)=FALSE),V$64,V26)) | Q77: =IF(ISBLANK(W26),"NO DATA",IF(OR(W26<W$63,ISNUMBER(W26)=FALSE),W$64,W26)) | R77: =IF(ISBLANK(X26),"NO DATA",IF(OR(X26<X$63,ISNUMBER(X26)=FALSE),X$64,X26)) | S77: =IF(ISBLANK(Y26),"NO DATA",IF(OR(Y26<Y$63,ISNUMBER(Y26)=FALSE),Y$64,Y26)) | T77: =IF(ISBLANK(AB26),"NO DATA",IF(OR(AB26<AB$63,ISNUMBER(AB26)=FALSE),AB$64,AB26)) | U77: =IF(ISBLANK(AC26),"NO DATA",IF(OR(AC26<AC$63,ISNUMBER(AC26)=FALSE),AC$64,AC26)) | V77: =IF(ISBLANK(AD26),"NO DATA",IF(OR(AD26<AD$63,ISNUMBER(AD26)=FALSE),AD$64,AD26))
...

Sheet ICPQQQ RESULTS
A1: University of Northern British Columbia | B1: THIS DOES NOT AUTO DETECT OVER-RANGE VALUES
A2: Northern Analytical Laboratory Services
A3: Report File (Processing) | B3: =INSTRUCTIONS!A3
A5: Analyst: | B5: ='ICPOES RESULTS'!B5
A6: NALS Director: | B6: ='ICPOES RESULTS'!B6
A8: Date: | B8: ='ICPOES RESULTS'!B8
A9: Client Name: | B9: ='ICPOES RESULTS'!B9
A10: Supervisor: | B10: ='ICPOES RESULTS'!B10
A11: Client Company Name: | B11: ='ICPOES RESULTS'!B11
A12: Reference File: | B12: ='ICPOES RESULTS'!B12
A13: Number of Samples: | B13: ='ICPOES RESULTS'!B13
A14: Detection Limits File: | B14: =INSTRUCTIONS!B41
A16: ICPQQQ (Raw Data - ONLY CLIENT SAMPLE, NO QA/QC) | C16: 9 Be [ He ] | D16: 11 B [ He ] | E16: 23 Na [ He ] | F16: 24 Mg [ He ] | G16: 27 Al [ He ] | H16: 39 K [ He ] | I16: 24 -> 40 Mg [ O2 ] | J16: 27 -> 43 Al [ O2 ] | K16: 28 -> 44 Si [ O2 ] | L16: 47 Ti [ He ] | M16: 31 -> 47 P [ O2 ] | N16: 34 -> 50 S [ O2 ] | O16: 51 V [ He ] | P16: 52 Cr [ He ] | Q16: 55 Mn [ He ] | R16: 56 Fe [ He ] | S16: 59 Co [ He ] | T16: 60 Ni [ He ] | U16: 44 -> 60 Ca [ O2 ] | V16: 63 Cu [ He ] | W16: 66 Zn [ He ] | X16: 71 Ga [ He ] | Y16: 75 As [ He ] | Z16: 85 Rb [ He ] | AA16: 88 Sr [ He ] | AB16: 90 Zr [ He ] | AC16: 78 -> 94 Se [ O2 ] | AD16: 95 Mo [ He ] | AE16: 107 Ag [ He ] | AF16: 111 Cd [ He ] | AG16: 121 Sb [ He ] | AH16: 125 Te [ He ] | AI16: 133 Cs [ He ] | AJ16: 118 -> 134 Sn [ O2 ] | AK16: 137 Ba [ He ] | AL16: 178 Hf [ He ] | AM16: 181 Ta [ He ] | AN16: 182 W [ He ] | AO16: 201 Hg [ He ] | AP16: 205 Tl [ He ] | AQ16: 206 [Pb] [ He ] | AR16: 207 [Pb] [ He ] | AS16: 208 Pb [ He ] | AT16: 232 Th [ He ] | AU16: 238 U [ He ]
A17: Sample Name | B17: Comment | C17: Conc. [ ug/L ] | D17: Conc. [ ug/L ] | E17: Conc. [ mg/L ] | F17: Conc. [ mg/L ] | G17: Conc. [ ug/L ] | H17: Conc. [ mg/L ] | I17: Conc. [ mg/L ] | J17: Conc. [ ug/L ] | K17: Conc. [ ug/L ] | L17: Conc. [ ug/L ] | M17: Conc. [ ug/L ] | N17: Conc. [ mg/L ] | O17: Conc. [ ug/L ] | P17: Conc. [ ug/L ] | Q17: Conc. [ ug/L ] | R17: Conc. [ ug/L ] | S17: Conc. [ ug/L ] | T17: Conc. [ ug/L ] | U17: Conc. [ mg/L ] | V17: Conc. [ ug/L ] | W17: Conc. [ ug/L ] | X17: Conc. [ ug/L ] | Y17: Conc. [ ug/L ] | Z17: Conc. [ ug/L ] | AA17: Conc. [ ug/L ] | AB17: Conc. [ ug/L ] | AC17: Conc. [ ug/L ] | AD17: Conc. [ ug/L ] | AE17: Conc. [ ug/L ] | AF17: Conc. [ ug/L ] | AG17: Conc. [ ug/L ] | AH17: Conc. [ ug/L ] | AI17: Conc. [ ug/L ] | AJ17: Conc. [ ug/L ] | AK17: Conc. [ ug/L ] | AL17: Conc. [ ug/L ] | AM17: Conc. [ ug/L ] | AN17: Conc. [ ug/L ] | AO17: Conc. [ ug/L ] | AP17: Conc. [ ug/L ] | AQ17: Conc. [ ug/L ] | AR17: Conc. [ ug/L ] | AS17: Conc. [ ug/L ] | AT17: Conc. [ ug/L ] | AU17: Conc. [ ug/L ]
A18: ='ICPOES RESULTS'!A18
A19: ='ICPOES RESULTS'!A19
A20: ='ICPOES RESULTS'!A20
A21: ='ICPOES RESULTS'!A21
A22: ='ICPOES RESULTS'!A22
A23: ='ICPOES RESULTS'!A23
A24: ='ICPOES RESULTS'!A24
A25: ='ICPOES RESULTS'!A25
A26: ='ICPOES RESULTS'!A26
A27: ='ICPOES RESULTS'!A27
A28: ='ICPOES RESULTS'!A28
A29: ='ICPOES RESULTS'!A29
... A62: ='ICPOES RESULTS'!A62
A63: Reportable Limit (3xMDL) | B63: Reportable Limit (No Dilution) | C63: 3 | D63: 6 | E63: 0.01 | F63: 0.01 | G63: 4 | H63: 0.01 | I63: 0.01 | J63: 2 | K63: 2 | L63: 4 | M63: 1 | N63: 0.02 | O63: 0.2 | P63: 0.3 | Q63: 1 | R63: 1 | S63: 0.2 | T63: 0.3 | U63: 0.01 | V63: 0.2 | W63: 1 | X63: 1 | Y63: 0.3 | Z63: 0.4 | AA63: 0.6 | AB63: 0.2 | AC63: 0.4 | AD63: 0.3 | AE63: 1 | AF63: 0.2 | AG63: 1 | AH63: 7 | AI63: 0.3 | AJ63: 0.3 | AK63: 0.8 | AL63: 0.2 | AM63: 0.2 | AN63: 0.4 | AO63: 0.1 | AP63: 0.3 | AQ63: 0.2 | AR63: 0.2 | AS63: 0.2 | AT63: 0.2 | AU63: 0.2
A64: Reportable Limit (3xMDL) | B64: Reportable Limit (No Dilution) | C64: ="<"&C63 | D64: ="<"&D63 | E64: ="<"&E63 | F64: ="<"&F63 | G64: ="<"&G63 | H64: ="<"&H63 | I64: ="<"&I63 | J64: ="<"&J63 | ... AU64: ="<"&AU63
A67: ICPQQQ (Reportable Numbers) *DO NOT ADJUST* | C67: 9 Be [ He ] | D67: 11 B [ He ] | E67: 23 Na [ He ] | F67: 24 Mg [ He ] | G67: 27 Al [ He ] | H67: 39 K [ He ] | I67: 24 -> 40 Mg [ O2 ] | J67: 27 -> 43 Al [ O2 ] | K67: 28 -> 44 Si [ O2 ] | L67: 47 Ti [ He ] | M67: 31 -> 47 P [ O2 ] | N67: 34 -> 50 S [ O2 ] | O67: 51 V [ He ] | P67: 52 Cr [ He ] | Q67: 55 Mn [ He ] | R67: 56 Fe [ He ] | S67: 59 Co [ He ] | T67: 60 Ni [ He ] | U67: 44 -> 60 Ca [ O2 ] | V67: 63 Cu [ He ] | W67: 66 Zn [ He ] | X67: 71 Ga [ He ] | Y67: 75 As [ He ] | Z67: 85 Rb [ He ] | AA67: 88 Sr [ He ] | AB67: 90 Zr [ He ] | AC67: 78 -> 94 Se [ O2 ] | AD67: 95 Mo [ He ] | AE67: 107 Ag [ He ] | AF67: 111 Cd [ He ] | AG67: 121 Sb [ He ] | AH67: 125 Te [ He ] | AI67: 133 Cs [ He ] | AJ67: 118 -> 134 Sn [ O2 ] | AK67: 137 Ba [ He ] | AL67: 178 Hf [ He ] | AM67: 181 Ta [ He ] | AN67: 182 W [ He ] | AO67: 201 Hg [ He ] | AP67: 205 Tl [ He ] | AQ67: 206 [Pb] [ He ] | AR67: 207 [Pb] [ He ] | AS67: 208 Pb [ He ] | AT67: 232 Th [ He ] | AU67: 238 U [ He ]
A68: Sample Name | B68: Comment | C68: Conc. [ ug/L ] | D68: Conc. [ ug/L ] | E68: Conc. [ mg/L ] | F68: Conc. [ mg/L ] | G68: Conc. [ ug/L ] | H68: Conc. [ mg/L ] | I68: Conc. [ mg/L ] | J68: Conc. [ ug/L ] | K68: Conc. [ ug/L ] | L68: Conc. [ ug/L ] | M68: Conc. [ ug/L ] | N68: Conc. [ mg/L ] | O68: Conc. [ ug/L ] | P68: Conc. [ ug/L ] | Q68: Conc. [ ug/L ] | R68: Conc. [ ug/L ] | S68: Conc. [ ug/L ] | T68: Conc. [ ug/L ] | U68: Conc. [ mg/L ] | V68: Conc. [ ug/L ] | W68: Conc. [ ug/L ] | X68: Conc. [ ug/L ] | Y68: Conc. [ ug/L ] | Z68: Conc. [ ug/L ] | AA68: Conc. [ ug/L ] | AB68: Conc. [ ug/L ] | AC68: Conc. [ ug/L ] | AD68: Conc. [ ug/L ] | AE68: Conc. [ ug/L ] | AF68: Conc. [ ug/L ] | AG68: Conc. [ ug/L ] | AH68: Conc. [ ug/L ] | AI68: Conc. [ ug/L ] | AJ68: Conc. [ ug/L ] | AK68: Conc. [ ug/L ] | AL68: Conc. [ ug/L ] | AM68: Conc. [ ug/L ] | AN68: Conc. [ ug/L ] | AO68: Conc. [ ug/L ] | AP68: Conc. [ ug/L ] | AQ68: Conc. [ ug/L ] | AR68: Conc. [ ug/L ] | AS68: Conc. [ ug/L ] | AT68: Conc. [ ug/L ] | AU68: Conc. [ ug/L ]
A69: =A18 | B69: =B18 | C69: =IF(ISBLANK(C18),"NO DATA",IF(OR(C18<C$63,ISNUMBER(C18)=FALSE),C$64,C18)) | D69: =IF(ISBLANK(D18),"NO DATA",IF(OR(D18<D$63,ISNUMBER(D18)=FALSE),D$64,D18)) | E69: =IF(ISBLANK(E18),"NO DATA",IF(OR(E18<E$63,ISNUMBER(E18)=FALSE),E$64,E18)) | F69: =IF(ISBLANK(F18),"NO DATA",IF(OR(F18<F$63,ISNUMBER(F18)=FALSE),F$64,F18)) | G69: =IF(ISBLANK(G18),"NO DATA",IF(OR(G18<G$63,ISNUMBER(G18)=FALSE),G$64,G18)) | H69: =IF(ISBLANK(H18),"NO DATA",IF(OR(H18<H$63,ISNUMBER(H18)=FALSE),H$64,H18)) | I69: =IF(ISBLANK(I18),"NO DATA",IF(OR(I18<I$63,ISNUMBER(I18)=FALSE),I$64,I18)) | J69: =IF(ISBLANK(J18),"NO DATA",IF(OR(J18<J$63,ISNUMBER(J18)=FALSE),J$64,J18)) | ... AU69: =IF(ISBLANK(AU18),"NO DATA",IF(OR(AU18<AU$63,ISNUMBER(AU18)=FALSE),AU$64,AU18))
