Workbook
Name Slicer_Total_Metals: #N/A

Sheet BATCH
A1: University of Northern British Columbia
A2: Northern Analytical Laboratory Services
A3: QA/QC Report File (Processing) | B3: =INSTRUCTIONS!A3
A4: BATCH | B4: A
A6: Analyst: | B6: Erwin
A7: NALS Director: | B7: Dr. Hossein Kazemian
A9: Date: | B9: 46066
A10: Client Name: | B10: Multiple Clients
A11: Supervisor: | B11: n/a
A12: Client Company Name: | B12: n/a
A13: Reference File: | B13: 2025NALS02540_2621_2623_2627_Feb_13_2026_OES
A14: Number of Samples: | B14: Multiple Samples
A15: Detection Limits File: | B15: =INSTRUCTIONS!B11
A17: ICPOES (Raw Data from QA/QC from UNADJUSTED DATA) | C17: Ag 328.068 nm | D17: Ag 338.289 nm | E17: Al 396.152 nm | F17: As 188.980 nm | G17: As 193.696 nm | H17: B 249.678 nm | I17: B 249.772 nm | J17: Ba 493.408 nm | K17: Ba-A 455.403 nm | L17: Be 234.861 nm | M17: Be 313.042 nm | N17: Bi 222.821 nm | O17: Bi 223.061 nm | P17: Ca 317.933 nm | Q17: Ca 422.673 nm | R17: Cd 214.439 nm | S17: Cd 226.502 nm | T17: Ce 418.659 nm | U17: Ce 446.021 nm | V17: Co 238.892 nm | W17: Co 258.033 nm | X17: Cr 206.158 nm | Y17: Cr 267.716 nm | Z17: Cu-A 327.395 nm | AA17: Dy 340.780 nm | AB17: Dy 353.171 nm | AC17: Er 337.275 nm | AD17: Er 349.910 nm | AE17: Eu 397.197 nm | AF17: Eu 420.504 nm | AG17: Fe 234.350 nm | AH17: Fe 238.204 nm | AI17: Ga 294.363 nm | AJ17: Ga 417.204 nm | AK17: Gd 335.048 nm | AL17: Gd 342.246 nm | AM17: Hf 263.872 nm | AN17: Hf 264.141 nm | AO17: Hg 184.887 nm | AP17: Hg 194.164 nm | AQ17: Ho 339.895 nm | AR17: Ho 345.600 nm | AS17: K 766.491 nm | AT17: La 333.749 nm | AU17: La 379.477 nm | AV17: Li 610.365 nm | AW17: Li 670.783 nm | AX17: Lu 261.541 nm | AY17: Lu 291.139 nm | AZ17: Mg 280.270 nm | BA17: Mg 285.213 nm | BB17: Mn 257.610 nm | BC17: Mn 294.921 nm | BD17: Mo 202.032 nm | BE17: Mo 204.598 nm | BF17: Na 588.995 nm | BG17: Na 589.592 nm | BH17: Nb 309.417 nm | BI17: Nb 313.078 nm | BJ17: Nd 401.224 nm | BK17: Nd 406.108 nm | BL17: Ni 216.555 nm | BM17: Ni 231.604 nm | BN17: P 177.434 nm | BO17: P 178.222 nm | BP17: P 213.618 nm | BQ17: Pb 220.353 nm | BR17: Rb 780.026 nm | BS17: S 180.669 nm | BT17: S 181.972 nm | BU17: Sb 206.834 nm | BV17: Sb 217.582 nm | BW17: Sc 335.372 nm | BX17: Sc 361.383 nm | BY17: Se 196.026 nm | BZ17: Se 203.985 nm | CA17: Si 251.611 nm | CB17: Si 288.158 nm | CC17: Sm 359.259 nm | CD17: Sm 360.949 nm | CE17: Sn 189.925 nm | CF17: Sn 283.998 nm | CG17: Sr-R 407.771 nm | CH17: Sr-R 421.552 nm | CI17: Ta 263.558 nm | CJ17: Ta 268.517 nm | CK17: Te 182.153 nm | CL17: Te 214.282 nm | CM17: Th 269.242 nm | CN17: Th 283.730 nm | CO17: Ti 334.941 nm | CP17: Ti 336.122 nm | CQ17: Tl 190.794 nm | CR17: Tl 276.789 nm | CS17: Tl 351.923 nm | CT17: Tm 313.125 nm | CU17: Tm 342.508 nm | CV17: U 367.007 nm | CW17: U 385.957 nm | CX17: V 292.401 nm | CY17: V 309.310 nm | CZ17: W 207.912 nm | DA17: W 209.475 nm | DB17: Y 360.074 nm | DC17: Y 371.029 nm | DD17: Yb 328.937 nm | DE17: Yb 369.419 nm | DF17: Zn 202.548 nm | DG17: Zn 213.857 nm | DH17: Zr 339.198 nm | DI17: Zr 343.823 nm
A18: QA/QC SAMPLES NAMES | B18: Comment | C18: Conc. (mg/L) | D18: Conc. (mg/L) | E18: Conc. (mg/L) | F18: Conc. (mg/L) | G18: Conc. (mg/L) | H18: Conc. (mg/L) | I18: Conc. (mg/L) | J18: Conc. (mg/L) | K18: Conc. (mg/L) | L18: Conc. (mg/L) | M18: Conc. (µg/L) | N18: Conc. (mg/L) | O18: Conc. (mg/L) | P18: Conc. (mg/L) | Q18: Conc. (mg/L) | R18: Conc. (mg/L) | S18: Conc. (mg/L) | T18: Conc. (mg/L) | U18: Conc. (mg/L) | V18: Conc. (mg/L) | W18: Conc. (mg/L) | X18: Conc. (mg/L) | Y18: Conc. (mg/L) | Z18: Conc. (mg/L) | AA18: Conc. (mg/L) | AB18: Conc. (mg/L) | AC18: Conc. (mg/L) | AD18: Conc. (mg/L) | AE18: Conc. (mg/L) | AF18: Conc. (mg/L) | AG18: Conc. (mg/L) | AH18: Conc. (mg/L) | AI18: Conc. (mg/L) | AJ18: Conc. (mg/L) | AK18: Conc. (mg/L) | AL18: Conc. (mg/L) | AM18: Conc. (mg/L) | AN18: Conc. (mg/L) | AO18: Conc. (µg/L) | AP18: Conc. (µg/L) | AQ18: Conc. (mg/L) | AR18: Conc. (mg/L) | AS18: Conc. (mg/L) | AT18: Conc. (mg/L) | AU18: Conc. (mg/L) | AV18: Conc. (mg/L) | AW18: Conc. (mg/L) | AX18: Conc. (mg/L) | AY18: Conc. (mg/L) | AZ18: Conc. (mg/L) | BA18: Conc. (mg/L) | BB18: Conc. (mg/L) | BC18: Conc. (mg/L) | BD18: Conc. (mg/L) | BE18: Conc. (mg/L) | BF18: Conc. (mg/L) | BG18: Conc. (mg/L) | BH18: Conc. (mg/L) | BI18: Conc. (mg/L) | BJ18: Conc. (mg/L) | BK18: Conc. (mg/L) | BL18: Conc. (mg/L) | BM18: Conc. (mg/L) | BN18: Conc. (mg/L) | BO18: Conc. (mg/L) | BP18: Conc. (mg/L) | BQ18: Conc. (mg/L) | BR18: Conc. (mg/L) | BS18: Conc. (mg/L) | BT18: Conc. (mg/L) | BU18: Conc. (mg/L) | BV18: Conc. (mg/L) | BW18: Conc. (mg/L) | BX18: Conc. (mg/L) | BY18: Conc. (mg/L) | BZ18: Conc. (mg/L) | CA18: Conc. (mg/L) | CB18: Conc. (mg/L) | CC18: Conc. (mg/L) | CD18: Conc. (mg/L) | CE18: Conc. (mg/L) | CF18: Conc. (mg/L) | CG18: Conc. (mg/L) | CH18: Conc. (mg/L) | CI18: Conc. (mg/L) | CJ18: Conc. (mg/L) | CK18: Conc. (mg/L) | CL18: Conc. (mg/L) | CM18: Conc. (mg/L) | CN18: Conc. (mg/L) | CO18: Conc. (mg/L) | CP18: Conc. (mg/L) | CQ18: Conc. (mg/L) | CR18: Conc. (mg/L) | CS18: Conc. (mg/L) | CT18: Conc. (mg/L) | CU18: Conc. (mg/L) | CV18: Conc. (mg/L) | CW18: Conc. (mg/L) | CX18: Conc. (mg/L) | CY18: Conc. (mg/L) | CZ18: Conc. (mg/L) | DA18: Conc. (mg/L) | DB18: Conc. (mg/L) | DC18: Conc. (mg/L) | DD18: Conc. (mg/L) | DE18: Conc. (mg/L) | DF18: Conc. (mg/L) | DG18: Conc. (mg/L) | DH18: Conc. (mg/L) | DI18: Conc. (mg/L)
A19: IPC Blank after Calibration (NALS Blank) | B19: IPC Blank
A20: IPC CCV5 after Calibration | B20: CCV 500ppb
A21: IPC CCV5 after Batch | B21: CCV 500ppb
A22: Digest Method Blank (LRB) | B22: 2026NALS02621 A01
A23: Digest LFB | B23: 2026NALS02621 A02
A24: SAMPLE, RPD Calculated | B24: 2026NALS02621 A03
A25: SAMPLE DUPLICATE, RPD Calculated | B25: 2026NALS02621 A04
A26: LFM Background (10X Dil. of Sample) | B26: 2026NALS02621 A03 - Dil. 10X
A27: LFM Spike | B27: 2026NALS02621 A05
A28: Instrument LFB | B28: Lab Fortified Blank 1ppm Jan 20/26 ICV
A29: Instrument Interference Check | B29: Interference Check 1ppm Jan 20/26 ICV
A30: Instrument ICV | B30: ICV LVL 5 Jan 27/26
... A38: N/A | B38: USED ONLY FOR ADDITIONAL QC
A39: Reportable Limit (3xMDL) | B39: Reportable Limit (No Dilution) | C39: =CODES!C29 | D39: =CODES!D29 | E39: =CODES!E29 | F39: =CODES!F29 | G39: =CODES!G29 | H39: =CODES!H29 | I39: =CODES!I29 | J39: =CODES!J29 | ... DI39: =CODES!DI29
A40: Reportable Limit (3xMDL) | B40: Reportable Limit (No Dilution) | C40: =CODES!C30 | D40: =CODES!D30 | E40: =CODES!E30 | F40: =CODES!F30 | G40: =CODES!G30 | H40: =CODES!H30 | I40: =CODES!I30 | J40: =CODES!J30 | ... DI40: =CODES!DI30
A43: YELLOW IS PREFERRED WAVELENGTH
A44: ICPOES (Reportable Numbers) *DO NOT ADJUST* | C44: =C17 | D44: =D17 | E44: =E17 | F44: =F17 | G44: =G17 | H44: =H17 | I44: =I17 | J44: =J17 | ... DI44: =DI17
A45: Sample Name | B45: Comment | C45: =C18 | D45: =D18 | E45: =E18 | F45: =F18 | G45: =G18 | H45: =H18 | I45: =I18 | J45: =J18 | ... DI45: =DI18
A46: =A19 | B46: =B19 | C46: =IF(ISBLANK(C19),"NO DATA",IF(ISNUMBER(FIND(CODES!$A$12,C19)),CODES!$A$12,IF(OR(ISNUMBER(FIND(CODES!$A$10,C19)),ISNUMBER(FIND(CODES!$A$11,C19))),CODES!$A$13,IF(OR(C19<C$39,ISNUMBER(C19)=FALSE),C$40,C19)))) | D46: =IF(ISBLANK(D19),"NO DATA",IF(ISNUMBER(FIND(CODES!$A$12,D19)),CODES!$A$12,IF(OR(ISNUMBER(FIND(CODES!$A$10,D19)),ISNUMBER(FIND(CODES!$A$11,D19))),CODES!$A$13,IF(OR(D19<D$39,ISNUMBER(D19)=FALSE),D$40,D19)))) | E46: =IF(ISBLANK(E19),"NO DATA",IF(ISNUMBER(FIND(CODES!$A$12,E19)),CODES!$A$12,IF(OR(ISNUMBER(FIND(CODES!$A$10,E19)),ISNUMBER(FIND(CODES!$A$11,E19))),CODES!$A$13,IF(OR(E19<E$39,ISNUMBER(E19)=FALSE),E$40,E19)))) | F46: =IF(ISBLANK(F19),"NO DATA",IF(ISNUMBER(FIND(CODES!$A$12,F19)),CODES!$A$12,IF(OR(ISNUMBER(FIND(CODES!$A$10,F19)),ISNUMBER(FIND(CODES!$A$11,F19))),CODES!$A$13,IF(OR(F19<F$39,ISNUMBER(F19)=FALSE),F$40,F19)))) | G46: =IF(ISBLANK(G19),"NO DATA",IF(ISNUMBER(FIND(CODES!$A$12,G19)),CODES!$A$12,IF(OR(ISNUMBER(FIND(CODES!$A$10,G19)),ISNUMBER(FIND(CODES!$A$11,G19))),CODES!$A$13,IF(OR(G19<G$39,ISNUMBER(G19)=FALSE),G$40,G19)))) | H46: =IF(ISBLANK(H19),"NO DATA",IF(ISNUMBER(FIND(CODES!$A$12,H19)),CODES!$A$12,IF(OR(ISNUMBER(FIND(CODES!$A$10,H19)),ISNUMBER(FIND(CODES!$A$11,H19))),CODES!$A$13,IF(OR(H19<H$39,ISNUMBER(H19)=FALSE),H$40,H19)))) | I46: =IF(ISBLANK(I19),"NO DATA",IF(ISNUMBER(FIND(CODES!$A$12,I19)),CODES!$A$12,IF(OR(ISNUMBER(FIND(CODES!$A$10,I19)),ISNUMBER(FIND(CODES!$A$11,I19))),CODES!$A$13,IF(OR(I19<I$39,ISNUMBER(I19)=FALSE),I$40,I19)))) | J46: =IF(ISBLANK(J19),"NO DATA",IF(ISNUMBER(FIND(CODES!$A$12,J19)),CODES!$A$12,IF(OR(ISNUMBER(FIND(CODES!$A$10,J19)),ISNUMBER(FIND(CODES!$A$11,J19))),CODES!$A$13,IF(OR(J19<J$39,ISNUMBER(J19)=FALSE),J$40,J19)))) | ... DI46: =IF(ISBLANK(DI19),"NO DATA",IF(ISNUMBER(FIND(CODES!$A$12,DI19)),CODES!$A$12,IF(OR(ISNUMBER(FIND(CODES!$A$10,DI19)),ISNUMBER(FIND(CODES!$A$11,DI19))),CODES!$A$13,IF(OR(DI19<DI$39,ISNUMBER(DI19)=FALSE),DI$40,DI19))))
A47: =A20 | B47: =B20 | C47: =IF(ISBLANK(C20),"NO DATA",IF(ISNUMBER(FIND(CODES!$A$12,C20)),CODES!$A$12,IF(OR(ISNUMBER(FIND(CODES!$A$10,C20)),ISNUMBER(FIND(CODES!$A$11,C20))),CODES!$A$13,IF(OR(C20<C$39,ISNUMBER(C20)=FALSE),C$40,C20)))) | D47: =IF(ISBLANK(D20),"NO DATA",IF(ISNUMBER(FIND(CODES!$A$12,D20)),CODES!$A$12,IF(OR(ISNUMBER(FIND(CODES!$A$10,D20)),ISNUMBER(FIND(CODES!$A$11,D20))),CODES!$A$13,IF(OR(D20<D$39,ISNUMBER(D20)=FALSE),D$40,D20)))) | E47: =IF(ISBLANK(E20),"NO DATA",IF(ISNUMBER(FIND(CODES!$A$12,E20)),CODES!$A$12,IF(OR(ISNUMBER(FIND(CODES!$A$10,E20)),ISNUMBER(FIND(CODES!$A$11,E20))),CODES!$A$13,IF(OR(E20<E$39,ISNUMBER(E20)=FALSE),E$40,E20)))) | F47: =IF(ISBLANK(F20),"NO DATA",IF(ISNUMBER(FIND(CODES!$A$12,F20)),CODES!$A$12,IF(OR(ISNUMBER(FIND(CODES!$A$10,F20)),ISNUMBER(FIND(CODES!$A$11,F20))),CODES!$A$13,IF(OR(F20<F$39,ISNUMBER(F20)=FALSE),F$40,F20)))) | G47: =IF(ISBLANK(G20),"NO DATA",IF(ISNUMBER(FIND(CODES!$A$12,G20)),CODES!$A$12,IF(OR(ISNUMBER(FIND(CODES!$A$10,G20)),ISNUMBER(FIND(CODES!$A$11,G20))),CODES!$A$13,IF(OR(G20<G$39,ISNUMBER(G20)=FALSE),G$40,G20)))) | H47: =IF(ISBLANK(H20),"NO DATA",IF(ISNUMBER(FIND(CODES!$A$12,H20)),CODES!$A$12,IF(OR(ISNUMBER(FIND(CODES!$A$10,H20)),ISNUMBER(FIND(CODES!$A$11,H20))),CODES!$A$13,IF(OR(H20<H$39,ISNUMBER(H20)=FALSE),H$40,H20)))) | I47: =IF(ISBLANK(I20),"NO DATA",IF(ISNUMBER(FIND(CODES!$A$12,I20)),CODES!$A$12,IF(OR(ISNUMBER(FIND(CODES!$A$10,I20)),ISNUMBER(FIND(CODES!$A$11,I20))),CODES!$A$13,IF(OR(I20<I$39,ISNUMBER(I20)=FALSE),I$40,I20)))) | J47: =IF(ISBLANK(J20),"NO DATA",IF(ISNUMBER(FIND(CODES!$A$12,J20)),CODES!$A$12,IF(OR(ISNUMBER(FIND(CODES!$A$10,J20)),ISNUMBER(FIND(CODES!$A$11,J20))),CODES!$A$13,IF(OR(J20<J$39,ISNUMBER(J20)=FALSE),J$40,J20)))) | ... DI47: =IF(ISBLANK(DI20),"NO DATA",IF(ISNUMBER(FIND(CODES!$A$12,DI20)),CODES!$A$12,IF(OR(ISNUMBER(FIND(CODES!$A$10,DI20)),ISNUMBER(FIND(CODES!$A$11,DI20))),CODES!$A$13,IF(OR(DI20<DI$39,ISNUMBER(DI20)=FALSE),DI$40,DI20))))
A48: =A21 | B48: =B21 | C48: =IF(ISBLANK(C21),"NO DATA",IF(ISNUMBER(FIND(CODES!$A$12,C21)),CODES!$A$12,IF(OR(ISNUMBER(FIND(CODES!$A$10,C21)),ISNUMBER(FIND(CODES!$A$11,C21))),CODES!$A$13,IF(OR(C21<C$39,ISNUMBER(C21)=FALSE),C$40,C21)))) | D48: =IF(ISBLANK(D21),"NO DATA",IF(ISNUMBER(FIND(CODES!$A$12,D21)),CODES!$A$12,IF(OR(ISNUMBER(FIND(CODES!$A$10,D21)),ISNUMBER(FIND(CODES!$A$11,D21))),CODES!$A$13,IF(OR(D21<D$39,ISNUMBER(D21)=FALSE),D$40,D21)))) | E48: =IF(ISBLANK(E21),"NO DATA",IF(ISNUMBER(FIND(CODES!$A$12,E21)),CODES!$A$12,IF(OR(ISNUMBER(FIND(CODES!$A$10,E21)),ISNUMBER(FIND(CODES!$A$11,E21))),CODES!$A$13,IF(OR(E21<E$39,ISNUMBER(E21)=FALSE),E$40,E21)))) | F48: =IF(ISBLANK(F21),"NO DATA",IF(ISNUMBER(FIND(CODES!$A$12,F21)),CODES!$A$12,IF(OR(ISNUMBER(FIND(CODES!$A$10,F21)),ISNUMBER(FIND(CODES!$A$11,F21))),CODES!$A$13,IF(OR(F21<F$39,ISNUMBER(F21)=FALSE),F$40,F21)))) | G48: =IF(ISBLANK(G21),"NO DATA",IF(ISNUMBER(FIND(CODES!$A$12,G21)),CODES!$A$12,IF(OR(ISNUMBER(FIND(CODES!$A$10,G21)),ISNUMBER(FIND(CODES!$A$11,G21))),CODES!$A$13,IF(OR(G21<G$39,ISNUMBER(G21)=FALSE),G$40,G21)))) | H48: =IF(ISBLANK(H21),"NO DATA",IF(ISNUMBER(FIND(CODES!$A$12,H21)),CODES!$A$12,IF(OR(ISNUMBER(FIND(CODES!$A$10,H21)),ISNUMBER(FIND(CODES!$A$11,H21))),CODES!$A$13,IF(OR(H21<H$39,ISNUMBER(H21)=FALSE),H$40,H21)))) | I48: =IF(ISBLANK(I21),"NO DATA",IF(ISNUMBER(FIND(CODES!$A$12,I21)),CODES!$A$12,IF(OR(ISNUMBER(FIND(CODES!$A$10,I21)),ISNUMBER(FIND(CODES!$A$11,I21))),CODES!$A$13,IF(OR(I21<I$39,ISNUMBER(I21)=FALSE),I$40,I21)))) | J48: =IF(ISBLANK(J21),"NO DATA",IF(ISNUMBER(FIND(CODES!$A$12,J21)),CODES!$A$12,IF(OR(ISNUMBER(FIND(CODES!$A$10,J21)),ISNUMBER(FIND(CODES!$A$11,J21))),CODES!$A$13,IF(OR(J21<J$39,ISNUMBER(J21)=FALSE),J$40,J21)))) | ... DI48: =IF(ISBLANK(DI21),"NO DATA",IF(ISNUMBER(FIND(CODES!$A$12,DI21)),CODES!$A$12,IF(OR(ISNUMBER(FIND(CODES!$A$10,DI21)),ISNUMBER(FIND(CODES!$A$11,DI21))),CODES!$A$13,IF(OR(DI21<DI$39,ISNUMBER(DI21)=FALSE),DI$40,DI21))))
A49: =A22 | B49: =B22 | C49: =IF(ISBLANK(C22),"NO DATA",IF(ISNUMBER(FIND(CODES!$A$12,C22)),CODES!$A$12,IF(OR(ISNUMBER(FIND(CODES!$A$10,C22)),ISNUMBER(FIND(CODES!$A$11,C22))),CODES!$A$13,IF(OR(C22<C$39,ISNUMBER(C22)=FALSE),C$40,C22)))) | D49: =IF(ISBLANK(D22),"NO DATA",IF(ISNUMBER(FIND(CODES!$A$12,D22)),CODES!$A$12,IF(OR(ISNUMBER(FIND(CODES!$A$10,D22)),ISNUMBER(FIND(CODES!$A$11,D22))),CODES!$A$13,IF(OR(D22<D$39,ISNUMBER(D22)=FALSE),D$40,D22)))) | E49: =IF(ISBLANK(E22),"NO DATA",IF(ISNUMBER(FIND(CODES!$A$12,E22)),CODES!$A$12,IF(OR(ISNUMBER(FIND(CODES!$A$10,E22)),ISNUMBER(FIND(CODES!$A$11,E22))),CODES!$A$13,IF(OR(E22<E$39,ISNUMBER(E22)=FALSE),E$40,E22)))) | F49: =IF(ISBLANK(F22),"NO DATA",IF(ISNUMBER(FIND(CODES!$A$12,F22)),CODES!$A$12,IF(OR(ISNUMBER(FIND(CODES!$A$10,F22)),ISNUMBER(FIND(CODES!$A$11,F22))),CODES!$A$13,IF(OR(F22<F$39,ISNUMBER(F22)=FALSE),F$40,F22)))) | G49: =IF(ISBLANK(G22),"NO DATA",IF(ISNUMBER(FIND(CODES!$A$12,G22)),CODES!$A$12,IF(OR(ISNUMBER(FIND(CODES!$A$10,G22)),ISNUMBER(FIND(CODES!$A$11,G22))),CODES!$A$13,IF(OR(G22<G$39,ISNUMBER(G22)=FALSE),G$40,G22)))) | H49: =IF(ISBLANK(H22),"NO DATA",IF(ISNUMBER(FIND(CODES!$A$12,H22)),CODES!$A$12,IF(OR(ISNUMBER(FIND(CODES!$A$10,H22)),ISNUMBER(FIND(CODES!$A$11,H22))),CODES!$A$13,IF(OR(H22<H$39,ISNUMBER(H22)=FALSE),H$40,H22)))) | I49: =IF(ISBLANK(I22),"NO DATA",IF(ISNUMBER(FIND(CODES!$A$12,I22)),CODES!$A$12,IF(OR(ISNUMBER(FIND(CODES!$A$10,I22)),ISNUMBER(FIND(CODES!$A$11,I22))),CODES!$A$13,IF(OR(I22<I$39,ISNUMBER(I22)=FALSE),I$40,I22)))) | J49: =IF(ISBLANK(J22),"NO DATA",IF(ISNUMBER(FIND(CODES!$A$12,J22)),CODES!$A$12,IF(OR(ISNUMBER(FIND(CODES!$A$10,J22)),ISNUMBER(FIND(CODES!$A$11,J22))),CODES!$A$13,IF(OR(J22<J$39,ISNUMBER(J22)=FALSE),J$40,J22)))) | ... DI49: =IF(ISBLANK(DI22),"NO DATA",IF(ISNUMBER(FIND(CODES!$A$12,DI22)),CODES!$A$12,IF(OR(ISNUMBER(FIND(CODES!$A$10,DI22)),ISNUMBER(FIND(CODES!$A$11,DI22))),CODES!$A$13,IF(OR(DI22<DI$39,ISNUMBER(DI22)=FALSE),DI$40,DI22))))
A50: =A23 | B50: =B23 | C50: =IF(ISBLANK(C23),"NO DATA",IF(ISNUMBER(FIND(CODES!$A$12,C23)),CODES!$A$12,IF(OR(ISNUMBER(FIND(CODES!$A$10,C23)),ISNUMBER(FIND(CODES!$A$11,C23))),CODES!$A$13,IF(OR(C23<C$39,ISNUMBER(C23)=FALSE),C$40,C23)))) | D50: =IF(ISBLANK(D23),"NO DATA",IF(ISNUMBER(FIND(CODES!$A$12,D23)),CODES!$A$12,IF(OR(ISNUMBER(FIND(CODES!$A$10,D23)),ISNUMBER(FIND(CODES!$A$11,D23))),CODES!$A$13,IF(OR(D23<D$39,ISNUMBER(D23)=FALSE),D$40,D23)))) | E50: =IF(ISBLANK(E23),"NO DATA",IF(ISNUMBER(FIND(CODES!$A$12,E23)),CODES!$A$12,IF(OR(ISNUMBER(FIND(CODES!$A$10,E23)),ISNUMBER(FIND(CODES!$A$11,E23))),CODES!$A$13,IF(OR(E23<E$39,ISNUMBER(E23)=FALSE),E$40,E23)))) | F50: =IF(ISBLANK(F23),"NO DATA",IF(ISNUMBER(FIND(CODES!$A$12,F23)),CODES!$A$12,IF(OR(ISNUMBER(FIND(CODES!$A$10,F23)),ISNUMBER(FIND(CODES!$A$11,F23))),CODES!$A$13,IF(OR(F23<F$39,ISNUMBER(F23)=FALSE),F$40,F23)))) | G50: =IF(ISBLANK(G23),"NO DATA",IF(ISNUMBER(FIND(CODES!$A$12,G23)),CODES!$A$12,IF(OR(ISNUMBER(FIND(CODES!$A$10,G23)),ISNUMBER(FIND(CODES!$A$11,G23))),CODES!$A$13,IF(OR(G23<G$39,ISNUMBER(G23)=FALSE),G$40,G23)))) | H50: =IF(ISBLANK(H23),"NO DATA",IF(ISNUMBER(FIND(CODES!$A$12,H23)),CODES!$A$12,IF(OR(ISNUMBER(FIND(CODES!$A$10,H23)),ISNUMBER(FIND(CODES!$A$11,H23))),CODES!$A$13,IF(OR(H23<H$39,ISNUMBER(H23)=FALSE),H$40,H23)))) | I50: =IF(ISBLANK(I23),"NO DATA",IF(ISNUMBER(FIND(CODES!$A$12,I23)),CODES!$A$12,IF(OR(ISNUMBER(FIND(CODES!$A$10,I23)),ISNUMBER(FIND(CODES!$A$11,I23))),CODES!$A$13,IF(OR(I23<I$39,ISNUMBER(I23)=FALSE),I$40,I23)))) | J50: =IF(ISBLANK(J23),"NO DATA",IF(ISNUMBER(FIND(CODES!$A$12,J23)),CODES!$A$12,IF(OR(ISNUMBER(FIND(CODES!$A$10,J23)),ISNUMBER(FIND(CODES!$A$11,J23))),CODES!$A$13,IF(OR(J23<J$39,ISNUMBER(J23)=FALSE),J$40,J23)))) | ... DI50: =IF(ISBLANK(DI23),"NO DATA",IF(ISNUMBER(FIND(CODES!$A$12,DI23)),CODES!$A$12,IF(OR(ISNUMBER(FIND(CODES!$A$10,DI23)),ISNUMBER(FIND(CODES!$A$11,DI23))),CODES!$A$13,IF(OR(DI23<DI$39,ISNUMBER(DI23)=FALSE),DI$40,DI23))))
A51: =A24 | B51: =B24 | C51: =IF(ISBLANK(C24),"NO DATA",IF(ISNUMBER(FIND(CODES!$A$12,C24)),CODES!$A$12,IF(OR(ISNUMBER(FIND(CODES!$A$10,C24)),ISNUMBER(FIND(CODES!$A$11,C24))),CODES!$A$13,IF(OR(C24<C$39,ISNUMBER(C24)=FALSE),C$40,C24)))) | D51: =IF(ISBLANK(D24),"NO DATA",IF(ISNUMBER(FIND(CODES!$A$12,D24)),CODES!$A$12,IF(OR(ISNUMBER(FIND(CODES!$A$10,D24)),ISNUMBER(FIND(CODES!$A$11,D24))),CODES!$A$13,IF(OR(D24<D$39,ISNUMBER(D24)=FALSE),D$40,D24)))) | E51: =IF(ISBLANK(E24),"NO DATA",IF(ISNUMBER(FIND(CODES!$A$12,E24)),CODES!$A$12,IF(OR(ISNUMBER(FIND(CODES!$A$10,E24)),ISNUMBER(FIND(CODES!$A$11,E24))),CODES!$A$13,IF(OR(E24<E$39,ISNUMBER(E24)=FALSE),E$40,E24)))) | F51: =IF(ISBLANK(F24),"NO DATA",IF(ISNUMBER(FIND(CODES!$A$12,F24)),CODES!$A$12,IF(OR(ISNUMBER(FIND(CODES!$A$10,F24)),ISNUMBER(FIND(CODES!$A$11,F24))),CODES!$A$13,IF(OR(F24<F$39,ISNUMBER(F24)=FALSE),F$40,F24)))) | G51: =IF(ISBLANK(G24),"NO DATA",IF(ISNUMBER(FIND(CODES!$A$12,G24)),CODES!$A$12,IF(OR(ISNUMBER(FIND(CODES!$A$10,G24)),ISNUMBER(FIND(CODES!$A$11,G24))),CODES!$A$13,IF(OR(G24<G$39,ISNUMBER(G24)=FALSE),G$40,G24)))) | H51: =IF(ISBLANK(H24),"NO DATA",IF(ISNUMBER(FIND(CODES!$A$12,H24)),CODES!$A$12,IF(OR(ISNUMBER(FIND(CODES!$A$10,H24)),ISNUMBER(FIND(CODES!$A$11,H24))),CODES!$A$13,IF(OR(H24<H$39,ISNUMBER(H24)=FALSE),H$40,H24)))) | I51: =IF(ISBLANK(I24),"NO DATA",IF(ISNUMBER(FIND(CODES!$A$12,I24)),CODES!$A$12,IF(OR(ISNUMBER(FIND(CODES!$A$10,I24)),ISNUMBER(FIND(CODES!$A$11,I24))),CODES!$A$13,IF(OR(I24<I$39,ISNUMBER(I24)=FALSE),I$40,I24)))) | J51: =IF(ISBLANK(J24),"NO DATA",IF(ISNUMBER(FIND(CODES!$A$12,J24)),CODES!$A$12,IF(OR(ISNUMBER(FIND(CODES!$A$10,J24)),ISNUMBER(FIND(CODES!$A$11,J24))),CODES!$A$13,IF(OR(J24<J$39,ISNUMBER(J24)=FALSE),J$40,J24)))) | ... DI51: =IF(ISBLANK(DI24),"NO DATA",IF(ISNUMBER(FIND(CODES!$A$12,DI24)),CODES!$A$12,IF(OR(ISNUMBER(FIND(CODES!$A$10,DI24)),ISNUMBER(FIND(CODES!$A$11,DI24))),CODES!$A$13,IF(OR(DI24<DI$39,ISNUMBER(DI24)=FALSE),DI$40,DI24))))
A52: =A25 | B52: =B25 | C52: =IF(ISBLANK(C25),"NO DATA",IF(ISNUMBER(FIND(CODES!$A$12,C25)),CODES!$A$12,IF(OR(ISNUMBER(FIND(CODES!$A$10,C25)),ISNUMBER(FIND(CODES!$A$11,C25))),CODES!$A$13,IF(OR(C25<C$39,ISNUMBER(C25)=FALSE),C$40,C25)))) | D52: =IF(ISBLANK(D25),"NO DATA",IF(ISNUMBER(FIND(CODES!$A$12,D25)),CODES!$A$12,IF(OR(ISNUMBER(FIND(CODES!$A$10,D25)),ISNUMBER(FIND(CODES!$A$11,D25))),CODES!$A$13,IF(OR(D25<D$39,ISNUMBER(D25)=FALSE),D$40,D25)))) | E52: =IF(ISBLANK(E25),"NO DATA",IF(ISNUMBER(FIND(CODES!$A$12,E25)),CODES!$A$12,IF(OR(ISNUMBER(FIND(CODES!$A$10,E25)),ISNUMBER(FIND(CODES!$A$11,E25))),CODES!$A$13,IF(OR(E25<E$39,ISNUMBER(E25)=FALSE),E$40,E25)))) | F52: =IF(ISBLANK(F25),"NO DATA",IF(ISNUMBER(FIND(CODES!$A$12,F25)),CODES!$A$12,IF(OR(ISNUMBER(FIND(CODES!$A$10,F25)),ISNUMBER(FIND(CODES!$A$11,F25))),CODES!$A$13,IF(OR(F25<F$39,ISNUMBER(F25)=FALSE),F$40,F25)))) | G52: =IF(ISBLANK(G25),"NO DATA",IF(ISNUMBER(FIND(CODES!$A$12,G25)),CODES!$A$12,IF(OR(ISNUMBER(FIND(CODES!$A$10,G25)),ISNUMBER(FIND(CODES!$A$11,G25))),CODES!$A$13,IF(OR(G25<G$39,ISNUMBER(G25)=FALSE),G$40,G25)))) | H52: =IF(ISBLANK(H25),"NO DATA",IF(ISNUMBER(FIND(CODES!$A$12,H25)),CODES!$A$12,IF(OR(ISNUMBER(FIND(CODES!$A$10,H25)),ISNUMBER(FIND(CODES!$A$11,H25))),CODES!$A$13,IF(OR(H25<H$39,ISNUMBER(H25)=FALSE),H$40,H25)))) | I52: =IF(ISBLANK(I25),"NO DATA",IF(ISNUMBER(FIND(CODES!$A$12,I25)),CODES!$A$12,IF(OR(ISNUMBER(FIND(CODES!$A$10,I25)),ISNUMBER(FIND(CODES!$A$11,I25))),CODES!$A$13,IF(OR(I25<I$39,ISNUMBER(I25)=FALSE),I$40,I25)))) | J52: =IF(ISBLANK(J25),"NO DATA",IF(ISNUMBER(FIND(CODES!$A$12,J25)),CODES!$A$12,IF(OR(ISNUMBER(FIND(CODES!$A$10,J25)),ISNUMBER(FIND(CODES!$A$11,J25))),CODES!$A$13,IF(OR(J25<J$39,ISNUMBER(J25)=FALSE),J$40,J25)))) | ... DI52: =IF(ISBLANK(DI25),"NO DATA",IF(ISNUMBER(FIND(CODES!$A$12,DI25)),CODES!$A$12,IF(OR(ISNUMBER(FIND(CODES!$A$10,DI25)),ISNUMBER(FIND(CODES!$A$11,DI25))),CODES!$A$13,IF(OR(DI25<DI$39,ISNUMBER(DI25)=FALSE),DI$40,DI25))))
...

Sheet SUMMARY TABLE
A1: REPORT ICPOES QA/QC DATA
A3: =INSTRUCTIONS!A3
B5: ="BATCH "&BATCH!B4
B7: Total Metals | C7: Units | D7: {=TRANSPOSE(BATCH!A96:A107)} | E7: IPC CCV5 after Calibration | F7: IPC CCV5 after Batch | G7: Digest Method Blank (LRB) | H7: Digest LFB | I7: SAMPLE DUPLICATE, RPD Calculated | J7: LFM Spike | K7: Instrument LFB | L7: Instrument Interference Check | M7: Instrument ICV | N7: Digest Method Blank Comparison to Sample Matrix | O7: Digest Method Blank Comparison to 2.2X RL
B8: Silver | C8: =CODES!$A$17 | D8: {=TRANSPOSE(BATCH!C96:C107)}
B9: Aluminum | C9: =CODES!$A$17 | D9: {=TRANSPOSE(BATCH!E96:E107)}
B10: Arsenic | C10: =CODES!$A$17 | D10: {=TRANSPOSE(BATCH!F96:F107)}
B11: Boron | C11: =CODES!$A$17 | D11: {=TRANSPOSE(BATCH!I96:I107)}
B12: Barium | C12: =CODES!$A$17 | D12: {=TRANSPOSE(BATCH!K96:K107)}
B13: Beryllium | C13: =CODES!$A$17 | D13: {=TRANSPOSE(BATCH!M96:M107)}
B14: Calcium | C14: =CODES!$A$17 | D14: {=TRANSPOSE(BATCH!P96:P107)}
B15: Cadmium | C15: =CODES!$A$17 | D15: {=TRANSPOSE(BATCH!R96:R107)}
B16: Cerium | C16: =CODES!$A$17 | D16: {=TRANSPOSE(BATCH!T96:T107)}
B17: Cobalt | C17: =CODES!$A$17 | D17: {=TRANSPOSE(BATCH!V96:V107)}
B18: Chromium | C18: =CODES!$A$17 | D18: {=TRANSPOSE(BATCH!Y96:Y107)}
B19: Copper | C19: =CODES!$A$17 | D19: {=TRANSPOSE(BATCH!Z96:Z107)}
B20: Dysprosium | C20: =CODES!$A$17 | D20: {=TRANSPOSE(BATCH!AB96:AB107)}
B21: Erbium | C21: =CODES!$A$17 | D21: {=TRANSPOSE(BATCH!AD96:AD107)}
B22: Europium | C22: =CODES!$A$17 | D22: {=TRANSPOSE(BATCH!AF96:AF107)}
B23: Iron | C23: =CODES!$A$17 | D23: {=TRANSPOSE(BATCH!AH96:AH107)}
B24: Gallium | C24: =CODES!$A$17 | D24: {=TRANSPOSE(BATCH!AI96:AI107)}
B25: Gadolinium | C25: =CODES!$A$17 | D25: {=TRANSPOSE(BATCH!AL96:AL107)}
B26: Hafnium | C26: =CODES!$A$17 | D26: {=TRANSPOSE(BATCH!AN96:AN107)}
B27: Mercury | C27: =CODES!$A$16 | D27: {=TRANSPOSE(BATCH!AP96:AP107)}
B28: Holmium | C28: =CODES!$A$17 | D28: {=TRANSPOSE(BATCH!AR96:AR107)}
B29: Potassium | C29: =CODES!$A$17 | D29: {=TRANSPOSE(BATCH!AS96:AS107)}
B30: Lanthanum | C30: =CODES!$A$17 | D30: {=TRANSPOSE(BATCH!AT96:AT107)}
B31: Lutetium | C31: =CODES!$A$17 | D31: {=TRANSPOSE(BATCH!AX96:AX107)}
B32: Magnesium | C32: =CODES!$A$17 | D32: {=TRANSPOSE(BATCH!AZ96:AZ107)}
B33: Manganese | C33: =CODES!$A$17 | D33: {=TRANSPOSE(BATCH!BB96:BB107)}
B34: Molybdenum | C34: =CODES!$A$17 | D34: {=TRANSPOSE(BATCH!BD96:BD107)}
B35: Sodium | C35: =CODES!$A$17 | D35: {=TRANSPOSE(BATCH!BG96:BG107)}
B36: Niobium | C36: =CODES!$A$17 | D36: {=TRANSPOSE(BATCH!BI96:BI107)}
B37: Neodymium | C37: =CODES!$A$17 | D37: {=TRANSPOSE(BATCH!BJ96:BJ107)}
B38: Nickel | C38: =CODES!$A$17 | D38: {=TRANSPOSE(BATCH!BM96:BM107)}
B39: Phosphorus | C39: =CODES!$A$17 | D39: {=TRANSPOSE(BATCH!BP96:BP107)}
B40: Lead | C40: =CODES!$A$17 | D40: {=TRANSPOSE(BATCH!BQ96:BQ107)}
B41: Rubidium | C41: =CODES!$A$17 | D41: {=TRANSPOSE(BATCH!BR96:BR107)}
B42: Sulfur | C42: =CODES!$A$17 | D42: {=TRANSPOSE(BATCH!BT96:BT107)}
B43: Antimony | C43: =CODES!$A$17 | D43: {=TRANSPOSE(BATCH!BU96:BU107)}
...

Sheet INSTRUCTIONS
A1: INSTRUCTIONS
A3: NALS_WTRICPOES_QC_XL_20250725_Rev1
A5: ICPOES RESULTS
A6: 1. Input raw data from ICPOES run from client sample into GREEN CELLS of the "BATCH" tab. Copy and Paste using "123 Values" function.
A7: 2. Check "SUMMARY TABLE" tab to view QC Results for selected elements
A8: 3. If a fail occurs see if it falls within the comments section selection, as per SOP.
A10: CURRENT DETECTION LIMITS FILES
A11: ICPOES | B11: 2024NALS02081_ICPOES_FullMetals_DL_RL_Nov_04_2024_ICPOES
A13: CURRENT INSTRUMENT TEMPLATES
A14: ICPOES | B14: NALS_ICPOES_TEMPLATE_AUG_18_2023
A16: ACRONYMS
A17: IPC | B17: Instrument Perfomance Check
A18: LRB | B18: Lab Reagent Blank
A19: LFB | B19: Lab Fortified Blank
A20: IC | B20: Interference Check
A21: LFM | B21: Lab Fortified Matrix
A22: CCV | B22: Continuous Calibration Verification
A23: ICV | B23: Independent Calibration Verification
A25: PERCENT RECOVERY EQUATION (EPA 200.7)
A26: Percent Recovery = (Cs - C / s) *100
A27: Cs = Sample Concentration
A28: C = Sample Background
A29: s = true analyte concentration
A31: RELATIVE PERCENT DIFFERENCE EQUATION
A32: RPD = (ABS(Determined Value-True Value)/True Value)*100
A34: RELATIVE PERCENT DIFFERENCE EQUATION FOR DUPLICATES
A35: RPD = (abs(R1-R2)/((R1+R2)/2))*100
A37: ICV and CCV PERCENT RECOVERY EQUATION
A38: Percent Recovery = (Cs/s)*100
A39: Cs = Sample Concentration
A40: s = true analyte concentration

Sheet CODES
A1: DO NOT EDIT THIS PAGE
A2: =INSTRUCTIONS!A3
A4: INSTRUMENT LIST
A5: ICPOES
A6: ICPMS
A7: ICPQQQ
A9: ICPOES CODES
A10: o
A11: ####
A12: Uncal
A13: over-range
A15: UNITS
A16: µg/L
A17: mg/L
... A22: <0.0000
A23: 1000
A24: 20
A27: INSTRUMENT REPORTABLE LIMIT TABLE | C27: Ag 328.068 nm | D27: Ag 338.289 nm | E27: Al 396.152 nm | F27: As 188.980 nm | G27: As 193.696 nm | H27: B 249.678 nm | I27: B 249.772 nm | J27: Ba 493.408 nm | K27: Ba-A 455.403 nm | L27: Be 234.861 nm | M27: Be 313.042 nm | N27: Bi 222.821 nm | O27: Bi 223.061 nm | P27: Ca 317.933 nm | Q27: Ca 422.673 nm | R27: Cd 214.439 nm | S27: Cd 226.502 nm | T27: Ce 418.659 nm | U27: Ce 446.021 nm | V27: Co 238.892 nm | W27: Co 258.033 nm | X27: Cr 206.158 nm | Y27: Cr 267.716 nm | Z27: Cu-A 327.395 nm | AA27: Dy 340.780 nm | AB27: Dy 353.171 nm | AC27: Er 337.275 nm | AD27: Er 349.910 nm | AE27: Eu 397.197 nm | AF27: Eu 420.504 nm | AG27: Fe 234.350 nm | AH27: Fe 238.204 nm | AI27: Ga 294.363 nm | AJ27: Ga 417.204 nm | AK27: Gd 335.048 nm | AL27: Gd 342.246 nm | AM27: Hf 263.872 nm | AN27: Hf 264.141 nm | AO27: Hg 184.887 nm | AP27: Hg 194.164 nm | AQ27: Ho 339.895 nm | AR27: Ho 345.600 nm | AS27: K 766.491 nm | AT27: La 333.749 nm | AU27: La 379.477 nm | AV27: Li 610.365 nm | AW27: Li 670.783 nm | AX27: Lu 261.541 nm | AY27: Lu 291.139 nm | AZ27: Mg 280.270 nm | BA27: Mg 285.213 nm | BB27: Mn 257.610 nm | BC27: Mn 294.921 nm | BD27: Mo 202.032 nm | BE27: Mo 204.598 nm | BF27: Na 588.995 nm | BG27: Na 589.592 nm | BH27: Nb 309.417 nm | BI27: Nb 313.078 nm | BJ27: Nd 401.224 nm | BK27: Nd 406.108 nm | BL27: Ni 216.555 nm | BM27: Ni 231.604 nm | BN27: P 177.434 nm | BO27: P 178.222 nm | BP27: P 213.618 nm | BQ27: Pb 220.353 nm | BR27: Rb 780.026 nm | BS27: S 180.669 nm | BT27: S 181.972 nm | BU27: Sb 206.834 nm | BV27: Sb 217.582 nm | BW27: Sc 335.372 nm | BX27: Sc 361.383 nm | BY27: Se 196.026 nm | BZ27: Se 203.985 nm | CA27: Si 251.611 nm | CB27: Si 288.158 nm | CC27: Sm 359.259 nm | CD27: Sm 360.949 nm | CE27: Sn 189.925 nm | CF27: Sn 283.998 nm | CG27: Sr-R 407.771 nm | CH27: Sr-R 421.552 nm | CI27: Ta 263.558 nm | CJ27: Ta 268.517 nm | CK27: Te 182.153 nm | CL27: Te 214.282 nm | CM27: Th 269.242 nm | CN27: Th 283.730 nm | CO27: Ti 334.941 nm | CP27: Ti 336.122 nm | CQ27: Tl 190.794 nm | CR27: Tl 276.789 nm | CS27: Tl 351.923 nm | CT27: Tm 313.125 nm | CU27: Tm 342.508 nm | CV27: U 367.007 nm | CW27: U 385.957 nm | CX27: V 292.401 nm | CY27: V 309.310 nm | CZ27: W 207.912 nm | DA27: W 209.475 nm | DB27: Y 360.074 nm | DC27: Y 371.029 nm | DD27: Yb 328.937 nm | DE27: Yb 369.419 nm | DF27: Zn 202.548 nm | DG27: Zn 213.857 nm | DH27: Zr 339.198 nm | DI27: Zr 343.823 nm
C28: Conc. (mg/L) | D28: Conc. (mg/L) | E28: Conc. (mg/L) | F28: Conc. (mg/L) | G28: Conc. (mg/L) | H28: Conc. (mg/L) | I28: Conc. (mg/L) | J28: Conc. (mg/L) | K28: Conc. (mg/L) | L28: Conc. (mg/L) | M28: Conc. (µg/L) | N28: Conc. (mg/L) | O28: Conc. (mg/L) | P28: Conc. (mg/L) | Q28: Conc. (mg/L) | R28: Conc. (mg/L) | S28: Conc. (mg/L) | T28: Conc. (mg/L) | U28: Conc. (mg/L) | V28: Conc. (mg/L) | W28: Conc. (mg/L) | X28: Conc. (mg/L) | Y28: Conc. (mg/L) | Z28: Conc. (mg/L) | AA28: Conc. (mg/L) | AB28: Conc. (mg/L) | AC28: Conc. (mg/L) | AD28: Conc. (mg/L) | AE28: Conc. (mg/L) | AF28: Conc. (mg/L) | AG28: Conc. (mg/L) | AH28: Conc. (mg/L) | AI28: Conc. (mg/L) | AJ28: Conc. (mg/L) | AK28: Conc. (mg/L) | AL28: Conc. (mg/L) | AM28: Conc. (mg/L) | AN28: Conc. (mg/L) | AO28: Conc. (µg/L) | AP28: Conc. (µg/L) | AQ28: Conc. (mg/L) | AR28: Conc. (mg/L) | AS28: Conc. (mg/L) | AT28: Conc. (mg/L) | AU28: Conc. (mg/L) | AV28: Conc. (mg/L) | AW28: Conc. (mg/L) | AX28: Conc. (mg/L) | AY28: Conc. (mg/L) | AZ28: Conc. (mg/L) | BA28: Conc. (mg/L) | BB28: Conc. (mg/L) | BC28: Conc. (mg/L) | BD28: Conc. (mg/L) | BE28: Conc. (mg/L) | BF28: Conc. (mg/L) | BG28: Conc. (mg/L) | BH28: Conc. (mg/L) | BI28: Conc. (mg/L) | BJ28: Conc. (mg/L) | BK28: Conc. (mg/L) | BL28: Conc. (mg/L) | BM28: Conc. (mg/L) | BN28: Conc. (mg/L) | BO28: Conc. (mg/L) | BP28: Conc. (mg/L) | BQ28: Conc. (mg/L) | BR28: Conc. (mg/L) | BS28: Conc. (mg/L) | BT28: Conc. (mg/L) | BU28: Conc. (mg/L) | BV28: Conc. (mg/L) | BW28: Conc. (mg/L) | BX28: Conc. (mg/L) | BY28: Conc. (mg/L) | BZ28: Conc. (mg/L) | CA28: Conc. (mg/L) | CB28: Conc. (mg/L) | CC28: Conc. (mg/L) | CD28: Conc. (mg/L) | CE28: Conc. (mg/L) | CF28: Conc. (mg/L) | CG28: Conc. (mg/L) | CH28: Conc. (mg/L) | CI28: Conc. (mg/L) | CJ28: Conc. (mg/L) | CK28: Conc. (mg/L) | CL28: Conc. (mg/L) | CM28: Conc. (mg/L) | CN28: Conc. (mg/L) | CO28: Conc. (mg/L) | CP28: Conc. (mg/L) | CQ28: Conc. (mg/L) | CR28: Conc. (mg/L) | CS28: Conc. (mg/L) | CT28: Conc. (mg/L) | CU28: Conc. (mg/L) | CV28: Conc. (mg/L) | CW28: Conc. (mg/L) | CX28: Conc. (mg/L) | CY28: Conc. (mg/L) | CZ28: Conc. (mg/L) | DA28: Conc. (mg/L) | DB28: Conc. (mg/L) | DC28: Conc. (mg/L) | DD28: Conc. (mg/L) | DE28: Conc. (mg/L) | DF28: Conc. (mg/L) | DG28: Conc. (mg/L) | DH28: Conc. (mg/L) | DI28: Conc. (mg/L)
A29: Reportable Limit (3xMDL) | B29: Reportable Limit (No Dilution) | C29: 0.007 | D29: 0.009 | E29: 0.012 | F29: 0.013 | G29: 0.014 | H29: 0.0017 | I29: 0.0011 | J29: 0.0007 | K29: 0.001 | L29: 0.0005 | M29: 0.0015 | N29: n/a | O29: n/a | P29: 0.004 | Q29: 0.02 | R29: 0.0007 | S29: 0.0007 | T29: 0.001 | U29: 0.002 | V29: 0.0009 | W29: 0.0014 | X29: 0.0032 | Y29: 0.0005 | Z29: 0.0007 | AA29: 0.002 | AB29: 0.001 | AC29: 0.0003 | AD29: 0.001 | AE29: 0.0005 | AF29: 0.0003 | AG29: 0.0067 | AH29: 0.0025 | AI29: 0.004 | AJ29: 0.005 | AK29: 0.001 | AL29: 0.001 | AM29: 0.002 | AN29: 0.001 | AO29: 7 | AP29: 7 | AQ29: 0.002 | AR29: 0.001 | AS29: 0.002 | AT29: 0.0004 | AU29: 0.0003 | AV29: n/a | AW29: n/a | AX29: 0.0004 | AY29: 0.001 | AZ29: 0.0007 | BA29: 0.0041 | BB29: 0.0007 | BC29: 0.0035 | BD29: 0.0023 | BE29: 0.0022 | BF29: 0.0069 | BG29: 0.0011 | BH29: 0.01 | BI29: 0.06 | BJ29: 0.003 | BK29: 0.002 | BL29: 0.0017 | BM29: 0.0009 | BN29: n/a | BO29: n/a | BP29: 0.011 | BQ29: 0.0053 | BR29: 0.007 | BS29: 0.056 | BT29: 0.034 | BU29: 0.011 | BV29: 0.007 | BW29: n/a | BX29: n/a | BY29: 0.018 | BZ29: 0.025 | CA29: 0.004 | CB29: 0.003 | CC29: 0.001 | CD29: 0.002 | CE29: 0.01 | CF29: 0.005 | CG29: 0.0003 | CH29: 0.0005 | CI29: 0.003 | CJ29: 0.004 | CK29: 0.1 | CL29: 0.01 | CM29: 0.01 | CN29: 0.003 | CO29: 0.0005 | CP29: 0.0005 | CQ29: 0.01 | CR29: 0.03 | CS29: 0.02 | CT29: 0.002 | CU29: 0.001 | CV29: 0.03 | CW29: 0.012 | CX29: 0.0008 | CY29: 0.003 | CZ29: 0.005 | DA29: 0.01 | DB29: n/a | DC29: n/a | DD29: 0.0003 | DE29: 0.0004 | DF29: 0.001 | DG29: 0.0007 | DH29: 0.0006 | DI29: 0.0005
A30: Reportable Limit (3xMDL) | B30: Reportable Limit (No Dilution) | C30: <0.007 | D30: <0.009 | E30: <0.012 | F30: <0.013 | G30: <0.014 | H30: <0.0017 | I30: <0.0011 | J30: <0.0007 | K30: <0.0010 | L30: <0.0005 | M30: <0.0015 | N30: n/a | O30: n/a | P30: <0.004 | Q30: <0.02 | R30: <0.0007 | S30: <0.0007 | T30: <0.001 | U30: <0.002 | V30: <0.0009 | W30: <0.0014 | X30: <0.0032 | Y30: <0.0005 | Z30: <0.0007 | AA30: <0.002 | AB30: <0.001 | AC30: <0.0003 | AD30: <0.001 | AE30: <0.0005 | AF30: <0.0003 | AG30: <0.0067 | AH30: <0.0025 | AI30: <0.004 | AJ30: <0.005 | AK30: <0.001 | AL30: <0.001 | AM30: <0.002 | AN30: <0.001 | AO30: <7 | AP30: <7 | AQ30: <0.002 | AR30: <0.001 | AS30: <0.002 | AT30: <0.0004 | AU30: <0.0003 | AV30: n/a | AW30: n/a | AX30: <0.0004 | AY30: <0.001 | AZ30: <0.0007 | BA30: <0.0041 | BB30: <0.0007 | BC30: <0.0035 | BD30: <0.0023 | BE30: <0.0022 | BF30: <0.0069 | BG30: <0.0011 | BH30: <0.01 | BI30: <0.06 | BJ30: <0.003 | BK30: <0.002 | BL30: <0.0017 | BM30: <0.0009 | BN30: n/a | BO30: n/a | BP30: <0.011 | BQ30: <0.0053 | BR30: <0.007 | BS30: <0.056 | BT30: <0.034 | BU30: <0.011 | BV30: <0.007 | BW30: n/a | BX30: n/a | BY30: <0.018 | BZ30: <0.025 | CA30: <0.004 | CB30: <0.003 | CC30: <0.001 | CD30: <0.002 | CE30: <0.010 | CF30: <0.005 | CG30: <0.0003 | CH30: <0.0005 | CI30: <0.003 | CJ30: <0.004 | CK30: <0.1 | CL30: <0.01 | CM30: <0.01 | CN30: <0.003 | CO30: <0.0005 | CP30: <0.0005 | CQ30: <0.01 | CR30: <0.03 | CS30: <0.02 | CT30: <0.002 | CU30: <0.001 | CV30: <0.03 | CW30: <0.012 | CX30: <0.0008 | CY30: <0.003 | CZ30: <0.005 | DA30: <0.01 | DB30: n/a | DC30: n/a | DD30: <0.0003 | DE30: <0.0004 | DF30: <0.0010 | DG30: <0.0007 | DH30: <0.0006 | DI30: <0.0005
A32: PERCENT RECOVERIES | B32: PERCENT | C32: LOW END, % | D32: UPPER END, %
A33: IPC Blank (NALS Blank) | B33: <RL | E33: <-- EPA 200.7, Section 9.3.4
A34: IPC CCV5 after Calibration | B34: 10 | C34: 90 | D34: 110 | E34: <-- EPA 200.7, Section 9.3.4
A35: IPC CCV5 after Batch | B35: 10 | C35: 90 | D35: 110 | E35: <-- EPA 200.7, Section 9.3.4
A36: Digest Method Blank (LRB) | B36: <RL or up to 10% of sample matrix or 2.2X RL | C36: 10 | D36: 2.2 | E36: <-- EPA 200.7, Section 9.3.1
A37: Digest LFB | B37: 20 | C37: 80 | D37: 120 | E37: <-- EPA 200.7, Section 9.3.2
A38: SAMPLE, RPD Calculated | E38: <-- Standard Method for the Examination of Water and Wastewater, Section 1020 B. Quality Control, and BCMOE SECTION C METALS C-9 Quality Control Table
A39: SAMPLE DUPLICATE, RPD Calculated | B39: 20 | C39: 80 | D39: 120 | E39: <-- Standard Method for the Examination of Water and Wastewater, Section 1020 B. Quality Control, and BCMOE SECTION C METALS C-9 Quality Control Table
A40: LFM Background | E40: <-- Used for calculation for LFM
A41: LFM Spike | B41: 30 | C41: 70 | D41: 130 | E41: <-- EPA 200.7, Section 9.3.5
A42: Instrument LFB | B42: 20 | C42: 80 | D42: 120 | E42: <-- EPA 200.7, Section 9.3.2
A43: Instrument Interference Check | B43: 30 | C43: 70 | D43: 130 | E43: <-- EPA 200.7, Section 9.3.5, while not stated, using LFM values
A44: Instrument ICV | B44: 5 | C44: 95 | D44: 105 | E44: <-- Standard Method for the Examination of Water and Wastewater, Section 1020 B. Quality Control 1. 'First Paragraph'
B47: All Metals Except Hg (mg/L) | C47: Hg (ug/L)
A48: SPIKE AMOUNT (UNDILUTED) | B48: 0.1 | C48: 10
A49: CCV5 Amount | B49: 0.5 | C49: 50
A50: ICV Amount | B50: 0.5 | C50: 50

Sheet TRACKED CHANGES
A1: DATE | B1: VERSION | C1: AUTHOR | D1: EDITS
A2: 45841 | B2: NALS_WTRICPOES_QC_XL_20250703_Rev0 | C2: Erwin Rehl | D2: Entire excel workbook was created by Erwin
A3: 45863 | B3: NALS_WTRICPOES_QC_XL_20250703_Rev0 | C3: Erwin Rehl | D3: Updated ICV and CCV5 equation to not use blank subtraction as they are not diluted into matrix solution after being made. Included equation in "Instructions Tab".

Sheet BATCH VERIFICATION
A1: University of Northern British Columbia
A2: Northern Analytical Laboratory Services
A3: QA/QC Report File (Processing) | B3: =INSTRUCTIONS!A3
A4: BATCH | B4: A
A6: Analyst: | B6: Erwin
A7: NALS Director: | B7: Dr. Hossein Kazemian
A9: Date: | B9: 45819
A10: Client Name: | B10: Multiple Clients
A11: Supervisor: | B11: n/a
A12: Client Company Name: | B12: n/a
A13: Reference File: | B13: 2025NALS02286_2290_2293_2296
A14: Number of Samples: | B14: 1+2+1+2
A15: Detection Limits File: | B15: =INSTRUCTIONS!B11
A17: ICPOES (Raw Data from QA/QC from UNADJUSTED DATA) | C17: Ag 328.068 nm | D17: Ag 338.289 nm | E17: Al 396.152 nm | F17: As 188.980 nm | G17: As 193.696 nm | H17: B 249.678 nm | I17: B 249.772 nm | J17: Ba 493.408 nm | K17: Ba-A 455.403 nm | L17: Be 234.861 nm | M17: Be 313.042 nm | N17: Bi 222.821 nm | O17: Bi 223.061 nm | P17: Ca 317.933 nm | Q17: Ca 422.673 nm | R17: Cd 214.439 nm | S17: Cd 226.502 nm | T17: Ce 418.659 nm | U17: Ce 446.021 nm | V17: Co 238.892 nm | W17: Co 258.033 nm | X17: Cr 206.158 nm | Y17: Cr 267.716 nm | Z17: Cu-A 327.395 nm | AA17: Dy 340.780 nm | AB17: Dy 353.171 nm | AC17: Er 337.275 nm | AD17: Er 349.910 nm | AE17: Eu 397.197 nm | AF17: Eu 420.504 nm | AG17: Fe 234.350 nm | AH17: Fe 238.204 nm | AI17: Ga 294.363 nm | AJ17: Ga 417.204 nm | AK17: Gd 335.048 nm | AL17: Gd 342.246 nm | AM17: Hf 263.872 nm | AN17: Hf 264.141 nm | AO17: Hg 184.887 nm | AP17: Hg 194.164 nm | AQ17: Ho 339.895 nm | AR17: Ho 345.600 nm | AS17: K 766.491 nm | AT17: La 333.749 nm | AU17: La 379.477 nm | AV17: Li 610.365 nm | AW17: Li 670.783 nm | AX17: Lu 261.541 nm | AY17: Lu 291.139 nm | AZ17: Mg 280.270 nm | BA17: Mg 285.213 nm | BB17: Mn 257.610 nm | BC17: Mn 294.921 nm | BD17: Mo 202.032 nm | BE17: Mo 204.598 nm | BF17: Na 588.995 nm | BG17: Na 589.592 nm | BH17: Nb 309.417 nm | BI17: Nb 313.078 nm | BJ17: Nd 401.224 nm | BK17: Nd 406.108 nm | BL17: Ni 216.555 nm | BM17: Ni 231.604 nm | BN17: P 177.434 nm | BO17: P 178.222 nm | BP17: P 213.618 nm | BQ17: Pb 220.353 nm | BR17: Rb 780.026 nm | BS17: S 180.669 nm | BT17: S 181.972 nm | BU17: Sb 206.834 nm | BV17: Sb 217.582 nm | BW17: Sc 335.372 nm | BX17: Sc 361.383 nm | BY17: Se 196.026 nm | BZ17: Se 203.985 nm | CA17: Si 251.611 nm | CB17: Si 288.158 nm | CC17: Sm 359.259 nm | CD17: Sm 360.949 nm | CE17: Sn 189.925 nm | CF17: Sn 283.998 nm | CG17: Sr-R 407.771 nm | CH17: Sr-R 421.552 nm | CI17: Ta 263.558 nm | CJ17: Ta 268.517 nm | CK17: Te 182.153 nm | CL17: Te 214.282 nm | CM17: Th 269.242 nm | CN17: Th 283.730 nm | CO17: Ti 334.941 nm | CP17: Ti 336.122 nm | CQ17: Tl 190.794 nm | CR17: Tl 276.789 nm | CS17: Tl 351.923 nm | CT17: Tm 313.125 nm | CU17: Tm 342.508 nm | CV17: U 367.007 nm | CW17: U 385.957 nm | CX17: V 292.401 nm | CY17: V 309.310 nm | CZ17: W 207.912 nm | DA17: W 209.475 nm | DB17: Y 360.074 nm | DC17: Y 371.029 nm | DD17: Yb 328.937 nm | DE17: Yb 369.419 nm | DF17: Zn 202.548 nm | DG17: Zn 213.857 nm | DH17: Zr 339.198 nm | DI17: Zr 343.823 nm
A18: QA/QC SAMPLES NAMES | B18: Comment | C18: Conc. (mg/L) | D18: Conc. (mg/L) | E18: Conc. (mg/L) | F18: Conc. (mg/L) | G18: Conc. (mg/L) | H18: Conc. (mg/L) | I18: Conc. (mg/L) | J18: Conc. (mg/L) | K18: Conc. (mg/L) | L18: Conc. (mg/L) | M18: Conc. (µg/L) | N18: Conc. (mg/L) | O18: Conc. (mg/L) | P18: Conc. (mg/L) | Q18: Conc. (mg/L) | R18: Conc. (mg/L) | S18: Conc. (mg/L) | T18: Conc. (mg/L) | U18: Conc. (mg/L) | V18: Conc. (mg/L) | W18: Conc. (mg/L) | X18: Conc. (mg/L) | Y18: Conc. (mg/L) | Z18: Conc. (mg/L) | AA18: Conc. (mg/L) | AB18: Conc. (mg/L) | AC18: Conc. (mg/L) | AD18: Conc. (mg/L) | AE18: Conc. (mg/L) | AF18: Conc. (mg/L) | AG18: Conc. (mg/L) | AH18: Conc. (mg/L) | AI18: Conc. (mg/L) | AJ18: Conc. (mg/L) | AK18: Conc. (mg/L) | AL18: Conc. (mg/L) | AM18: Conc. (mg/L) | AN18: Conc. (mg/L) | AO18: Conc. (µg/L) | AP18: Conc. (µg/L) | AQ18: Conc. (mg/L) | AR18: Conc. (mg/L) | AS18: Conc. (mg/L) | AT18: Conc. (mg/L) | AU18: Conc. (mg/L) | AV18: Conc. (mg/L) | AW18: Conc. (mg/L) | AX18: Conc. (mg/L) | AY18: Conc. (mg/L) | AZ18: Conc. (mg/L) | BA18: Conc. (mg/L) | BB18: Conc. (mg/L) | BC18: Conc. (mg/L) | BD18: Conc. (mg/L) | BE18: Conc. (mg/L) | BF18: Conc. (mg/L) | BG18: Conc. (mg/L) | BH18: Conc. (mg/L) | BI18: Conc. (mg/L) | BJ18: Conc. (mg/L) | BK18: Conc. (mg/L) | BL18: Conc. (mg/L) | BM18: Conc. (mg/L) | BN18: Conc. (mg/L) | BO18: Conc. (mg/L) | BP18: Conc. (mg/L) | BQ18: Conc. (mg/L) | BR18: Conc. (mg/L) | BS18: Conc. (mg/L) | BT18: Conc. (mg/L) | BU18: Conc. (mg/L) | BV18: Conc. (mg/L) | BW18: Conc. (mg/L) | BX18: Conc. (mg/L) | BY18: Conc. (mg/L) | BZ18: Conc. (mg/L) | CA18: Conc. (mg/L) | CB18: Conc. (mg/L) | CC18: Conc. (mg/L) | CD18: Conc. (mg/L) | CE18: Conc. (mg/L) | CF18: Conc. (mg/L) | CG18: Conc. (mg/L) | CH18: Conc. (mg/L) | CI18: Conc. (mg/L) | CJ18: Conc. (mg/L) | CK18: Conc. (mg/L) | CL18: Conc. (mg/L) | CM18: Conc. (mg/L) | CN18: Conc. (mg/L) | CO18: Conc. (mg/L) | CP18: Conc. (mg/L) | CQ18: Conc. (mg/L) | CR18: Conc. (mg/L) | CS18: Conc. (mg/L) | CT18: Conc. (mg/L) | CU18: Conc. (mg/L) | CV18: Conc. (mg/L) | CW18: Conc. (mg/L) | CX18: Conc. (mg/L) | CY18: Conc. (mg/L) | CZ18: Conc. (mg/L) | DA18: Conc. (mg/L) | DB18: Conc. (mg/L) | DC18: Conc. (mg/L) | DD18: Conc. (mg/L) | DE18: Conc. (mg/L) | DF18: Conc. (mg/L) | DG18: Conc. (mg/L) | DH18: Conc. (mg/L) | DI18: Conc. (mg/L)
A19: IPC Blank after Calibration (NALS Blank) | B19: IPC Blank | C19: 0.0017 | D19: -0.0002 u | E19: -0.0042 u | F19: -0.0066 u | G19: 0.0037 | H19: 0.0001 u | I19: 0.0002 | J19: 0.0000 u | K19: 0 | L19: 0.0000 u | M19: 0.0004 | N19: Uncal | O19: Uncal | P19: -0.0068 u | Q19: -0.0114 u | R19: 0.0001 | S19: -0.0001 u | T19: 0.0000 u | U19: 0.0002 | V19: -0.0001 u | W19: 0.0001 u | X19: -0.0021 u | Y19: 0.0001 | Z19: 0.0001 u | AA19: 0.0004 u | AB19: 0.0000 u | AC19: 0.0002 | AD19: 0.0000 u | AE19: 0.0001 | AF19: 0.0000 u | AG19: 0.0015 | AH19: 0.0016 | AI19: 0.0006 | AJ19: 0.0006 u | AK19: 0.0001 u | AL19: -0.0001 u | AM19: 0.0001 u | AN19: 0.0003 | AO19: 1.2945 | AP19: -2.3549 u | AQ19: -0.0003 u | AR19: -0.0001 u | AS19: 0.0001 u | AT19: 0.0000 u | AU19: 0.0000 u | AV19: Uncal | AW19: Uncal | AX19: 0.0000 u | AY19: 0.0001 u | AZ19: 0.0000 u | BA19: -0.0006 u | BB19: 0.0002 | BC19: 0.0012 | BD19: 0.0008 | BE19: 0.0019 | BF19: -0.0025 u | BG19: 0.0001 u | BH19: 0.0008 | BI19: -0.0053 u | BJ19: 0.0002 | BK19: 0.0003 u | BL19: 0.0004 | BM19: -0.0003 u | BN19: Uncal | BO19: -0.0089 u | BP19: 0.0051 | BQ19: 0.0006 | BR19: 0.0009 u | BS19: 0.0000 u | BT19: -0.0032 u | BU19: 0.0020 u | BV19: 0.0043 | BW19: Uncal | BX19: Uncal | BY19: 0.0017 u | BZ19: -0.0037 u | CA19: -0.0001 u | CB19: 0.0002 | CC19: 0.0001 | CD19: -0.0002 u | CE19: -0.0038 u | CF19: -0.0002 u | CG19: 0.0000 u | CH19: -0.0001 u | CI19: 0.0001 u | CJ19: 0.0003 u | CK19: 0.0008 u | CL19: 0.0007 u | CM19: -0.0012 u | CN19: 0.0001 u | CO19: 0.0004 | CP19: 0.0003 | CQ19: 0.0008 u | CR19: -0.0047 u | CS19: -0.0045 u | CT19: -0.0003 u | CU19: 0.0000 u | CV19: 0.0002 u | CW19: -0.0002 u | CX19: -0.0003 u | CY19: 0 | CZ19: 0.003 | DA19: 0.0044 | DB19: Uncal | DC19: Uncal | DD19: 0 | DE19: 0.0000 u | DF19: 0.0000 u | DG19: -0.0003 u | DH19: 0.0000 u | DI19: 0.0000 u
A20: IPC CCV5 after Calibration | B20: CCV 500ppb | C20: 0.4009 | D20: 0.4004 | E20: 0.5087 | F20: 0.4977 | G20: 0.5047 | H20: 0.4992 | I20: 0.5045 | J20: 0.4975 | K20: 0.5006 | L20: 0.5044 | M20: 0.515 | N20: Uncal | O20: Uncal | P20: 0.4992 | Q20: 0.5017 | R20: 0.4998 | S20: 0.5076 | T20: 0.5011 | U20: 0.4977 | V20: 0.4989 | W20: 0.4996 | X20: 0.5028 | Y20: 0.502 | Z20: 0.5 | AA20: 0.505 | AB20: 0.5032 | AC20: 0.5128 | AD20: 0.5049 | AE20: 0.5144 | AF20: 0.5103 | AG20: 0.5152 | AH20: 0.5153 | AI20: 0.4994 | AJ20: 0.5002 | AK20: 0.5011 | AL20: 0.5029 | AM20: 0.5001 | AN20: 0.499 | AO20: 49.5219 | AP20: 47.9035 | AQ20: 0.5034 | AR20: 0.5005 | AS20: 0.5123 | AT20: 0.5055 | AU20: 0.5015 | AV20: Uncal | AW20: Uncal | AX20: 0.5006 | AY20: 0.4996 | AZ20: 0.5099 | BA20: 0.5056 | BB20: 0.5041 | BC20: 0.5022 | BD20: 0.5 | BE20: 0.5002 | BF20: 0.5015 | BG20: 0.5128 | BH20: 0.5004 | BI20: 0.4861 | BJ20: 0.4974 | BK20: 0.5019 | BL20: 0.5032 | BM20: 0.5006 | BN20: Uncal | BO20: 0.5344 | BP20: 0.513 | BQ20: 0.4979 | BR20: 0.4861 | BS20: 0.4846 | BT20: 0.4936 | BU20: 0.4875 | BV20: 0.4852 | BW20: Uncal | BX20: Uncal | BY20: 0.504 | BZ20: 0.5092 | CA20: 0.4997 | CB20: 0.4975 | CC20: 0.5082 | CD20: 0.5073 | CE20: 0.5062 | CF20: 0.503 | CG20: 0.4999 | CH20: 0.4994 | CI20: 0.51 | CJ20: 0.5094 | CK20: 0.4998 | CL20: 0.5057 | CM20: 0.4938 | CN20: 0.5162 | CO20: 0.499 | CP20: 0.5035 | CQ20: 0.5024 | CR20: 0.4957 | CS20: 0.502 | CT20: 0.5567 | CU20: 0.503 | CV20: 0.4891 | CW20: 0.5032 | CX20: 0.506 | CY20: 0.5207 | CZ20: 0.4976 | DA20: 0.4948 | DB20: Uncal | DC20: Uncal | DD20: 0.5042 | DE20: 0.507 | DF20: 0.4997 | DG20: 0.5003 | DH20: 0.5038 | DI20: 0.5025
A21: IPC CCV5 after Batch | B21: CCV 500ppb | C21: 0.4 | D21: 0.3967 | E21: 0.5042 | F21: 0.4965 | G21: 0.506 | H21: 0.5002 | I21: 0.5054 | J21: 0.4992 | K21: 0.5018 | L21: 0.5041 | M21: 0.5166 | N21: Uncal | O21: Uncal | P21: 0.4985 | Q21: 0.4975 | R21: 0.5003 | S21: 0.5073 | T21: 0.5014 | U21: 0.4986 | V21: 0.4995 | W21: 0.5008 | X21: 0.5043 | Y21: 0.5015 | Z21: 0.5005 | AA21: 0.5048 | AB21: 0.5043 | AC21: 0.5105 | AD21: 0.5048 | AE21: 0.5137 | AF21: 0.5108 | AG21: 0.5024 | AH21: 0.5024 | AI21: 0.5004 | AJ21: 0.5011 | AK21: 0.5003 | AL21: 0.5039 | AM21: 0.4994 | AN21: 0.4977 | AO21: 49.3751 | AP21: 49.0272 | AQ21: 0.503 | AR21: 0.5002 | AS21: 0.5143 | AT21: 0.5032 | AU21: 0.5027 | AV21: Uncal | AW21: Uncal | AX21: 0.5014 | AY21: 0.4994 | AZ21: 0.5095 | BA21: 0.5027 | BB21: 0.5034 | BC21: 0.5016 | BD21: 0.5016 | BE21: 0.5029 | BF21: 0.5091 | BG21: 0.516 | BH21: 0.4974 | BI21: 0.4851 | BJ21: 0.4989 | BK21: 0.5019 | BL21: 0.5032 | BM21: 0.5003 | BN21: Uncal | BO21: 0.5082 | BP21: 0.5068 | BQ21: 0.4969 | BR21: 0.4867 | BS21: 0.4997 | BT21: 0.5025 | BU21: 0.4916 | BV21: 0.4873 | BW21: Uncal | BX21: Uncal | BY21: 0.5107 | BZ21: 0.5116 | CA21: 0.5012 | CB21: 0.4998 | CC21: 0.5109 | CD21: 0.5075 | CE21: 0.5065 | CF21: 0.503 | CG21: 0.504 | CH21: 0.5028 | CI21: 0.5092 | CJ21: 0.5068 | CK21: 0.5268 | CL21: 0.5038 | CM21: 0.495 | CN21: 0.5158 | CO21: 0.5009 | CP21: 0.503 | CQ21: 0.503 | CR21: 0.4949 | CS21: 0.4948 | CT21: 0.5588 | CU21: 0.5042 | CV21: 0.4918 | CW21: 0.5029 | CX21: 0.5063 | CY21: 0.521 | CZ21: 0.4966 | DA21: 0.4944 | DB21: Uncal | DC21: Uncal | DD21: 0.505 | DE21: 0.5097 | DF21: 0.5007 | DG21: 0.5018 | DH21: 0.5049 | DI21: 0.5038
A22: Digest Method Blank (LRB) | B22: 2025NALS02293 A01 | C22: 0.0004 | D22: -0.0002 u | E22: 0.0012 u | F22: -0.0036 u | G22: 0.0041 | H22: 0.0006 | I22: 0.0006 | J22: -0.0003 u | K22: 0.0000 u | L22: 0.0000 u | M22: 0.0004 | N22: Uncal | O22: Uncal | P22: -0.0042 u | Q22: -0.0023 u | R22: 0.0001 | S22: -0.0001 u | T22: -0.0001 u | U22: 0.0001 | V22: 0.0000 u | W22: -0.0001 u | X22: -0.0009 u | Y22: 0.0001 | Z22: 0.0000 u | AA22: 0.0002 u | AB22: 0.0000 u | AC22: 0.0000 u | AD22: 0 | AE22: 0.0000 u | AF22: 0.0000 u | AG22: -0.0001 u | AH22: -0.0001 u | AI22: 0.0005 | AJ22: 0.0005 | AK22: 0.0002 u | AL22: -0.0001 u | AM22: -0.0001 u | AN22: 0.0001 u | AO22: 0.5189 u | AP22: -1.5927 u | AQ22: -0.0003 u | AR22: -0.0002 u | AS22: -0.0005 u | AT22: -0.0001 u | AU22: 0.0000 u | AV22: Uncal | AW22: Uncal | AX22: 0.0000 u | AY22: 0.0001 u | AZ22: 0.0003 | BA22: 0.0005 u | BB22: 0.0000 u | BC22: 0.0012 | BD22: -0.0001 u | BE22: 0.0007 | BF22: 0.0003 u | BG22: 0.0025 | BH22: -0.0003 u | BI22: -0.0105 u | BJ22: 0.0000 u | BK22: 0.0004 | BL22: 0.0008 | BM22: -0.0002 u | BN22: Uncal | BO22: 0.0067 u | BP22: 0.0076 | BQ22: 0.0014 | BR22: 0.0013 | BS22: 0.0028 u | BT22: 0.0071 | BU22: 0.0012 u | BV22: 0.0016 u | BW22: Uncal | BX22: Uncal | BY22: -0.0034 u | BZ22: -0.0004 u | CA22: 0.0092 | CB22: 0.0094 | CC22: 0.0002 | CD22: -0.0002 u | CE22: -0.0017 u | CF22: -0.0002 u | CG22: 0.0000 u | CH22: 0.0000 u | CI22: -0.0001 u | CJ22: 0.0003 u | CK22: -0.0144 u | CL22: -0.0006 u | CM22: -0.0013 u | CN22: 0.0004 | CO22: 0 | CP22: 0.0001 | CQ22: 0.0002 u | CR22: -0.0024 u | CS22: -0.0052 u | CT22: -0.0001 u | CU22: -0.0002 u | CV22: -0.0019 u | CW22: 0.0004 u | CX22: -0.0002 u | CY22: 0.0000 u | CZ22: 0.0009 | DA22: -0.0017 u | DB22: Uncal | DC22: Uncal | DD22: 0 | DE22: 0.0000 u | DF22: 0.0005 | DG22: 0.0004 | DH22: 0.0000 u | DI22: 0.0000 u
A23: Digest LFB | B23: 2025NALS02293 A02 | C23: 0.0297 | D23: 0.0231 | E23: 0.1032 | F23: 0.0967 | G23: 0.0966 | H23: 0.102 | I23: 0.1024 | J23: 0.1033 | K23: 0.1043 | L23: 0.1031 | M23: 0.1058 | N23: Uncal | O23: Uncal | P23: 0.0974 | Q23: 0.1 | R23: 0.1021 | S23: 0.1031 | T23: 0.0924 | U23: 0.0938 | V23: 0.1038 | W23: 0.1034 | X23: 0.1015 | Y23: 0.103 | Z23: 0.1032 | AA23: 0.1015 | AB23: 0.1032 | AC23: 0.1026 | AD23: 0.1026 | AE23: 0.1054 | AF23: 0.1047 | AG23: 0.1032 | AH23: 0.1037 | AI23: 0.0983 | AJ23: 0.1002 | AK23: 0.1016 | AL23: 0.1024 | AM23: 0.1 | AN23: 0.099 | AO23: 9.1142 | AP23: 7.971 | AQ23: 0.1026 | AR23: 0.1025 | AS23: 0.1006 | AT23: 0.1027 | AU23: 0.1027 | AV23: Uncal | AW23: Uncal | AX23: 0.1024 | AY23: 0.1028 | AZ23: 0.1044 | BA23: 0.1042 | BB23: 0.102 | BC23: 0.1026 | BD23: 0.105 | BE23: 0.1074 | BF23: 0.1037 | BG23: 0.1048 | BH23: 0.0851 | BI23: 0.0779 | BJ23: 0.0977 | BK23: 0.103 | BL23: 0.1045 | BM23: 0.1029 | BN23: Uncal | BO23: 0.1145 | BP23: 0.105 | BQ23: 0.1011 | BR23: 0.0962 | BS23: 0.0962 | BT23: 0.1036 | BU23: 0.0995 | BV23: 0.0999 | BW23: Uncal | BX23: Uncal | BY23: 0.1004 | BZ23: 0.0932 | CA23: 0.1096 | CB23: 0.1037 | CC23: 0.1032 | CD23: 0.1038 | CE23: 0.1014 | CF23: 0.1043 | CG23: 0.1027 | CH23: 0.1025 | CI23: 0.0625 | CJ23: 0.0623 | CK23: 0.1163 | CL23: 0.0978 | CM23: 0.0976 | CN23: 0.1011 | CO23: 0.0994 | CP23: 0.0998 | CQ23: 0.0993 | CR23: 0.0933 | CS23: 0.0974 | CT23: 0.1076 | CU23: 0.1026 | CV23: 0.0794 | CW23: 0.1001 | CX23: 0.1028 | CY23: 0.0986 | CZ23: 0.0945 | DA23: 0.0923 | DB23: Uncal | DC23: Uncal | DD23: 0.1042 | DE23: 0.1041 | DF23: 0.1029 | DG23: 0.1032 | DH23: 0.1 | DI23: 0.0996
A24: SAMPLE, RPD Calculated | B24: 2025NALS02293 A03 | C24: -0.0003 u | D24: -0.0007 u | E24: 0.0043 | F24: 0.0002 u | G24: 0.003 | H24: 0.0048 | I24: 0.005 | J24: 0.0221 | K24: 0.022 | L24: 0.0000 u | M24: 0.0004 | N24: Uncal | O24: Uncal | P24: 29.4233 | Q24: 28.9931 | R24: 0.0002 | S24: 0.0000 u | T24: -0.0006 u | U24: 0.0001 u | V24: 0.0000 u | W24: 0.0003 | X24: 0.0002 u | Y24: 0.0001 | Z24: 0.2819 | AA24: 0.0004 | AB24: 0.0000 u | AC24: 0.0001 u | AD24: 0.0008 | AE24: -0.0001 u | AF24: 0.0000 u | AG24: 0.0095 | AH24: 0.0091 | AI24: -0.0001 u | AJ24: -0.0008 u | AK24: 0.0014 | AL24: 0.0002 | AM24: 0.0005 | AN24: 0.0001 | AO24: 1.5117 | AP24: -1.5423 u | AQ24: -0.0006 u | AR24: -0.0001 u | AS24: 1.6497 | AT24: 0.0035 | AU24: 0.0002 | AV24: Uncal | AW24: Uncal | AX24: 0 | AY24: 0.0005 | AZ24: 8.8887 | BA24: 8.8506 | BB24: 0.0048 | BC24: 0.0063 | BD24: 0.0028 | BE24: 0.0033 | BF24: 5.4815 | BG24: 5.4966 | BH24: 0.0018 | BI24: -0.0101 u | BJ24: -0.0007 u | BK24: 0.0006 | BL24: 0.0009 | BM24: 0.0000 u | BN24: Uncal | BO24: 0.0045 u | BP24: 0.0209 | BQ24: -0.0001 u | BR24: 0.0001 u | BS24: 3.4935 | BT24: 3.5196 | BU24: -0.0002 u | BV24: 0.001 | BW24: Uncal | BX24: Uncal | BY24: -0.0034 u | BZ24: 0.0027 u | CA24: 4.7145 o | CB24: 4.6166 o | CC24: 0.0000 u | CD24: 0.0007 | CE24: -0.0014 u | CF24: 0.0053 | CG24: 0.1317 | CH24: 0.1358 | CI24: 0.0009 | CJ24: 0.0001 u | CK24: 0.0013 u | CL24: 0.0018 | CM24: 0.0039 | CN24: 0.0000 u | CO24: 0.0000 u | CP24: -0.0001 u | CQ24: 0.0003 | CR24: -0.0072 u | CS24: 0.0001 u | CT24: -0.0002 u | CU24: 0.0000 u | CV24: 0.0609 | CW24: -0.0121 u | CX24: 0.0006 | CY24: 0.0208 | CZ24: 0.0014 | DA24: -0.0013 u | DB24: Uncal | DC24: Uncal | DD24: 0.0001 | DE24: 0.0001 | DF24: 0.0077 | DG24: 0.006 | DH24: 0.0000 u | DI24: 0
A25: SAMPLE DUPLICATE, RPD Calculated | B25: 2025NALS02293 A04 | C25: -0.0002 u | D25: -0.0005 u | E25: 0.005 | F25: -0.0035 u | G25: 0.0061 | H25: 0.0048 | I25: 0.0049 | J25: 0.0221 | K25: 0.022 | L25: 0.0000 u | M25: 0.0004 | N25: Uncal | O25: Uncal | P25: 29.4265 | Q25: 28.8258 | R25: 0.0001 | S25: -0.0001 u | T25: -0.0007 u | U25: 0.0003 | V25: 0.0002 | W25: 0.0006 | X25: -0.0020 u | Y25: 0.0002 | Z25: 0.2813 | AA25: 0.0003 | AB25: 0.0000 u | AC25: 0.0000 u | AD25: 0.0004 | AE25: -0.0001 u | AF25: 0 | AG25: 0.0108 | AH25: 0.0091 | AI25: 0.0000 u | AJ25: -0.0005 u | AK25: 0.0012 | AL25: 0.0002 | AM25: 0.0005 | AN25: 0.0000 u | AO25: 1.0849 | AP25: 0.1124 u | AQ25: -0.0003 u | AR25: -0.0002 u | AS25: 1.6463 | AT25: 0.0038 | AU25: 0.0000 u | AV25: Uncal | AW25: Uncal | AX25: 0 | AY25: 0.0006 | AZ25: 8.9013 | BA25: 8.8665 | BB25: 0.0048 | BC25: 0.0061 | BD25: 0.0025 | BE25: 0.0026 | BF25: 5.4582 | BG25: 5.4574 | BH25: 0.0015 | BI25: 0.0094 | BJ25: -0.0007 u | BK25: 0.0006 | BL25: 0.0012 | BM25: -0.0002 u | BN25: Uncal | BO25: 0.0239 | BP25: 0.017 | BQ25: 0.0009 u | BR25: -0.0006 u | BS25: 3.4799 | BT25: 3.5118 | BU25: 0.0032 u | BV25: 0.0016 u | BW25: Uncal | BX25: Uncal | BY25: 0.0009 u | BZ25: -0.0035 u | CA25: 4.7049 o | CB25: 4.6202 o | CC25: -0.0004 u | CD25: 0.0007 | CE25: -0.0013 u | CF25: 0.0052 | CG25: 0.1317 | CH25: 0.136 | CI25: 0.0008 | CJ25: 0.0000 u | CK25: -0.0173 u | CL25: 0.0014 u | CM25: 0.004 | CN25: -0.0004 u | CO25: -0.0001 u | CP25: -0.0001 u | CQ25: 0.0000 u | CR25: -0.0095 u | CS25: 0.0000 u | CT25: -0.0002 u | CU25: 0.0001 u | CV25: 0.06 | CW25: -0.0132 u | CX25: 0.0008 | CY25: 0.0163 | CZ25: 0.0014 | DA25: -0.0007 u | DB25: Uncal | DC25: Uncal | DD25: 0.0001 | DE25: 0.0001 | DF25: 0.0075 | DG25: 0.0061 | DH25: 0.0000 u | DI25: 0.0000 u
A26: LFM Background (10X Dil. of Sample) | B26: 2025NALS02293 A03 - Dil. 10X | C26: 0.0006 | D26: 0.0001 u | E26: 0.0007 u | F26: -0.0028 u | G26: -0.0008 u | H26: 0.0005 | I26: 0.0005 | J26: 0.0021 | K26: 0.0023 | L26: 0.0000 u | M26: -0.0003 u | N26: Uncal | O26: Uncal | P26: 2.9521 | Q26: 2.8867 | R26: 0.0001 | S26: 0.0000 u | T26: 0.0001 u | U26: 0.0000 u | V26: 0.0000 u | W26: -0.0001 u | X26: -0.0003 u | Y26: 0.0000 u | Z26: 0.0286 | AA26: 0.0002 | AB26: 0.0000 u | AC26: 0.0000 u | AD26: 0.0001 | AE26: -0.0001 u | AF26: 0.0000 u | AG26: 0.0016 | AH26: 0.0012 | AI26: 0.0000 u | AJ26: -0.0007 u | AK26: -0.0005 u | AL26: 0.0001 | AM26: 0.0002 u | AN26: -0.0001 u | AO26: -0.7129 u | AP26: -1.7131 u | AQ26: -0.0001 u | AR26: 0.0001 | AS26: 0.138 | AT26: 0.0002 | AU26: 0.0000 u | AV26: Uncal | AW26: Uncal | AX26: 0.0000 u | AY26: 0.0000 u | AZ26: 0.8955 | BA26: 0.8873 | BB26: 0.0007 | BC26: 0.0014 | BD26: 0.0008 | BE26: -0.0001 u | BF26: 0.5415 | BG26: 0.5116 | BH26: 0.0003 | BI26: 0.0000 u | BJ26: -0.0002 u | BK26: -0.0003 u | BL26: -0.0005 u | BM26: 0.0001 u | BN26: Uncal | BO26: -0.0004 u | BP26: 0.0064 | BQ26: 0.0001 u | BR26: 0.0000 u | BS26: 0.3458 | BT26: 0.3524 | BU26: 0.0021 | BV26: 0.0002 u | BW26: Uncal | BX26: Uncal | BY26: -0.0085 u | BZ26: -0.0078 u | CA26: 0.5022 | CB26: 0.4869 | CC26: -0.0003 u | CD26: 0.0002 | CE26: 0.0011 u | CF26: 0.0013 | CG26: 0.0132 | CH26: 0.0133 | CI26: 0.0001 u | CJ26: -0.0006 u | CK26: 0.0070 u | CL26: 0.0008 u | CM26: 0.0000 u | CN26: 0.0003 u | CO26: 0.0001 | CP26: 0.0002 | CQ26: -0.0024 u | CR26: -0.0052 u | CS26: 0.0074 | CT26: -0.0001 u | CU26: 0.0000 u | CV26: -0.0002 u | CW26: -0.0061 u | CX26: 0.0002 | CY26: 0.0002 | CZ26: 0.0017 | DA26: -0.0008 u | DB26: Uncal | DC26: Uncal | DD26: 0 | DE26: 0 | DF26: 0.001 | DG26: 0.0009 | DH26: 0.0000 u | DI26: 0.0000 u
A27: LFM Spike | B27: 2025NALS02293 A05 | C27: 0.0292 | D27: 0.0225 | E27: 0.1042 | F27: 0.1002 | G27: 0.0984 | H27: 0.1037 | I27: 0.1038 | J27: 0.1053 | K27: 0.1063 | L27: 0.104 | M27: 0.1069 | N27: Uncal | O27: Uncal | P27: 3.1018 | Q27: 3.0629 | R27: 0.102 | S27: 0.1028 | T27: 0.0922 | U27: 0.0932 | V27: 0.103 | W27: 0.1026 | X27: 0.1031 | Y27: 0.1033 | Z27: 0.13 | AA27: 0.1015 | AB27: 0.103 | AC27: 0.1026 | AD27: 0.1025 | AE27: 0.1049 | AF27: 0.1046 | AG27: 0.1039 | AH27: 0.1044 | AI27: 0.0993 | AJ27: 0.1016 | AK27: 0.1018 | AL27: 0.1027 | AM27: 0.1003 | AN27: 0.0984 | AO27: 11.2645 | AP27: 9.8008 | AQ27: 0.1016 | AR27: 0.1023 | AS27: 0.2502 | AT27: 0.1019 | AU27: 0.1025 | AV27: Uncal | AW27: Uncal | AX27: 0.1023 | AY27: 0.1025 | AZ27: 1.0264 | BA27: 1.0154 | BB27: 0.1022 | BC27: 0.1043 | BD27: 0.1063 | BE27: 0.1063 | BF27: 0.6602 | BG27: 0.6262 | BH27: 0.0861 | BI27: 0.0792 | BJ27: 0.0969 | BK27: 0.1029 | BL27: 0.1029 | BM27: 0.1022 | BN27: Uncal | BO27: 0.1224 | BP27: 0.1099 | BQ27: 0.1009 | BR27: 0.0988 | BS27: 0.4368 | BT27: 0.4631 | BU27: 0.102 | BV27: 0.0991 | BW27: Uncal | BX27: Uncal | BY27: 0.0997 | BZ27: 0.0993 | CA27: 0.6142 | CB27: 0.5885 | CC27: 0.103 | CD27: 0.1033 | CE27: 0.1033 | CF27: 0.1045 | CG27: 0.1159 | CH27: 0.1164 | CI27: 0.0627 | CJ27: 0.0625 | CK27: 0.0975 | CL27: 0.0984 | CM27: 0.0972 | CN27: 0.1009 | CO27: 0.0994 | CP27: 0.1001 | CQ27: 0.1013 | CR27: 0.0951 | CS27: 0.0998 | CT27: 0.1087 | CU27: 0.1029 | CV27: 0.0849 | CW27: 0.0999 | CX27: 0.1037 | CY27: 0.1029 | CZ27: 0.0941 | DA27: 0.0937 | DB27: Uncal | DC27: Uncal | DD27: 0.1039 | DE27: 0.104 | DF27: 0.1033 | DG27: 0.1033 | DH27: 0.1001 | DI27: 0.0997
A28: Instrument LFB | B28: Lab Fortified Blank 1ppm May 29/25 ICV | C28: 0.0321 | D28: 0.026 | E28: 0.094 | F28: 0.0956 | G28: 0.0948 | H28: 0.0996 | I28: 0.0997 | J28: 0.1002 | K28: 0.1017 | L28: 0.1011 | M28: 0.1013 | N28: Uncal | O28: Uncal | P28: 0.0943 | Q28: 0.0954 | R28: 0.1007 | S28: 0.1001 | T28: 0.0903 | U28: 0.0909 | V28: 0.1004 | W28: 0.1003 | X28: 0.0984 | Y28: 0.1004 | Z28: 0.0983 | AA28: 0.0977 | AB28: 0.1 | AC28: 0.0983 | AD28: 0.0993 | AE28: 0.1 | AF28: 0.1007 | AG28: 0.0988 | AH28: 0.1 | AI28: 0.096 | AJ28: 0.0981 | AK28: 0.0997 | AL28: 0.0995 | AM28: 0.0975 | AN28: 0.0959 | AO28: 10.3399 | AP28: 8.4278 | AQ28: 0.0986 | AR28: 0.0992 | AS28: 0.0972 | AT28: 0.0997 | AU28: 0.0999 | AV28: Uncal | AW28: Uncal | AX28: 0.1012 | AY28: 0.1006 | AZ28: 0.0999 | BA28: 0.1 | BB28: 0.0986 | BC28: 0.0991 | BD28: 0.1028 | BE28: 0.103 | BF28: 0.0998 | BG28: 0.1001 | BH28: Uncal | BI28: Uncal | BJ28: 0.0959 | BK28: 0.0996 | BL28: 0.1015 | BM28: 0.1006 | BN28: Uncal | BO28: 0.1006 | BP28: 0.1018 | BQ28: 0.0987 | BR28: 0.0995 | BS28: 0.0909 | BT28: 0.0967 | BU28: 0.0954 | BV28: 0.0911 | BW28: Uncal | BX28: Uncal | BY28: 0.0951 | BZ28: 0.0853 | CA28: 0.1 | CB28: 0.0987 | CC28: 0.0988 | CD28: 0.0997 | CE28: 0.0977 | CF28: 0.0993 | CG28: 0.0995 | CH28: 0.0991 | CI28: 0.0878 | CJ28: 0.0874 | CK28: 0.1077 | CL28: 0.0993 | CM28: 0.0961 | CN28: 0.0975 | CO28: 0.098 | CP28: 0.0975 | CQ28: 0.0949 | CR28: 0.1003 | CS28: 0.1027 | CT28: 0.1023 | CU28: 0.099 | CV28: 0.0761 | CW28: 0.0923 | CX28: 0.0996 | CY28: 0.0948 | CZ28: 0.0927 | DA28: 0.0938 | DB28: Uncal | DC28: Uncal | DD28: 0.101 | DE28: 0.1012 | DF28: 0.1013 | DG28: 0.1005 | DH28: 0.0995 | DI28: 0.0968
